Workbook

Sheet Instructions
A2: 2026 Live Auction Tool
A4: Purpose: | B4: This auction tool will give you projected/starting auction values for each player depending on your league settings. Then during your draft, enter the amount players are drafted for. The tool will then adjust a market price for the remaning players on the board. This is based off trends your league is showing so you know if you need to adjust high or low if you want to bid on a player.
A5: Note: | B5: Just like any tool you use. This is providing calculated data to guide you, it is not telling you who you have to or don't have to draft and at what price. You ultimately have to the make the decision and react to your draft room on the fly if need be.
A7: Step 1: | B7: Go to the Setup tab and enter your league's Starting Budget, Number of Teams, and Scoring Format.
A9: Step 2: | B9: Still on Setup, enter your Roster Shape -- Starters at each position, any Flex slots (RB/WR/TE, RB/WR, WR/TE, or Superflex -- these can combine, e.g. 1 RB/WR flex AND 1 Superflex in the same league), DEF, K, and Bench spots.
B10: Every value on the whole board recalculates instantly when you change anything here - You should sort each position by "Starting Value" (low to high) if you change anything from the defaults.
A12: Step 3: | B12: Go to the Draft Board tab. Each position (QB/RB/WR/TE) has its own set of columns. "Starting Value" is what a player is worth before any picks are made. "Market Value" is the live price that updates as your draft happens.
A14: Step 4: | B14: As players get drafted -- by you or anyone else in your league -- enter the actual winning bid in that player's "Price Paid" column. You don't need to delete, sort, or remove anything; Market Value for every remaining player updates on its own.
B15: Click the dropdown arrow on any position's header row to sort that block -- handy after switching Scoring Format, since row order is only set once when the sheet is built.
A17: Step 5: | B17: Track your own roster and remaining budget on the My Team tab -- separate from the main board, just for you.
A19: Note | B19: A single pick won't swing anyone's price much -- Market Value only moves once a couple of real prices come in for players near each other in value.
A21: Note | B21: The board is trimmed to a realistic depth per position -- you won't see every player who could theoretically be rostered, just anyone with a real shot at being drafted.
A23: Note | B23: If you change anything on Setup mid-draft, every value recalculates instantly -- but any Price Paid you've already entered stays exactly as typed.
A26: Field Legend
A27: Player / Team | B27: Who and where.
A28: Proj Pts | B28: Projected season points, based on your selected Scoring Format.
A29: Starting Value | B29: What we'd expect this player to cost before any picks are made.
A30: Price Paid | B30: Enter the real winning bid once a player is drafted -- blank until then.
A31: Market Value | B31: The live price estimate. Equals Price Paid once you've entered it; otherwise it's the current estimate given who's already gone.

Sheet Setup
A1: League Setup
A3: Starting Budget ($) | B3: 200
A5: Number of Teams | B5: 12
A7: Scoring Format | B7: Half-PPR
A9: Roster Shape
A11: QB Starters | B11: 1
A13: RB Starters | B13: 2
A15: WR Starters | B15: 3
A17: TE Starters | B17: 1
A19: Flex: RB/WR/TE Count | B19: 1
A21: Flex: RB/WR Count | B21: 0
A23: Flex: WR/TE Count | B23: 0
A25: Superflex Count (QB/RB/WR/TE) | B25: 0
A27: DEF | B27: 1
A29: K | B29: 1
A31: Bench | B31: 6

Sheet Draft Board
A1: Player | B1: Team | C1: Points (STD) | D1: Points (Half-PPR) | E1: Points (PPR) | F1: Proj Pts | G1: Tier | H1: Weighted VORP | I1: Row Num | J1: Gap Start | K1: Gap Tier Top | L1: Tier Start | M1: Starting Value | N1: Price Paid | O1: Market Value | Q1: Player | R1: Team | S1: Points (STD) | T1: Points (Half-PPR) | U1: Points (PPR) | V1: Proj Pts | W1: Tier | X1: Weighted VORP | Y1: Row Num | Z1: Gap Start | AA1: Gap Tier Top | AB1: Tier Start | AC1: Starting Value | AD1: Price Paid | AE1: Market Value | AG1: Player | AH1: Team | AI1: Points (STD) | AJ1: Points (Half-PPR) | AK1: Points (PPR) | AL1: Proj Pts | AM1: Tier | AN1: Weighted VORP | AO1: Row Num | AP1: Gap Start | AQ1: Gap Tier Top | AR1: Tier Start | AS1: Starting Value | AT1: Price Paid | AU1: Market Value | AW1: Player | AX1: Team | AY1: Points (STD) | AZ1: Points (Half-PPR) | BA1: Points (PPR) | BB1: Proj Pts | BC1: Tier | BD1: Weighted VORP | BE1: Row Num | BF1: Gap Start | BG1: Gap Tier Top | BH1: Tier Start | BI1: Starting Value | BJ1: Price Paid | BK1: Market Value
A2: Josh Allen | B2: BUF | C2: 352.84 | D2: 352.84 | E2: 352.84 | F2: =CHOOSE(MATCH(Setup!$B$7,{"STD","Half-PPR","PPR"},0),C2,D2,E2) -> 352.84 | G2: =COUNTIFS('Draft Board'!$H$2:$H$61,">="&H2,'Draft Board'!$L$2:$L$61,1) -> 1 | H2: =MAX(0,F2-'Live Calc'!$H$19)^'Live Calc'!$E$19 -> 223.01558 | I2: 2 | J2: =IF(I2<>_xlfn.MINIFS('Draft Board'!$I$2:$I$61,'Draft Board'!$H$2:$H$61,"="&H2),0,IF(_xlfn.MINIFS('Draft Board'!$H$2:$H$61,'Draft Board'!$H$2:$H$61,">"&H2)=0,1,IF((_xlfn.MINIFS('Draft Board'!$H$2:$H$61,'Draft Board'!$H$2:$H$61,">"&H2)-H2)/_xlfn.MINIFS('Draft Board'!$H$2:$H$61,'Draft Board'!$H$2:$H$61,">"&H2)>0.08,1,0))) -> 1 | K2: =_xlfn.MINIFS('Draft Board'!$H$2:$H$61,'Draft Board'!$H$2:$H$61,">="&H2,'Draft Board'!$J$2:$J$61,1) -> 223.01558 | L2: =IF(I2<>_xlfn.MINIFS('Draft Board'!$I$2:$I$61,'Draft Board'!$H$2:$H$61,"="&H2),0,IF(OR(J2=1,IFERROR(FLOOR((K2-H2)/K2/0.25,1),0)<>IFERROR(FLOOR((K2-_xlfn.MINIFS('Draft Board'!$H$2:$H$61,'Draft Board'!$H$2:$H$61,">"&H2))/K2/0.25,1),0)),1,0)) -> 1 | M2: =ROUND(1+H2*'Live Calc'!$D$26,0) -> 31 | O2: =IF(N2<>"",N2,ROUND(M2*INDEX('Live Calc'!$G$33:$G$92,MATCH(G2,'Live Calc'!$A$33:$A$92,0))*'Live Calc'!$J$543,0)) -> 31 | Q2: Jahmyr Gibbs | R2: DET | S2: 284.21 | T2: 318.53 | U2: 352.86 | V2: =CHOOSE(MATCH(Setup!$B$7,{"STD","Half-PPR","PPR"},0),S2,T2,U2) -> 318.53 | W2: =COUNTIFS('Draft Board'!$X$2:$X$162,">="&X2,'Draft Board'!$AB$2:$AB$162,1) -> 1 | X2: =MAX(0,V2-'Live Calc'!$H$20)^'Live Calc'!$E$20 -> 619.64589 | Y2: 2 | Z2: =IF(Y2<>_xlfn.MINIFS('Draft Board'!$Y$2:$Y$162,'Draft Board'!$X$2:$X$162,"="&X2),0,IF(_xlfn.MINIFS('Draft Board'!$X$2:$X$162,'Draft Board'!$X$2:$X$162,">"&X2)=0,1,IF((_xlfn.MINIFS('Draft Board'!$X$2:$X$162,'Draft Board'!$X$2:$X$162,">"&X2)-X2)/_xlfn.MINIFS('Draft Board'!$X$2:$X$162,'Draft Board'!$X$2:$X$162,">"&X2)>0.08,1,0))) -> 1 | AA2: =_xlfn.MINIFS('Draft Board'!$X$2:$X$162,'Draft Board'!$X$2:$X$162,">="&X2,'Draft Board'!$Z$2:$Z$162,1) -> 619.64589 | AB2: =IF(Y2<>_xlfn.MINIFS('Draft Board'!$Y$2:$Y$162,'Draft Board'!$X$2:$X$162,"="&X2),0,IF(OR(Z2=1,IFERROR(FLOOR((AA2-X2)/AA2/0.25,1),0)<>IFERROR(FLOOR((AA2-_xlfn.MINIFS('Draft Board'!$X$2:$X$162,'Draft Board'!$X$2:$X$162,">"&X2))/AA2/0.25,1),0)),1,0)) -> 1 | AC2: =ROUND(1+X2*'Live Calc'!$D$27,0) -> 62 | AE2: =IF(AD2<>"",AD2,ROUND(AC2*INDEX('Live Calc'!$G$96:$G$256,MATCH(W2,'Live Calc'!$A$96:$A$256,0))*'Live Calc'!$J$543,0)) -> 62 | AG2: Puka Nacua | AH2: LAR | AI2: 215.796 | AJ2: 275.318 | AK2: 334.84 | AL2: =CHOOSE(MATCH(Setup!$B$7,{"STD","Half-PPR","PPR"},0),AI2,AJ2,AK2) -> 275.318 | AM2: =COUNTIFS('Draft Board'!$AN$2:$AN$192,">="&AN2,'Draft Board'!$AR$2:$AR$192,1) -> 1 | AN2: =MAX(0,AL2-'Live Calc'!$H$21)^'Live Calc'!$E$21 -> 2249.1129 | AO2: 2 | AP2: =IF(AO2<>_xlfn.MINIFS('Draft Board'!$AO$2:$AO$192,'Draft Board'!$AN$2:$AN$192,"="&AN2),0,IF(_xlfn.MINIFS('Draft Board'!$AN$2:$AN$192,'Draft Board'!$AN$2:$AN$192,">"&AN2)=0,1,IF((_xlfn.MINIFS('Draft Board'!$AN$2:$AN$192,'Draft Board'!$AN$2:$AN$192,">"&AN2)-AN2)/_xlfn.MINIFS('Draft Board'!$AN$2:$AN$192,'Draft Board'!$AN$2:$AN$192,">"&AN2)>0.08,1,0))) -> 1 | AQ2: =_xlfn.MINIFS('Draft Board'!$AN$2:$AN$192,'Draft Board'!$AN$2:$AN$192,">="&AN2,'Draft Board'!$AP$2:$AP$192,1) -> 2249.1129 | AR2: =IF(AO2<>_xlfn.MINIFS('Draft Board'!$AO$2:$AO$192,'Draft Board'!$AN$2:$AN$192,"="&AN2),0,IF(OR(AP2=1,IFERROR(FLOOR((AQ2-AN2)/AQ2/0.25,1),0)<>IFERROR(FLOOR((AQ2-_xlfn.MINIFS('Draft Board'!$AN$2:$AN$192,'Draft Board'!$AN$2:$AN$192,">"&AN2))/AQ2/0.25,1),0)),1,0)) -> 1 | AS2: =ROUND(1+AN2*'Live Calc'!$D$28,0) -> 62 | AU2: =IF(AT2<>"",AT2,ROUND(AS2*INDEX('Live Calc'!$G$260:$G$450,MATCH(AM2,'Live Calc'!$A$260:$A$450,0))*'Live Calc'!$J$543,0)) -> 62 | AW2: Trey McBride | AX2: ARI | AY2: 141.57 | AZ2: 192.764 | BA2: 242.298 | BB2: =CHOOSE(MATCH(Setup!$B$7,{"STD","Half-PPR","PPR"},0),AY2,AZ2,BA2) -> 192.764 | BC2: =COUNTIFS('Draft Board'!$BD$2:$BD$87,">="&BD2,'Draft Board'!$BH$2:$BH$87,1) -> 1 | BD2: =MAX(0,BB2-'Live Calc'!$H$22)^'Live Calc'!$E$22 -> 1377.0247 | BE2: 2 | BF2: =IF(BE2<>_xlfn.MINIFS('Draft Board'!$BE$2:$BE$87,'Draft Board'!$BD$2:$BD$87,"="&BD2),0,IF(_xlfn.MINIFS('Draft Board'!$BD$2:$BD$87,'Draft Board'!$BD$2:$BD$87,">"&BD2)=0,1,IF((_xlfn.MINIFS('Draft Board'!$BD$2:$BD$87,'Draft Board'!$BD$2:$BD$87,">"&BD2)-BD2)/_xlfn.MINIFS('Draft Board'!$BD$2:$BD$87,'Draft Board'!$BD$2:$BD$87,">"&BD2)>0.08,1,0))) -> 1 | BG2: =_xlfn.MINIFS('Draft Board'!$BD$2:$BD$87,'Draft Board'!$BD$2:$BD$87,">="&BD2,'Draft Board'!$BF$2:$BF$87,1) -> 1377.0247 | BH2: =IF(BE2<>_xlfn.MINIFS('Draft Board'!$BE$2:$BE$87,'Draft Board'!$BD$2:$BD$87,"="&BD2),0,IF(OR(BF2=1,IFERROR(FLOOR((BG2-BD2)/BG2/0.25,1),0)<>IFERROR(FLOOR((BG2-_xlfn.MINIFS('Draft Board'!$BD$2:$BD$87,'Draft Board'!$BD$2:$BD$87,">"&BD2))/BG2/0.25,1),0)),1,0)) -> 1 | BI2: =ROUND(1+BD2*'Live Calc'!$D$29,0) -> 33 | BK2: =IF(BJ2<>"",BJ2,ROUND(BI2*INDEX('Live Calc'!$G$454:$G$539,MATCH(BC2,'Live Calc'!$A$454:$A$539,0))*'Live Calc'!$J$543,0)) -> 33
A3: Lamar Jackson | B3: BAL | C3: 314.58 | D3: 314.58 | E3: 314.58 | F3: =CHOOSE(MATCH(Setup!$B$7,{"STD","Half-PPR","PPR"},0),C3,D3,E3) -> 314.58 | G3: =COUNTIFS('Draft Board'!$H$2:$H$61,">="&H3,'Draft Board'!$L$2:$L$61,1) -> 2 | H3: =MAX(0,F3-'Live Calc'!$H$19)^'Live Calc'!$E$19 -> 115.40429 | I3: 3 | J3: =IF(I3<>_xlfn.MINIFS('Draft Board'!$I$2:$I$61,'Draft Board'!$H$2:$H$61,"="&H3),0,IF(_xlfn.MINIFS('Draft Board'!$H$2:$H$61,'Draft Board'!$H$2:$H$61,">"&H3)=0,1,IF((_xlfn.MINIFS('Draft Board'!$H$2:$H$61,'Draft Board'!$H$2:$H$61,">"&H3)-H3)/_xlfn.MINIFS('Draft Board'!$H$2:$H$61,'Draft Board'!$H$2:$H$61,">"&H3)>0.08,1,0))) -> 1 | K3: =_xlfn.MINIFS('Draft Board'!$H$2:$H$61,'Draft Board'!$H$2:$H$61,">="&H3,'Draft Board'!$J$2:$J$61,1) -> 115.40429 | L3: =IF(I3<>_xlfn.MINIFS('Draft Board'!$I$2:$I$61,'Draft Board'!$H$2:$H$61,"="&H3),0,IF(OR(J3=1,IFERROR(FLOOR((K3-H3)/K3/0.25,1),0)<>IFERROR(FLOOR((K3-_xlfn.MINIFS('Draft Board'!$H$2:$H$61,'Draft Board'!$H$2:$H$61,">"&H3))/K3/0.25,1),0)),1,0)) -> 1 | M3: =ROUND(1+H3*'Live Calc'!$D$26,0) -> 17 | O3: =IF(N3<>"",N3,ROUND(M3*INDEX('Live Calc'!$G$33:$G$92,MATCH(G3,'Live Calc'!$A$33:$A$92,0))*'Live Calc'!$J$543,0)) -> 17 | Q3: Bijan Robinson | R3: ATL | S3: 273.56 | T3: 310.43 | U3: 347.3 | V3: =CHOOSE(MATCH(Setup!$B$7,{"STD","Half-PPR","PPR"},0),S3,T3,U3) -> 310.43 | W3: =COUNTIFS('Draft Board'!$X$2:$X$162,">="&X3,'Draft Board'!$AB$2:$AB$162,1) -> 1 | X3: =MAX(0,V3-'Live Calc'!$H$20)^'Live Calc'!$E$20 -> 591.37461 | Y3: 3 | Z3: =IF(Y3<>_xlfn.MINIFS('Draft Board'!$Y$2:$Y$162,'Draft Board'!$X$2:$X$162,"="&X3),0,IF(_xlfn.MINIFS('Draft Board'!$X$2:$X$162,'Draft Board'!$X$2:$X$162,">"&X3)=0,1,IF((_xlfn.MINIFS('Draft Board'!$X$2:$X$162,'Draft Board'!$X$2:$X$162,">"&X3)-X3)/_xlfn.MINIFS('Draft Board'!$X$2:$X$162,'Draft Board'!$X$2:$X$162,">"&X3)>0.08,1,0))) -> 0 | AA3: =_xlfn.MINIFS('Draft Board'!$X$2:$X$162,'Draft Board'!$X$2:$X$162,">="&X3,'Draft Board'!$Z$2:$Z$162,1) -> 619.64589 | AB3: =IF(Y3<>_xlfn.MINIFS('Draft Board'!$Y$2:$Y$162,'Draft Board'!$X$2:$X$162,"="&X3),0,IF(OR(Z3=1,IFERROR(FLOOR((AA3-X3)/AA3/0.25,1),0)<>IFERROR(FLOOR((AA3-_xlfn.MINIFS('Draft Board'!$X$2:$X$162,'Draft Board'!$X$2:$X$162,">"&X3))/AA3/0.25,1),0)),1,0)) -> 0 | AC3: =ROUND(1+X3*'Live Calc'!$D$27,0) -> 59 | AE3: =IF(AD3<>"",AD3,ROUND(AC3*INDEX('Live Calc'!$G$96:$G$256,MATCH(W3,'Live Calc'!$A$96:$A$256,0))*'Live Calc'!$J$543,0)) -> 59 | AG3: Ja'Marr Chase | AH3: CIN | AI3: 214.254 | AJ3: 273.852 | AK3: 333.45 | AL3: =CHOOSE(MATCH(Setup!$B$7,{"STD","Half-PPR","PPR"},0),AI3,AJ3,AK3) -> 273.852 | AM3: =COUNTIFS('Draft Board'!$AN$2:$AN$192,">="&AN3,'Draft Board'!$AR$2:$AR$192,1) -> 1 | AN3: =MAX(0,AL3-'Live Calc'!$H$21)^'Live Calc'!$E$21 -> 2220.3632 | AO3: 3 | AP3: =IF(AO3<>_xlfn.MINIFS('Draft Board'!$AO$2:$AO$192,'Draft Board'!$AN$2:$AN$192,"="&AN3),0,IF(_xlfn.MINIFS('Draft Board'!$AN$2:$AN$192,'Draft Board'!$AN$2:$AN$192,">"&AN3)=0,1,IF((_xlfn.MINIFS('Draft Board'!$AN$2:$AN$192,'Draft Board'!$AN$2:$AN$192,">"&AN3)-AN3)/_xlfn.MINIFS('Draft Board'!$AN$2:$AN$192,'Draft Board'!$AN$2:$AN$192,">"&AN3)>0.08,1,0))) -> 0 | AQ3: =_xlfn.MINIFS('Draft Board'!$AN$2:$AN$192,'Draft Board'!$AN$2:$AN$192,">="&AN3,'Draft Board'!$AP$2:$AP$192,1) -> 2249.1129 | AR3: =IF(AO3<>_xlfn.MINIFS('Draft Board'!$AO$2:$AO$192,'Draft Board'!$AN$2:$AN$192,"="&AN3),0,IF(OR(AP3=1,IFERROR(FLOOR((AQ3-AN3)/AQ3/0.25,1),0)<>IFERROR(FLOOR((AQ3-_xlfn.MINIFS('Draft Board'!$AN$2:$AN$192,'Draft Board'!$AN$2:$AN$192,">"&AN3))/AQ3/0.25,1),0)),1,0)) -> 0 | AS3: =ROUND(1+AN3*'Live Calc'!$D$28,0) -> 61 | AU3: =IF(AT3<>"",AT3,ROUND(AS3*INDEX('Live Calc'!$G$260:$G$450,MATCH(AM3,'Live Calc'!$A$260:$A$450,0))*'Live Calc'!$J$543,0)) -> 61 | AW3: Brock Bowers | AX3: LV | AY3: 145.72 | AZ3: 192.606 | BA3: 241.152 | BB3: =CHOOSE(MATCH(Setup!$B$7,{"STD","Half-PPR","PPR"},0),AY3,AZ3,BA3) -> 192.606 | BC3: =COUNTIFS('Draft Board'!$BD$2:$BD$87,">="&BD3,'Draft Board'!$BH$2:$BH$87,1) -> 1 | BD3: =MAX(0,BB3-'Live Calc'!$H$22)^'Live Calc'!$E$22 -> 1373.2258 | BE3: 3 | BF3: =IF(BE3<>_xlfn.MINIFS('Draft Board'!$BE$2:$BE$87,'Draft Board'!$BD$2:$BD$87,"="&BD3),0,IF(_xlfn.MINIFS('Draft Board'!$BD$2:$BD$87,'Draft Board'!$BD$2:$BD$87,">"&BD3)=0,1,IF((_xlfn.MINIFS('Draft Board'!$BD$2:$BD$87,'Draft Board'!$BD$2:$BD$87,">"&BD3)-BD3)/_xlfn.MINIFS('Draft Board'!$BD$2:$BD$87,'Draft Board'!$BD$2:$BD$87,">"&BD3)>0.08,1,0))) -> 0 | BG3: =_xlfn.MINIFS('Draft Board'!$BD$2:$BD$87,'Draft Board'!$BD$2:$BD$87,">="&BD3,'Draft Board'!$BF$2:$BF$87,1) -> 1377.0247 | BH3: =IF(BE3<>_xlfn.MINIFS('Draft Board'!$BE$2:$BE$87,'Draft Board'!$BD$2:$BD$87,"="&BD3),0,IF(OR(BF3=1,IFERROR(FLOOR((BG3-BD3)/BG3/0.25,1),0)<>IFERROR(FLOOR((BG3-_xlfn.MINIFS('Draft Board'!$BD$2:$BD$87,'Draft Board'!$BD$2:$BD$87,">"&BD3))/BG3/0.25,1),0)),1,0)) -> 0 | BI3: =ROUND(1+BD3*'Live Calc'!$D$29,0) -> 33 | BK3: =IF(BJ3<>"",BJ3,ROUND(BI3*INDEX('Live Calc'!$G$454:$G$539,MATCH(BC3,'Live Calc'!$A$454:$A$539,0))*'Live Calc'!$J$543,0)) -> 33
A4: Drake Maye | B4: NE | C4: 308.86 | D4: 308.86 | E4: 308.86 | F4: =CHOOSE(MATCH(Setup!$B$7,{"STD","Half-PPR","PPR"},0),C4,D4,E4) -> 308.86 | G4: =COUNTIFS('Draft Board'!$H$2:$H$61,">="&H4,'Draft Board'!$L$2:$L$61,1) -> 3 | H4: =MAX(0,F4-'Live Calc'!$H$19)^'Live Calc'!$E$19 -> 100.42961 | I4: 4 | J4: =IF(I4<>_xlfn.MINIFS('Draft Board'!$I$2:$I$61,'Draft Board'!$H$2:$H$61,"="&H4),0,IF(_xlfn.MINIFS('Draft Board'!$H$2:$H$61,'Draft Board'!$H$2:$H$61,">"&H4)=0,1,IF((_xlfn.MINIFS('Draft Board'!$H$2:$H$61,'Draft Board'!$H$2:$H$61,">"&H4)-H4)/_xlfn.MINIFS('Draft Board'!$H$2:$H$61,'Draft Board'!$H$2:$H$61,">"&H4)>0.08,1,0))) -> 1 | K4: =_xlfn.MINIFS('Draft Board'!$H$2:$H$61,'Draft Board'!$H$2:$H$61,">="&H4,'Draft Board'!$J$2:$J$61,1) -> 100.42961 | L4: =IF(I4<>_xlfn.MINIFS('Draft Board'!$I$2:$I$61,'Draft Board'!$H$2:$H$61,"="&H4),0,IF(OR(J4=1,IFERROR(FLOOR((K4-H4)/K4/0.25,1),0)<>IFERROR(FLOOR((K4-_xlfn.MINIFS('Draft Board'!$H$2:$H$61,'Draft Board'!$H$2:$H$61,">"&H4))/K4/0.25,1),0)),1,0)) -> 1 | M4: =ROUND(1+H4*'Live Calc'!$D$26,0) -> 15 | O4: =IF(N4<>"",N4,ROUND(M4*INDEX('Live Calc'!$G$33:$G$92,MATCH(G4,'Live Calc'!$A$33:$A$92,0))*'Live Calc'!$J$543,0)) -> 15 | Q4: Christian McCaffrey | R4: SF | S4: 248.02 | T4: 285.6 | U4: 323.19 | V4: =CHOOSE(MATCH(Setup!$B$7,{"STD","Half-PPR","PPR"},0),S4,T4,U4) -> 285.6 | W4: =COUNTIFS('Draft Board'!$X$2:$X$162,">="&X4,'Draft Board'!$AB$2:$AB$162,1) -> 2 | X4: =MAX(0,V4-'Live Calc'!$H$20)^'Live Calc'!$E$20 -> 506.13606 | Y4: 4 | Z4: =IF(Y4<>_xlfn.MINIFS('Draft Board'!$Y$2:$Y$162,'Draft Board'!$X$2:$X$162,"="&X4),0,IF(_xlfn.MINIFS('Draft Board'!$X$2:$X$162,'Draft Board'!$X$2:$X$162,">"&X4)=0,1,IF((_xlfn.MINIFS('Draft Board'!$X$2:$X$162,'Draft Board'!$X$2:$X$162,">"&X4)-X4)/_xlfn.MINIFS('Draft Board'!$X$2:$X$162,'Draft Board'!$X$2:$X$162,">"&X4)>0.08,1,0))) -> 1 | AA4: =_xlfn.MINIFS('Draft Board'!$X$2:$X$162,'Draft Board'!$X$2:$X$162,">="&X4,'Draft Board'!$Z$2:$Z$162,1) -> 506.13606 | AB4: =IF(Y4<>_xlfn.MINIFS('Draft Board'!$Y$2:$Y$162,'Draft Board'!$X$2:$X$162,"="&X4),0,IF(OR(Z4=1,IFERROR(FLOOR((AA4-X4)/AA4/0.25,1),0)<>IFERROR(FLOOR((AA4-_xlfn.MINIFS('Draft Board'!$X$2:$X$162,'Draft Board'!$X$2:$X$162,">"&X4))/AA4/0.25,1),0)),1,0)) -> 1 | AC4: =ROUND(1+X4*'Live Calc'!$D$27,0) -> 51 | AE4: =IF(AD4<>"",AD4,ROUND(AC4*INDEX('Live Calc'!$G$96:$G$256,MATCH(W4,'Live Calc'!$A$96:$A$256,0))*'Live Calc'!$J$543,0)) -> 51 | AG4: Jaxon Smith-Njigba | AH4: SEA | AI4: 207.41 | AJ4: 261.32 | AK4: 315.23 | AL4: =CHOOSE(MATCH(Setup!$B$7,{"STD","Half-PPR","PPR"},0),AI4,AJ4,AK4) -> 261.32 | AM4: =COUNTIFS('Draft Board'!$AN$2:$AN$192,">="&AN4,'Draft Board'!$AR$2:$AR$192,1) -> 2 | AN4: =MAX(0,AL4-'Live Calc'!$H$21)^'Live Calc'!$E$21 -> 1979.6974 | AO4: 4 | AP4: =IF(AO4<>_xlfn.MINIFS('Draft Board'!$AO$2:$AO$192,'Draft Board'!$AN$2:$AN$192,"="&AN4),0,IF(_xlfn.MINIFS('Draft Board'!$AN$2:$AN$192,'Draft Board'!$AN$2:$AN$192,">"&AN4)=0,1,IF((_xlfn.MINIFS('Draft Board'!$AN$2:$AN$192,'Draft Board'!$AN$2:$AN$192,">"&AN4)-AN4)/_xlfn.MINIFS('Draft Board'!$AN$2:$AN$192,'Draft Board'!$AN$2:$AN$192,">"&AN4)>0.08,1,0))) -> 1 | AQ4: =_xlfn.MINIFS('Draft Board'!$AN$2:$AN$192,'Draft Board'!$AN$2:$AN$192,">="&AN4,'Draft Board'!$AP$2:$AP$192,1) -> 1979.6974 | AR4: =IF(AO4<>_xlfn.MINIFS('Draft Board'!$AO$2:$AO$192,'Draft Board'!$AN$2:$AN$192,"="&AN4),0,IF(OR(AP4=1,IFERROR(FLOOR((AQ4-AN4)/AQ4/0.25,1),0)<>IFERROR(FLOOR((AQ4-_xlfn.MINIFS('Draft Board'!$AN$2:$AN$192,'Draft Board'!$AN$2:$AN$192,">"&AN4))/AQ4/0.25,1),0)),1,0)) -> 1 | AS4: =ROUND(1+AN4*'Live Calc'!$D$28,0) -> 55 | AU4: =IF(AT4<>"",AT4,ROUND(AS4*INDEX('Live Calc'!$G$260:$G$450,MATCH(AM4,'Live Calc'!$A$260:$A$450,0))*'Live Calc'!$J$543,0)) -> 55 | AW4: Colston Loveland | AX4: CHI | AY4: 133.52 | AZ4: 172.41 | BA4: 211.3 | BB4: =CHOOSE(MATCH(Setup!$B$7,{"STD","Half-PPR","PPR"},0),AY4,AZ4,BA4) -> 172.41 | BC4: =COUNTIFS('Draft Board'!$BD$2:$BD$87,">="&BD4,'Draft Board'!$BH$2:$BH$87,1) -> 2 | BD4: =MAX(0,BB4-'Live Calc'!$H$22)^'Live Calc'!$E$22 -> 921.08505 | BE4: 4 | BF4: =IF(BE4<>_xlfn.MINIFS('Draft Board'!$BE$2:$BE$87,'Draft Board'!$BD$2:$BD$87,"="&BD4),0,IF(_xlfn.MINIFS('Draft Board'!$BD$2:$BD$87,'Draft Board'!$BD$2:$BD$87,">"&BD4)=0,1,IF((_xlfn.MINIFS('Draft Board'!$BD$2:$BD$87,'Draft Board'!$BD$2:$BD$87,">"&BD4)-BD4)/_xlfn.MINIFS('Draft Board'!$BD$2:$BD$87,'Draft Board'!$BD$2:$BD$87,">"&BD4)>0.08,1,0))) -> 1 | BG4: =_xlfn.MINIFS('Draft Board'!$BD$2:$BD$87,'Draft Board'!$BD$2:$BD$87,">="&BD4,'Draft Board'!$BF$2:$BF$87,1) -> 921.08505 | BH4: =IF(BE4<>_xlfn.MINIFS('Draft Board'!$BE$2:$BE$87,'Draft Board'!$BD$2:$BD$87,"="&BD4),0,IF(OR(BF4=1,IFERROR(FLOOR((BG4-BD4)/BG4/0.25,1),0)<>IFERROR(FLOOR((BG4-_xlfn.MINIFS('Draft Board'!$BD$2:$BD$87,'Draft Board'!$BD$2:$BD$87,">"&BD4))/BG4/0.25,1),0)),1,0)) -> 1 | BI4: =ROUND(1+BD4*'Live Calc'!$D$29,0) -> 23 | BK4: =IF(BJ4<>"",BJ4,ROUND(BI4*INDEX('Live Calc'!$G$454:$G$539,MATCH(BC4,'Live Calc'!$A$454:$A$539,0))*'Live Calc'!$J$543,0)) -> 23
A5: Jayden Daniels | B5: WAS | C5: 307.21 | D5: 307.21 | E5: 307.21 | F5: =CHOOSE(MATCH(Setup!$B$7,{"STD","Half-PPR","PPR"},0),C5,D5,E5) -> 307.21 | G5: =COUNTIFS('Draft Board'!$H$2:$H$61,">="&H5,'Draft Board'!$L$2:$L$61,1) -> 3 | H5: =MAX(0,F5-'Live Calc'!$H$19)^'Live Calc'!$E$19 -> 96.176042 | I5: 5 | J5: =IF(I5<>_xlfn.MINIFS('Draft Board'!$I$2:$I$61,'Draft Board'!$H$2:$H$61,"="&H5),0,IF(_xlfn.MINIFS('Draft Board'!$H$2:$H$61,'Draft Board'!$H$2:$H$61,">"&H5)=0,1,IF((_xlfn.MINIFS('Draft Board'!$H$2:$H$61,'Draft Board'!$H$2:$H$61,">"&H5)-H5)/_xlfn.MINIFS('Draft Board'!$H$2:$H$61,'Draft Board'!$H$2:$H$61,">"&H5)>0.08,1,0))) -> 0 | K5: =_xlfn.MINIFS('Draft Board'!$H$2:$H$61,'Draft Board'!$H$2:$H$61,">="&H5,'Draft Board'!$J$2:$J$61,1) -> 100.42961 | L5: =IF(I5<>_xlfn.MINIFS('Draft Board'!$I$2:$I$61,'Draft Board'!$H$2:$H$61,"="&H5),0,IF(OR(J5=1,IFERROR(FLOOR((K5-H5)/K5/0.25,1),0)<>IFERROR(FLOOR((K5-_xlfn.MINIFS('Draft Board'!$H$2:$H$61,'Draft Board'!$H$2:$H$61,">"&H5))/K5/0.25,1),0)),1,0)) -> 0 | M5: =ROUND(1+H5*'Live Calc'!$D$26,0) -> 14 | O5: =IF(N5<>"",N5,ROUND(M5*INDEX('Live Calc'!$G$33:$G$92,MATCH(G5,'Live Calc'!$A$33:$A$92,0))*'Live Calc'!$J$543,0)) -> 14 | Q5: Jonathan Taylor | R5: IND | S5: 257.54 | T5: 278.56 | U5: 299.58 | V5: =CHOOSE(MATCH(Setup!$B$7,{"STD","Half-PPR","PPR"},0),S5,T5,U5) -> 278.56 | W5: =COUNTIFS('Draft Board'!$X$2:$X$162,">="&X5,'Draft Board'!$AB$2:$AB$162,1) -> 2 | X5: =MAX(0,V5-'Live Calc'!$H$20)^'Live Calc'!$E$20 -> 482.38198 | Y5: 5 | Z5: =IF(Y5<>_xlfn.MINIFS('Draft Board'!$Y$2:$Y$162,'Draft Board'!$X$2:$X$162,"="&X5),0,IF(_xlfn.MINIFS('Draft Board'!$X$2:$X$162,'Draft Board'!$X$2:$X$162,">"&X5)=0,1,IF((_xlfn.MINIFS('Draft Board'!$X$2:$X$162,'Draft Board'!$X$2:$X$162,">"&X5)-X5)/_xlfn.MINIFS('Draft Board'!$X$2:$X$162,'Draft Board'!$X$2:$X$162,">"&X5)>0.08,1,0))) -> 0 | AA5: =_xlfn.MINIFS('Draft Board'!$X$2:$X$162,'Draft Board'!$X$2:$X$162,">="&X5,'Draft Board'!$Z$2:$Z$162,1) -> 506.13606 | AB5: =IF(Y5<>_xlfn.MINIFS('Draft Board'!$Y$2:$Y$162,'Draft Board'!$X$2:$X$162,"="&X5),0,IF(OR(Z5=1,IFERROR(FLOOR((AA5-X5)/AA5/0.25,1),0)<>IFERROR(FLOOR((AA5-_xlfn.MINIFS('Draft Board'!$X$2:$X$162,'Draft Board'!$X$2:$X$162,">"&X5))/AA5/0.25,1),0)),1,0)) -> 0 | AC5: =ROUND(1+X5*'Live Calc'!$D$27,0) -> 49 | AE5: =IF(AD5<>"",AD5,ROUND(AC5*INDEX('Live Calc'!$G$96:$G$256,MATCH(W5,'Live Calc'!$A$96:$A$256,0))*'Live Calc'!$J$543,0)) -> 49 | AG5: Amon-Ra St. Brown | AH5: DET | AI5: 194.69 | AJ5: 251.56 | AK5: 308.43 | AL5: =CHOOSE(MATCH(Setup!$B$7,{"STD","Half-PPR","PPR"},0),AI5,AJ5,AK5) -> 251.56 | AM5: =COUNTIFS('Draft Board'!$AN$2:$AN$192,">="&AN5,'Draft Board'!$AR$2:$AR$192,1) -> 3 | AN5: =MAX(0,AL5-'Live Calc'!$H$21)^'Live Calc'!$E$21 -> 1798.7462 | AO5: 5 | AP5: =IF(AO5<>_xlfn.MINIFS('Draft Board'!$AO$2:$AO$192,'Draft Board'!$AN$2:$AN$192,"="&AN5),0,IF(_xlfn.MINIFS('Draft Board'!$AN$2:$AN$192,'Draft Board'!$AN$2:$AN$192,">"&AN5)=0,1,IF((_xlfn.MINIFS('Draft Board'!$AN$2:$AN$192,'Draft Board'!$AN$2:$AN$192,">"&AN5)-AN5)/_xlfn.MINIFS('Draft Board'!$AN$2:$AN$192,'Draft Board'!$AN$2:$AN$192,">"&AN5)>0.08,1,0))) -> 1 | AQ5: =_xlfn.MINIFS('Draft Board'!$AN$2:$AN$192,'Draft Board'!$AN$2:$AN$192,">="&AN5,'Draft Board'!$AP$2:$AP$192,1) -> 1798.7462 | AR5: =IF(AO5<>_xlfn.MINIFS('Draft Board'!$AO$2:$AO$192,'Draft Board'!$AN$2:$AN$192,"="&AN5),0,IF(OR(AP5=1,IFERROR(FLOOR((AQ5-AN5)/AQ5/0.25,1),0)<>IFERROR(FLOOR((AQ5-_xlfn.MINIFS('Draft Board'!$AN$2:$AN$192,'Draft Board'!$AN$2:$AN$192,">"&AN5))/AQ5/0.25,1),0)),1,0)) -> 1 | AS5: =ROUND(1+AN5*'Live Calc'!$D$28,0) -> 50 | AU5: =IF(AT5<>"",AT5,ROUND(AS5*INDEX('Live Calc'!$G$260:$G$450,MATCH(AM5,'Live Calc'!$A$260:$A$450,0))*'Live Calc'!$J$543,0)) -> 50 | AW5: Tyler Warren | AX5: IND | AY5: 123.21 | AZ5: 162.92 | BA5: 202.63 | BB5: =CHOOSE(MATCH(Setup!$B$7,{"STD","Half-PPR","PPR"},0),AY5,AZ5,BA5) -> 162.92 | BC5: =COUNTIFS('Draft Board'!$BD$2:$BD$87,">="&BD5,'Draft Board'!$BH$2:$BH$87,1) -> 3 | BD5: =MAX(0,BB5-'Live Calc'!$H$22)^'Live Calc'!$E$22 -> 732.7429 | BE5: 5 | BF5: =IF(BE5<>_xlfn.MINIFS('Draft Board'!$BE$2:$BE$87,'Draft Board'!$BD$2:$BD$87,"="&BD5),0,IF(_xlfn.MINIFS('Draft Board'!$BD$2:$BD$87,'Draft Board'!$BD$2:$BD$87,">"&BD5)=0,1,IF((_xlfn.MINIFS('Draft Board'!$BD$2:$BD$87,'Draft Board'!$BD$2:$BD$87,">"&BD5)-BD5)/_xlfn.MINIFS('Draft Board'!$BD$2:$BD$87,'Draft Board'!$BD$2:$BD$87,">"&BD5)>0.08,1,0))) -> 1 | BG5: =_xlfn.MINIFS('Draft Board'!$BD$2:$BD$87,'Draft Board'!$BD$2:$BD$87,">="&BD5,'Draft Board'!$BF$2:$BF$87,1) -> 732.7429 | BH5: =IF(BE5<>_xlfn.MINIFS('Draft Board'!$BE$2:$BE$87,'Draft Board'!$BD$2:$BD$87,"="&BD5),0,IF(OR(BF5=1,IFERROR(FLOOR((BG5-BD5)/BG5/0.25,1),0)<>IFERROR(FLOOR((BG5-_xlfn.MINIFS('Draft Board'!$BD$2:$BD$87,'Draft Board'!$BD$2:$BD$87,">"&BD5))/BG5/0.25,1),0)),1,0)) -> 1 | BI5: =ROUND(1+BD5*'Live Calc'!$D$29,0) -> 18 | BK5: =IF(BJ5<>"",BJ5,ROUND(BI5*INDEX('Live Calc'!$G$454:$G$539,MATCH(BC5,'Live Calc'!$A$454:$A$539,0))*'Live Calc'!$J$543,0)) -> 18
A6: Jalen Hurts | B6: PHI | C6: 303.288 | D6: 303.288 | E6: 303.288 | F6: =CHOOSE(MATCH(Setup!$B$7,{"STD","Half-PPR","PPR"},0),C6,D6,E6) -> 303.288 | G6: =COUNTIFS('Draft Board'!$H$2:$H$61,">="&H6,'Draft Board'!$L$2:$L$61,1) -> 4 | H6: =MAX(0,F6-'Live Calc'!$H$19)^'Live Calc'!$E$19 -> 86.192152 | I6: 6 | J6: =IF(I6<>_xlfn.MINIFS('Draft Board'!$I$2:$I$61,'Draft Board'!$H$2:$H$61,"="&H6),0,IF(_xlfn.MINIFS('Draft Board'!$H$2:$H$61,'Draft Board'!$H$2:$H$61,">"&H6)=0,1,IF((_xlfn.MINIFS('Draft Board'!$H$2:$H$61,'Draft Board'!$H$2:$H$61,">"&H6)-H6)/_xlfn.MINIFS('Draft Board'!$H$2:$H$61,'Draft Board'!$H$2:$H$61,">"&H6)>0.08,1,0))) -> 1 | K6: =_xlfn.MINIFS('Draft Board'!$H$2:$H$61,'Draft Board'!$H$2:$H$61,">="&H6,'Draft Board'!$J$2:$J$61,1) -> 86.192152 | L6: =IF(I6<>_xlfn.MINIFS('Draft Board'!$I$2:$I$61,'Draft Board'!$H$2:$H$61,"="&H6),0,IF(OR(J6=1,IFERROR(FLOOR((K6-H6)/K6/0.25,1),0)<>IFERROR(FLOOR((K6-_xlfn.MINIFS('Draft Board'!$H$2:$H$61,'Draft Board'!$H$2:$H$61,">"&H6))/K6/0.25,1),0)),1,0)) -> 1 | M6: =ROUND(1+H6*'Live Calc'!$D$26,0) -> 13 | O6: =IF(N6<>"",N6,ROUND(M6*INDEX('Live Calc'!$G$33:$G$92,MATCH(G6,'Live Calc'!$A$33:$A$92,0))*'Live Calc'!$J$543,0)) -> 13 | Q6: James Cook III | R6: BUF | S6: 233.844 | T6: 248.9 | U6: 267.264 | V6: =CHOOSE(MATCH(Setup!$B$7,{"STD","Half-PPR","PPR"},0),S6,T6,U6) -> 248.9 | W6: =COUNTIFS('Draft Board'!$X$2:$X$162,">="&X6,'Draft Board'!$AB$2:$AB$162,1) -> 3 | X6: =MAX(0,V6-'Live Calc'!$H$20)^'Live Calc'!$E$20 -> 384.50933 | Y6: 6 | Z6: =IF(Y6<>_xlfn.MINIFS('Draft Board'!$Y$2:$Y$162,'Draft Board'!$X$2:$X$162,"="&X6),0,IF(_xlfn.MINIFS('Draft Board'!$X$2:$X$162,'Draft Board'!$X$2:$X$162,">"&X6)=0,1,IF((_xlfn.MINIFS('Draft Board'!$X$2:$X$162,'Draft Board'!$X$2:$X$162,">"&X6)-X6)/_xlfn.MINIFS('Draft Board'!$X$2:$X$162,'Draft Board'!$X$2:$X$162,">"&X6)>0.08,1,0))) -> 1 | AA6: =_xlfn.MINIFS('Draft Board'!$X$2:$X$162,'Draft Board'!$X$2:$X$162,">="&X6,'Draft Board'!$Z$2:$Z$162,1) -> 384.50933 | AB6: =IF(Y6<>_xlfn.MINIFS('Draft Board'!$Y$2:$Y$162,'Draft Board'!$X$2:$X$162,"="&X6),0,IF(OR(Z6=1,IFERROR(FLOOR((AA6-X6)/AA6/0.25,1),0)<>IFERROR(FLOOR((AA6-_xlfn.MINIFS('Draft Board'!$X$2:$X$162,'Draft Board'!$X$2:$X$162,">"&X6))/AA6/0.25,1),0)),1,0)) -> 1 | AC6: =ROUND(1+X6*'Live Calc'!$D$27,0) -> 39 | AE6: =IF(AD6<>"",AD6,ROUND(AC6*INDEX('Live Calc'!$G$96:$G$256,MATCH(W6,'Live Calc'!$A$96:$A$256,0))*'Live Calc'!$J$543,0)) -> 39 | AG6: CeeDee Lamb | AH6: DAL | AI6: 174.832 | AJ6: 222.998 | AK6: 271.24 | AL6: =CHOOSE(MATCH(Setup!$B$7,{"STD","Half-PPR","PPR"},0),AI6,AJ6,AK6) -> 222.998 | AM6: =COUNTIFS('Draft Board'!$AN$2:$AN$192,">="&AN6,'Draft Board'!$AR$2:$AR$192,1) -> 4 | AN6: =MAX(0,AL6-'Live Calc'!$H$21)^'Live Calc'!$E$21 -> 1303.7369 | AO6: 6 | AP6: =IF(AO6<>_xlfn.MINIFS('Draft Board'!$AO$2:$AO$192,'Draft Board'!$AN$2:$AN$192,"="&AN6),0,IF(_xlfn.MINIFS('Draft Board'!$AN$2:$AN$192,'Draft Board'!$AN$2:$AN$192,">"&AN6)=0,1,IF((_xlfn.MINIFS('Draft Board'!$AN$2:$AN$192,'Draft Board'!$AN$2:$AN$192,">"&AN6)-AN6)/_xlfn.MINIFS('Draft Board'!$AN$2:$AN$192,'Draft Board'!$AN$2:$AN$192,">"&AN6)>0.08,1,0))) -> 1 | AQ6: =_xlfn.MINIFS('Draft Board'!$AN$2:$AN$192,'Draft Board'!$AN$2:$AN$192,">="&AN6,'Draft Board'!$AP$2:$AP$192,1) -> 1303.7369 | AR6: =IF(AO6<>_xlfn.MINIFS('Draft Board'!$AO$2:$AO$192,'Draft Board'!$AN$2:$AN$192,"="&AN6),0,IF(OR(AP6=1,IFERROR(FLOOR((AQ6-AN6)/AQ6/0.25,1),0)<>IFERROR(FLOOR((AQ6-_xlfn.MINIFS('Draft Board'!$AN$2:$AN$192,'Draft Board'!$AN$2:$AN$192,">"&AN6))/AQ6/0.25,1),0)),1,0)) -> 1 | AS6: =ROUND(1+AN6*'Live Calc'!$D$28,0) -> 36 | AU6: =IF(AT6<>"",AT6,ROUND(AS6*INDEX('Live Calc'!$G$260:$G$450,MATCH(AM6,'Live Calc'!$A$260:$A$450,0))*'Live Calc'!$J$543,0)) -> 36 | AW6: Tucker Kraft | AX6: GB | AY6: 118.71 | AZ6: 149.94 | BA6: 181.58 | BB6: =CHOOSE(MATCH(Setup!$B$7,{"STD","Half-PPR","PPR"},0),AY6,AZ6,BA6) -> 149.94 | BC6: =COUNTIFS('Draft Board'!$BD$2:$BD$87,">="&BD6,'Draft Board'!$BH$2:$BH$87,1) -> 4 | BD6: =MAX(0,BB6-'Live Calc'!$H$22)^'Live Calc'!$E$22 -> 502.29507 | BE6: 6 | BF6: =IF(BE6<>_xlfn.MINIFS('Draft Board'!$BE$2:$BE$87,'Draft Board'!$BD$2:$BD$87,"="&BD6),0,IF(_xlfn.MINIFS('Draft Board'!$BD$2:$BD$87,'Draft Board'!$BD$2:$BD$87,">"&BD6)=0,1,IF((_xlfn.MINIFS('Draft Board'!$BD$2:$BD$87,'Draft Board'!$BD$2:$BD$87,">"&BD6)-BD6)/_xlfn.MINIFS('Draft Board'!$BD$2:$BD$87,'Draft Board'!$BD$2:$BD$87,">"&BD6)>0.08,1,0))) -> 1 | BG6: =_xlfn.MINIFS('Draft Board'!$BD$2:$BD$87,'Draft Board'!$BD$2:$BD$87,">="&BD6,'Draft Board'!$BF$2:$BF$87,1) -> 502.29507 | BH6: =IF(BE6<>_xlfn.MINIFS('Draft Board'!$BE$2:$BE$87,'Draft Board'!$BD$2:$BD$87,"="&BD6),0,IF(OR(BF6=1,IFERROR(FLOOR((BG6-BD6)/BG6/0.25,1),0)<>IFERROR(FLOOR((BG6-_xlfn.MINIFS('Draft Board'!$BD$2:$BD$87,'Draft Board'!$BD$2:$BD$87,">"&BD6))/BG6/0.25,1),0)),1,0)) -> 1 | BI6: =ROUND(1+BD6*'Live Calc'!$D$29,0) -> 13 | BK6: =IF(BJ6<>"",BJ6,ROUND(BI6*INDEX('Live Calc'!$G$454:$G$539,MATCH(BC6,'Live Calc'!$A$454:$A$539,0))*'Live Calc'!$J$543,0)) -> 13
A7: Joe Burrow | B7: CIN | C7: 301.932 | D7: 301.932 | E7: 301.932 | F7: =CHOOSE(MATCH(Setup!$B$7,{"STD","Half-PPR","PPR"},0),C7,D7,E7) -> 301.932 | G7: =COUNTIFS('Draft Board'!$H$2:$H$61,">="&H7,'Draft Board'!$L$2:$L$61,1) -> 4 | H7: =MAX(0,F7-'Live Calc'!$H$19)^'Live Calc'!$E$19 -> 82.783618 | I7: 7 | J7: =IF(I7<>_xlfn.MINIFS('Draft Board'!$I$2:$I$61,'Draft Board'!$H$2:$H$61,"="&H7),0,IF(_xlfn.MINIFS('Draft Board'!$H$2:$H$61,'Draft Board'!$H$2:$H$61,">"&H7)=0,1,IF((_xlfn.MINIFS('Draft Board'!$H$2:$H$61,'Draft Board'!$H$2:$H$61,">"&H7)-H7)/_xlfn.MINIFS('Draft Board'!$H$2:$H$61,'Draft Board'!$H$2:$H$61,">"&H7)>0.08,1,0))) -> 0 | K7: =_xlfn.MINIFS('Draft Board'!$H$2:$H$61,'Draft Board'!$H$2:$H$61,">="&H7,'Draft Board'!$J$2:$J$61,1) -> 86.192152 | L7: =IF(I7<>_xlfn.MINIFS('Draft Board'!$I$2:$I$61,'Draft Board'!$H$2:$H$61,"="&H7),0,IF(OR(J7=1,IFERROR(FLOOR((K7-H7)/K7/0.25,1),0)<>IFERROR(FLOOR((K7-_xlfn.MINIFS('Draft Board'!$H$2:$H$61,'Draft Board'!$H$2:$H$61,">"&H7))/K7/0.25,1),0)),1,0)) -> 0 | M7: =ROUND(1+H7*'Live Calc'!$D$26,0) -> 12 | O7: =IF(N7<>"",N7,ROUND(M7*INDEX('Live Calc'!$G$33:$G$92,MATCH(G7,'Live Calc'!$A$33:$A$92,0))*'Live Calc'!$J$543,0)) -> 12 | Q7: Ashton Jeanty | R7: LV | S7: 214.39 | T7: 242.978 | U7: 270.786 | V7: =CHOOSE(MATCH(Setup!$B$7,{"STD","Half-PPR","PPR"},0),S7,T7,U7) -> 242.978 | W7: =COUNTIFS('Draft Board'!$X$2:$X$162,">="&X7,'Draft Board'!$AB$2:$AB$162,1) -> 3 | X7: =MAX(0,V7-'Live Calc'!$H$20)^'Live Calc'!$E$20 -> 365.42664 | Y7: 7 | Z7: =IF(Y7<>_xlfn.MINIFS('Draft Board'!$Y$2:$Y$162,'Draft Board'!$X$2:$X$162,"="&X7),0,IF(_xlfn.MINIFS('Draft Board'!$X$2:$X$162,'Draft Board'!$X$2:$X$162,">"&X7)=0,1,IF((_xlfn.MINIFS('Draft Board'!$X$2:$X$162,'Draft Board'!$X$2:$X$162,">"&X7)-X7)/_xlfn.MINIFS('Draft Board'!$X$2:$X$162,'Draft Board'!$X$2:$X$162,">"&X7)>0.08,1,0))) -> 0 | AA7: =_xlfn.MINIFS('Draft Board'!$X$2:$X$162,'Draft Board'!$X$2:$X$162,">="&X7,'Draft Board'!$Z$2:$Z$162,1) -> 384.50933 | AB7: =IF(Y7<>_xlfn.MINIFS('Draft Board'!$Y$2:$Y$162,'Draft Board'!$X$2:$X$162,"="&X7),0,IF(OR(Z7=1,IFERROR(FLOOR((AA7-X7)/AA7/0.25,1),0)<>IFERROR(FLOOR((AA7-_xlfn.MINIFS('Draft Board'!$X$2:$X$162,'Draft Board'!$X$2:$X$162,">"&X7))/AA7/0.25,1),0)),1,0)) -> 0 | AC7: =ROUND(1+X7*'Live Calc'!$D$27,0) -> 37 | AE7: =IF(AD7<>"",AD7,ROUND(AC7*INDEX('Live Calc'!$G$96:$G$256,MATCH(W7,'Live Calc'!$A$96:$A$256,0))*'Live Calc'!$J$543,0)) -> 37 | AG7: Drake London | AH7: ATL | AI7: 172.582 | AJ7: 222.586 | AK7: 270.95 | AL7: =CHOOSE(MATCH(Setup!$B$7,{"STD","Half-PPR","PPR"},0),AI7,AJ7,AK7) -> 222.586 | AM7: =COUNTIFS('Draft Board'!$AN$2:$AN$192,">="&AN7,'Draft Board'!$AR$2:$AR$192,1) -> 4 | AN7: =MAX(0,AL7-'Live Calc'!$H$21)^'Live Calc'!$E$21 -> 1296.9915 | AO7: 7 | AP7: =IF(AO7<>_xlfn.MINIFS('Draft Board'!$AO$2:$AO$192,'Draft Board'!$AN$2:$AN$192,"="&AN7),0,IF(_xlfn.MINIFS('Draft Board'!$AN$2:$AN$192,'Draft Board'!$AN$2:$AN$192,">"&AN7)=0,1,IF((_xlfn.MINIFS('Draft Board'!$AN$2:$AN$192,'Draft Board'!$AN$2:$AN$192,">"&AN7)-AN7)/_xlfn.MINIFS('Draft Board'!$AN$2:$AN$192,'Draft Board'!$AN$2:$AN$192,">"&AN7)>0.08,1,0))) -> 0 | AQ7: =_xlfn.MINIFS('Draft Board'!$AN$2:$AN$192,'Draft Board'!$AN$2:$AN$192,">="&AN7,'Draft Board'!$AP$2:$AP$192,1) -> 1303.7369 | AR7: =IF(AO7<>_xlfn.MINIFS('Draft Board'!$AO$2:$AO$192,'Draft Board'!$AN$2:$AN$192,"="&AN7),0,IF(OR(AP7=1,IFERROR(FLOOR((AQ7-AN7)/AQ7/0.25,1),0)<>IFERROR(FLOOR((AQ7-_xlfn.MINIFS('Draft Board'!$AN$2:$AN$192,'Draft Board'!$AN$2:$AN$192,">"&AN7))/AQ7/0.25,1),0)),1,0)) -> 0 | AS7: =ROUND(1+AN7*'Live Calc'!$D$28,0) -> 36 | AU7: =IF(AT7<>"",AT7,ROUND(AS7*INDEX('Live Calc'!$G$260:$G$450,MATCH(AM7,'Live Calc'!$A$260:$A$450,0))*'Live Calc'!$J$543,0)) -> 36 | AW7: Harold Fannin Jr. | AX7: CLE | AY7: 110.502 | AZ7: 148.29 | BA7: 184.72 | BB7: =CHOOSE(MATCH(Setup!$B$7,{"STD","Half-PPR","PPR"},0),AY7,AZ7,BA7) -> 148.29 | BC7: =COUNTIFS('Draft Board'!$BD$2:$BD$87,">="&BD7,'Draft Board'!$BH$2:$BH$87,1) -> 4 | BD7: =MAX(0,BB7-'Live Calc'!$H$22)^'Live Calc'!$E$22 -> 475.37897 | BE7: 7 | BF7: =IF(BE7<>_xlfn.MINIFS('Draft Board'!$BE$2:$BE$87,'Draft Board'!$BD$2:$BD$87,"="&BD7),0,IF(_xlfn.MINIFS('Draft Board'!$BD$2:$BD$87,'Draft Board'!$BD$2:$BD$87,">"&BD7)=0,1,IF((_xlfn.MINIFS('Draft Board'!$BD$2:$BD$87,'Draft Board'!$BD$2:$BD$87,">"&BD7)-BD7)/_xlfn.MINIFS('Draft Board'!$BD$2:$BD$87,'Draft Board'!$BD$2:$BD$87,">"&BD7)>0.08,1,0))) -> 0 | BG7: =_xlfn.MINIFS('Draft Board'!$BD$2:$BD$87,'Draft Board'!$BD$2:$BD$87,">="&BD7,'Draft Board'!$BF$2:$BF$87,1) -> 502.29507 | BH7: =IF(BE7<>_xlfn.MINIFS('Draft Board'!$BE$2:$BE$87,'Draft Board'!$BD$2:$BD$87,"="&BD7),0,IF(OR(BF7=1,IFERROR(FLOOR((BG7-BD7)/BG7/0.25,1),0)<>IFERROR(FLOOR((BG7-_xlfn.MINIFS('Draft Board'!$BD$2:$BD$87,'Draft Board'!$BD$2:$BD$87,">"&BD7))/BG7/0.25,1),0)),1,0)) -> 0 | BI7: =ROUND(1+BD7*'Live Calc'!$D$29,0) -> 12 | BK7: =IF(BJ7<>"",BJ7,ROUND(BI7*INDEX('Live Calc'!$G$454:$G$539,MATCH(BC7,'Live Calc'!$A$454:$A$539,0))*'Live Calc'!$J$543,0)) -> 12
A8: Caleb Williams | B8: CHI | C8: 292.46 | D8: 292.244 | E8: 292.244 | F8: =CHOOSE(MATCH(Setup!$B$7,{"STD","Half-PPR","PPR"},0),C8,D8,E8) -> 292.244 | G8: =COUNTIFS('Draft Board'!$H$2:$H$61,">="&H8,'Draft Board'!$L$2:$L$61,1) -> 5 | H8: =MAX(0,F8-'Live Calc'!$H$19)^'Live Calc'!$E$19 -> 59.14997 | I8: 8 | J8: =IF(I8<>_xlfn.MINIFS('Draft Board'!$I$2:$I$61,'Draft Board'!$H$2:$H$61,"="&H8),0,IF(_xlfn.MINIFS('Draft Board'!$H$2:$H$61,'Draft Board'!$H$2:$H$61,">"&H8)=0,1,IF((_xlfn.MINIFS('Draft Board'!$H$2:$H$61,'Draft Board'!$H$2:$H$61,">"&H8)-H8)/_xlfn.MINIFS('Draft Board'!$H$2:$H$61,'Draft Board'!$H$2:$H$61,">"&H8)>0.08,1,0))) -> 1 | K8: =_xlfn.MINIFS('Draft Board'!$H$2:$H$61,'Draft Board'!$H$2:$H$61,">="&H8,'Draft Board'!$J$2:$J$61,1) -> 59.14997 | L8: =IF(I8<>_xlfn.MINIFS('Draft Board'!$I$2:$I$61,'Draft Board'!$H$2:$H$61,"="&H8),0,IF(OR(J8=1,IFERROR(FLOOR((K8-H8)/K8/0.25,1),0)<>IFERROR(FLOOR((K8-_xlfn.MINIFS('Draft Board'!$H$2:$H$61,'Draft Board'!$H$2:$H$61,">"&H8))/K8/0.25,1),0)),1,0)) -> 1 | M8: =ROUND(1+H8*'Live Calc'!$D$26,0) -> 9 | O8: =IF(N8<>"",N8,ROUND(M8*INDEX('Live Calc'!$G$33:$G$92,MATCH(G8,'Live Calc'!$A$33:$A$92,0))*'Live Calc'!$J$543,0)) -> 9 | Q8: Derrick Henry | R8: BAL | S8: 234.756 | T8: 241.416 | U8: 250.846 | V8: =CHOOSE(MATCH(Setup!$B$7,{"STD","Half-PPR","PPR"},0),S8,T8,U8) -> 241.416 | W8: =COUNTIFS('Draft Board'!$X$2:$X$162,">="&X8,'Draft Board'!$AB$2:$AB$162,1) -> 3 | X8: =MAX(0,V8-'Live Calc'!$H$20)^'Live Calc'!$E$20 -> 360.42057 | Y8: 8 | Z8: =IF(Y8<>_xlfn.MINIFS('Draft Board'!$Y$2:$Y$162,'Draft Board'!$X$2:$X$162,"="&X8),0,IF(_xlfn.MINIFS('Draft Board'!$X$2:$X$162,'Draft Board'!$X$2:$X$162,">"&X8)=0,1,IF((_xlfn.MINIFS('Draft Board'!$X$2:$X$162,'Draft Board'!$X$2:$X$162,">"&X8)-X8)/_xlfn.MINIFS('Draft Board'!$X$2:$X$162,'Draft Board'!$X$2:$X$162,">"&X8)>0.08,1,0))) -> 0 | AA8: =_xlfn.MINIFS('Draft Board'!$X$2:$X$162,'Draft Board'!$X$2:$X$162,">="&X8,'Draft Board'!$Z$2:$Z$162,1) -> 384.50933 | AB8: =IF(Y8<>_xlfn.MINIFS('Draft Board'!$Y$2:$Y$162,'Draft Board'!$X$2:$X$162,"="&X8),0,IF(OR(Z8=1,IFERROR(FLOOR((AA8-X8)/AA8/0.25,1),0)<>IFERROR(FLOOR((AA8-_xlfn.MINIFS('Draft Board'!$X$2:$X$162,'Draft Board'!$X$2:$X$162,">"&X8))/AA8/0.25,1),0)),1,0)) -> 0 | AC8: =ROUND(1+X8*'Live Calc'!$D$27,0) -> 37 | AE8: =IF(AD8<>"",AD8,ROUND(AC8*INDEX('Live Calc'!$G$96:$G$256,MATCH(W8,'Live Calc'!$A$96:$A$256,0))*'Live Calc'!$J$543,0)) -> 37 | AG8: Justin Jefferson | AH8: MIN | AI8: 173.762 | AJ8: 222.366 | AK8: 270.9 | AL8: =CHOOSE(MATCH(Setup!$B$7,{"STD","Half-PPR","PPR"},0),AI8,AJ8,AK8) -> 222.366 | AM8: =COUNTIFS('Draft Board'!$AN$2:$AN$192,">="&AN8,'Draft Board'!$AR$2:$AR$192,1) -> 4 | AN8: =MAX(0,AL8-'Live Calc'!$H$21)^'Live Calc'!$E$21 -> 1293.3943 | AO8: 8 | AP8: =IF(AO8<>_xlfn.MINIFS('Draft Board'!$AO$2:$AO$192,'Draft Board'!$AN$2:$AN$192,"="&AN8),0,IF(_xlfn.MINIFS('Draft Board'!$AN$2:$AN$192,'Draft Board'!$AN$2:$AN$192,">"&AN8)=0,1,IF((_xlfn.MINIFS('Draft Board'!$AN$2:$AN$192,'Draft Board'!$AN$2:$AN$192,">"&AN8)-AN8)/_xlfn.MINIFS('Draft Board'!$AN$2:$AN$192,'Draft Board'!$AN$2:$AN$192,">"&AN8)>0.08,1,0))) -> 0 | AQ8: =_xlfn.MINIFS('Draft Board'!$AN$2:$AN$192,'Draft Board'!$AN$2:$AN$192,">="&AN8,'Draft Board'!$AP$2:$AP$192,1) -> 1303.7369 | AR8: =IF(AO8<>_xlfn.MINIFS('Draft Board'!$AO$2:$AO$192,'Draft Board'!$AN$2:$AN$192,"="&AN8),0,IF(OR(AP8=1,IFERROR(FLOOR((AQ8-AN8)/AQ8/0.25,1),0)<>IFERROR(FLOOR((AQ8-_xlfn.MINIFS('Draft Board'!$AN$2:$AN$192,'Draft Board'!$AN$2:$AN$192,">"&AN8))/AQ8/0.25,1),0)),1,0)) -> 0 | AS8: =ROUND(1+AN8*'Live Calc'!$D$28,0) -> 36 | AU8: =IF(AT8<>"",AT8,ROUND(AS8*INDEX('Live Calc'!$G$260:$G$450,MATCH(AM8,'Live Calc'!$A$260:$A$450,0))*'Live Calc'!$J$543,0)) -> 36 | AW8: Kyle Pitts Sr. | AX8: ATL | AY8: 108.126 | AZ8: 143.92 | BA8: 179.724 | BB8: =CHOOSE(MATCH(Setup!$B$7,{"STD","Half-PPR","PPR"},0),AY8,AZ8,BA8) -> 143.92 | BC8: =COUNTIFS('Draft Board'!$BD$2:$BD$87,">="&BD8,'Draft Board'!$BH$2:$BH$87,1) -> 5 | BD8: =MAX(0,BB8-'Live Calc'!$H$22)^'Live Calc'!$E$22 -> 406.81809 | BE8: 8 | BF8: =IF(BE8<>_xlfn.MINIFS('Draft Board'!$BE$2:$BE$87,'Draft Board'!$BD$2:$BD$87,"="&BD8),0,IF(_xlfn.MINIFS('Draft Board'!$BD$2:$BD$87,'Draft Board'!$BD$2:$BD$87,">"&BD8)=0,1,IF((_xlfn.MINIFS('Draft Board'!$BD$2:$BD$87,'Draft Board'!$BD$2:$BD$87,">"&BD8)-BD8)/_xlfn.MINIFS('Draft Board'!$BD$2:$BD$87,'Draft Board'!$BD$2:$BD$87,">"&BD8)>0.08,1,0))) -> 1 | BG8: =_xlfn.MINIFS('Draft Board'!$BD$2:$BD$87,'Draft Board'!$BD$2:$BD$87,">="&BD8,'Draft Board'!$BF$2:$BF$87,1) -> 406.81809 | BH8: =IF(BE8<>_xlfn.MINIFS('Draft Board'!$BE$2:$BE$87,'Draft Board'!$BD$2:$BD$87,"="&BD8),0,IF(OR(BF8=1,IFERROR(FLOOR((BG8-BD8)/BG8/0.25,1),0)<>IFERROR(FLOOR((BG8-_xlfn.MINIFS('Draft Board'!$BD$2:$BD$87,'Draft Board'!$BD$2:$BD$87,">"&BD8))/BG8/0.25,1),0)),1,0)) -> 1 | BI8: =ROUND(1+BD8*'Live Calc'!$D$29,0) -> 11 | BK8: =IF(BJ8<>"",BJ8,ROUND(BI8*INDEX('Live Calc'!$G$454:$G$539,MATCH(BC8,'Live Calc'!$A$454:$A$539,0))*'Live Calc'!$J$543,0)) -> 11
A9: Trevor Lawrence | B9: JAC | C9: 291.206 | D9: 291.422 | E9: 291.422 | F9: =CHOOSE(MATCH(Setup!$B$7,{"STD","Half-PPR","PPR"},0),C9,D9,E9) -> 291.422 | G9: =COUNTIFS('Draft Board'!$H$2:$H$61,">="&H9,'Draft Board'!$L$2:$L$61,1) -> 5 | H9: =MAX(0,F9-'Live Calc'!$H$19)^'Live Calc'!$E$19 -> 57.208293 | I9: 9 | J9: =IF(I9<>_xlfn.MINIFS('Draft Board'!$I$2:$I$61,'Draft Board'!$H$2:$H$61,"="&H9),0,IF(_xlfn.MINIFS('Draft Board'!$H$2:$H$61,'Draft Board'!$H$2:$H$61,">"&H9)=0,1,IF((_xlfn.MINIFS('Draft Board'!$H$2:$H$61,'Draft Board'!$H$2:$H$61,">"&H9)-H9)/_xlfn.MINIFS('Draft Board'!$H$2:$H$61,'Draft Board'!$H$2:$H$61,">"&H9)>0.08,1,0))) -> 0 | K9: =_xlfn.MINIFS('Draft Board'!$H$2:$H$61,'Draft Board'!$H$2:$H$61,">="&H9,'Draft Board'!$J$2:$J$61,1) -> 59.14997 | L9: =IF(I9<>_xlfn.MINIFS('Draft Board'!$I$2:$I$61,'Draft Board'!$H$2:$H$61,"="&H9),0,IF(OR(J9=1,IFERROR(FLOOR((K9-H9)/K9/0.25,1),0)<>IFERROR(FLOOR((K9-_xlfn.MINIFS('Draft Board'!$H$2:$H$61,'Draft Board'!$H$2:$H$61,">"&H9))/K9/0.25,1),0)),1,0)) -> 0 | M9: =ROUND(1+H9*'Live Calc'!$D$26,0) -> 9 | O9: =IF(N9<>"",N9,ROUND(M9*INDEX('Live Calc'!$G$33:$G$92,MATCH(G9,'Live Calc'!$A$33:$A$92,0))*'Live Calc'!$J$543,0)) -> 9 | Q9: Saquon Barkley | R9: PHI | S9: 214.94 | T9: 238.084 | U9: 259.092 | V9: =CHOOSE(MATCH(Setup!$B$7,{"STD","Half-PPR","PPR"},0),S9,T9,U9) -> 238.084 | W9: =COUNTIFS('Draft Board'!$X$2:$X$162,">="&X9,'Draft Board'!$AB$2:$AB$162,1) -> 3 | X9: =MAX(0,V9-'Live Calc'!$H$20)^'Live Calc'!$E$20 -> 349.78057 | Y9: 9 | Z9: =IF(Y9<>_xlfn.MINIFS('Draft Board'!$Y$2:$Y$162,'Draft Board'!$X$2:$X$162,"="&X9),0,IF(_xlfn.MINIFS('Draft Board'!$X$2:$X$162,'Draft Board'!$X$2:$X$162,">"&X9)=0,1,IF((_xlfn.MINIFS('Draft Board'!$X$2:$X$162,'Draft Board'!$X$2:$X$162,">"&X9)-X9)/_xlfn.MINIFS('Draft Board'!$X$2:$X$162,'Draft Board'!$X$2:$X$162,">"&X9)>0.08,1,0))) -> 0 | AA9: =_xlfn.MINIFS('Draft Board'!$X$2:$X$162,'Draft Board'!$X$2:$X$162,">="&X9,'Draft Board'!$Z$2:$Z$162,1) -> 384.50933 | AB9: =IF(Y9<>_xlfn.MINIFS('Draft Board'!$Y$2:$Y$162,'Draft Board'!$X$2:$X$162,"="&X9),0,IF(OR(Z9=1,IFERROR(FLOOR((AA9-X9)/AA9/0.25,1),0)<>IFERROR(FLOOR((AA9-_xlfn.MINIFS('Draft Board'!$X$2:$X$162,'Draft Board'!$X$2:$X$162,">"&X9))/AA9/0.25,1),0)),1,0)) -> 0 | AC9: =ROUND(1+X9*'Live Calc'!$D$27,0) -> 36 | AE9: =IF(AD9<>"",AD9,ROUND(AC9*INDEX('Live Calc'!$G$96:$G$256,MATCH(W9,'Live Calc'!$A$96:$A$256,0))*'Live Calc'!$J$543,0)) -> 36 | AG9: Nico Collins | AH9: HOU | AI9: 170.644 | AJ9: 209.566 | AK9: 251.89 | AL9: =CHOOSE(MATCH(Setup!$B$7,{"STD","Half-PPR","PPR"},0),AI9,AJ9,AK9) -> 209.566 | AM9: =COUNTIFS('Draft Board'!$AN$2:$AN$192,">="&AN9,'Draft Board'!$AR$2:$AR$192,1) -> 5 | AN9: =MAX(0,AL9-'Live Calc'!$H$21)^'Live Calc'!$E$21 -> 1089.9472 | AO9: 9 | AP9: =IF(AO9<>_xlfn.MINIFS('Draft Board'!$AO$2:$AO$192,'Draft Board'!$AN$2:$AN$192,"="&AN9),0,IF(_xlfn.MINIFS('Draft Board'!$AN$2:$AN$192,'Draft Board'!$AN$2:$AN$192,">"&AN9)=0,1,IF((_xlfn.MINIFS('Draft Board'!$AN$2:$AN$192,'Draft Board'!$AN$2:$AN$192,">"&AN9)-AN9)/_xlfn.MINIFS('Draft Board'!$AN$2:$AN$192,'Draft Board'!$AN$2:$AN$192,">"&AN9)>0.08,1,0))) -> 1 | AQ9: =_xlfn.MINIFS('Draft Board'!$AN$2:$AN$192,'Draft Board'!$AN$2:$AN$192,">="&AN9,'Draft Board'!$AP$2:$AP$192,1) -> 1089.9472 | AR9: =IF(AO9<>_xlfn.MINIFS('Draft Board'!$AO$2:$AO$192,'Draft Board'!$AN$2:$AN$192,"="&AN9),0,IF(OR(AP9=1,IFERROR(FLOOR((AQ9-AN9)/AQ9/0.25,1),0)<>IFERROR(FLOOR((AQ9-_xlfn.MINIFS('Draft Board'!$AN$2:$AN$192,'Draft Board'!$AN$2:$AN$192,">"&AN9))/AQ9/0.25,1),0)),1,0)) -> 1 | AS9: =ROUND(1+AN9*'Live Calc'!$D$28,0) -> 30 | AU9: =IF(AT9<>"",AT9,ROUND(AS9*INDEX('Live Calc'!$G$260:$G$450,MATCH(AM9,'Live Calc'!$A$260:$A$450,0))*'Live Calc'!$J$543,0)) -> 30 | AW9: Sam LaPorta | AX9: DET | AY9: 109.53 | AZ9: 143.28 | BA9: 178.096 | BB9: =CHOOSE(MATCH(Setup!$B$7,{"STD","Half-PPR","PPR"},0),AY9,AZ9,BA9) -> 143.28 | BC9: =COUNTIFS('Draft Board'!$BD$2:$BD$87,">="&BD9,'Draft Board'!$BH$2:$BH$87,1) -> 5 | BD9: =MAX(0,BB9-'Live Calc'!$H$22)^'Live Calc'!$E$22 -> 397.11599 | BE9: 9 | BF9: =IF(BE9<>_xlfn.MINIFS('Draft Board'!$BE$2:$BE$87,'Draft Board'!$BD$2:$BD$87,"="&BD9),0,IF(_xlfn.MINIFS('Draft Board'!$BD$2:$BD$87,'Draft Board'!$BD$2:$BD$87,">"&BD9)=0,1,IF((_xlfn.MINIFS('Draft Board'!$BD$2:$BD$87,'Draft Board'!$BD$2:$BD$87,">"&BD9)-BD9)/_xlfn.MINIFS('Draft Board'!$BD$2:$BD$87,'Draft Board'!$BD$2:$BD$87,">"&BD9)>0.08,1,0))) -> 0 | BG9: =_xlfn.MINIFS('Draft Board'!$BD$2:$BD$87,'Draft Board'!$BD$2:$BD$87,">="&BD9,'Draft Board'!$BF$2:$BF$87,1) -> 406.81809 | BH9: =IF(BE9<>_xlfn.MINIFS('Draft Board'!$BE$2:$BE$87,'Draft Board'!$BD$2:$BD$87,"="&BD9),0,IF(OR(BF9=1,IFERROR(FLOOR((BG9-BD9)/BG9/0.25,1),0)<>IFERROR(FLOOR((BG9-_xlfn.MINIFS('Draft Board'!$BD$2:$BD$87,'Draft Board'!$BD$2:$BD$87,">"&BD9))/BG9/0.25,1),0)),1,0)) -> 0 | BI9: =ROUND(1+BD9*'Live Calc'!$D$29,0) -> 10 | BK9: =IF(BJ9<>"",BJ9,ROUND(BI9*INDEX('Live Calc'!$G$454:$G$539,MATCH(BC9,'Live Calc'!$A$454:$A$539,0))*'Live Calc'!$J$543,0)) -> 10
A10: Dak Prescott | B10: DAL | C10: 291.104 | D10: 290.28 | E10: 290.28 | F10: =CHOOSE(MATCH(Setup!$B$7,{"STD","Half-PPR","PPR"},0),C10,D10,E10) -> 290.28 | G10: =COUNTIFS('Draft Board'!$H$2:$H$61,">="&H10,'Draft Board'!$L$2:$L$61,1) -> 5 | H10: =MAX(0,F10-'Live Calc'!$H$19)^'Live Calc'!$E$19 -> 54.528916 | I10: 10 | J10: =IF(I10<>_xlfn.MINIFS('Draft Board'!$I$2:$I$61,'Draft Board'!$H$2:$H$61,"="&H10),0,IF(_xlfn.MINIFS('Draft Board'!$H$2:$H$61,'Draft Board'!$H$2:$H$61,">"&H10)=0,1,IF((_xlfn.MINIFS('Draft Board'!$H$2:$H$61,'Draft Board'!$H$2:$H$61,">"&H10)-H10)/_xlfn.MINIFS('Draft Board'!$H$2:$H$61,'Draft Board'!$H$2:$H$61,">"&H10)>0.08,1,0))) -> 0 | K10: =_xlfn.MINIFS('Draft Board'!$H$2:$H$61,'Draft Board'!$H$2:$H$61,">="&H10,'Draft Board'!$J$2:$J$61,1) -> 59.14997 | L10: =IF(I10<>_xlfn.MINIFS('Draft Board'!$I$2:$I$61,'Draft Board'!$H$2:$H$61,"="&H10),0,IF(OR(J10=1,IFERROR(FLOOR((K10-H10)/K10/0.25,1),0)<>IFERROR(FLOOR((K10-_xlfn.MINIFS('Draft Board'!$H$2:$H$61,'Draft Board'!$H$2:$H$61,">"&H10))/K10/0.25,1),0)),1,0)) -> 0 | M10: =ROUND(1+H10*'Live Calc'!$D$26,0) -> 8 | O10: =IF(N10<>"",N10,ROUND(M10*INDEX('Live Calc'!$G$33:$G$92,MATCH(G10,'Live Calc'!$A$33:$A$92,0))*'Live Calc'!$J$543,0)) -> 8 | Q10: Chase Brown | R10: CIN | S10: 203.41 | T10: 234.35 | U10: 261.158 | V10: =CHOOSE(MATCH(Setup!$B$7,{"STD","Half-PPR","PPR"},0),S10,T10,U10) -> 234.35 | W10: =COUNTIFS('Draft Board'!$X$2:$X$162,">="&X10,'Draft Board'!$AB$2:$AB$162,1) -> 3 | X10: =MAX(0,V10-'Live Calc'!$H$20)^'Live Calc'!$E$20 -> 337.9207 | Y10: 10 | Z10: =IF(Y10<>_xlfn.MINIFS('Draft Board'!$Y$2:$Y$162,'Draft Board'!$X$2:$X$162,"="&X10),0,IF(_xlfn.MINIFS('Draft Board'!$X$2:$X$162,'Draft Board'!$X$2:$X$162,">"&X10)=0,1,IF((_xlfn.MINIFS('Draft Board'!$X$2:$X$162,'Draft Board'!$X$2:$X$162,">"&X10)-X10)/_xlfn.MINIFS('Draft Board'!$X$2:$X$162,'Draft Board'!$X$2:$X$162,">"&X10)>0.08,1,0))) -> 0 | AA10: =_xlfn.MINIFS('Draft Board'!$X$2:$X$162,'Draft Board'!$X$2:$X$162,">="&X10,'Draft Board'!$Z$2:$Z$162,1) -> 384.50933 | AB10: =IF(Y10<>_xlfn.MINIFS('Draft Board'!$Y$2:$Y$162,'Draft Board'!$X$2:$X$162,"="&X10),0,IF(OR(Z10=1,IFERROR(FLOOR((AA10-X10)/AA10/0.25,1),0)<>IFERROR(FLOOR((AA10-_xlfn.MINIFS('Draft Board'!$X$2:$X$162,'Draft Board'!$X$2:$X$162,">"&X10))/AA10/0.25,1),0)),1,0)) -> 0 | AC10: =ROUND(1+X10*'Live Calc'!$D$27,0) -> 34 | AE10: =IF(AD10<>"",AD10,ROUND(AC10*INDEX('Live Calc'!$G$96:$G$256,MATCH(W10,'Live Calc'!$A$96:$A$256,0))*'Live Calc'!$J$543,0)) -> 34 | AG10: A.J. Brown | AH10: NE | AI10: 164.272 | AJ10: 208.164 | AK10: 251.772 | AL10: =CHOOSE(MATCH(Setup!$B$7,{"STD","Half-PPR","PPR"},0),AI10,AJ10,AK10) -> 208.164 | AM10: =COUNTIFS('Draft Board'!$AN$2:$AN$192,">="&AN10,'Draft Board'!$AR$2:$AR$192,1) -> 5 | AN10: =MAX(0,AL10-'Live Calc'!$H$21)^'Live Calc'!$E$21 -> 1068.3764 | AO10: 10 | AP10: =IF(AO10<>_xlfn.MINIFS('Draft Board'!$AO$2:$AO$192,'Draft Board'!$AN$2:$AN$192,"="&AN10),0,IF(_xlfn.MINIFS('Draft Board'!$AN$2:$AN$192,'Draft Board'!$AN$2:$AN$192,">"&AN10)=0,1,IF((_xlfn.MINIFS('Draft Board'!$AN$2:$AN$192,'Draft Board'!$AN$2:$AN$192,">"&AN10)-AN10)/_xlfn.MINIFS('Draft Board'!$AN$2:$AN$192,'Draft Board'!$AN$2:$AN$192,">"&AN10)>0.08,1,0))) -> 0 | AQ10: =_xlfn.MINIFS('Draft Board'!$AN$2:$AN$192,'Draft Board'!$AN$2:$AN$192,">="&AN10,'Draft Board'!$AP$2:$AP$192,1) -> 1089.9472 | AR10: =IF(AO10<>_xlfn.MINIFS('Draft Board'!$AO$2:$AO$192,'Draft Board'!$AN$2:$AN$192,"="&AN10),0,IF(OR(AP10=1,IFERROR(FLOOR((AQ10-AN10)/AQ10/0.25,1),0)<>IFERROR(FLOOR((AQ10-_xlfn.MINIFS('Draft Board'!$AN$2:$AN$192,'Draft Board'!$AN$2:$AN$192,">"&AN10))/AQ10/0.25,1),0)),1,0)) -> 0 | AS10: =ROUND(1+AN10*'Live Calc'!$D$28,0) -> 30 | AU10: =IF(AT10<>"",AT10,ROUND(AS10*INDEX('Live Calc'!$G$260:$G$450,MATCH(AM10,'Live Calc'!$A$260:$A$450,0))*'Live Calc'!$J$543,0)) -> 30 | AW10: George Kittle | AX10: SF | AY10: 108.362 | AZ10: 140.57 | BA10: 173.088 | BB10: =CHOOSE(MATCH(Setup!$B$7,{"STD","Half-PPR","PPR"},0),AY10,AZ10,BA10) -> 140.57 | BC10: =COUNTIFS('Draft Board'!$BD$2:$BD$87,">="&BD10,'Draft Board'!$BH$2:$BH$87,1) -> 6 | BD10: =MAX(0,BB10-'Live Calc'!$H$22)^'Live Calc'!$E$22 -> 357.01637 | BE10: 10 | BF10: =IF(BE10<>_xlfn.MINIFS('Draft Board'!$BE$2:$BE$87,'Draft Board'!$BD$2:$BD$87,"="&BD10),0,IF(_xlfn.MINIFS('Draft Board'!$BD$2:$BD$87,'Draft Board'!$BD$2:$BD$87,">"&BD10)=0,1,IF((_xlfn.MINIFS('Draft Board'!$BD$2:$BD$87,'Draft Board'!$BD$2:$BD$87,">"&BD10)-BD10)/_xlfn.MINIFS('Draft Board'!$BD$2:$BD$87,'Draft Board'!$BD$2:$BD$87,">"&BD10)>0.08,1,0))) -> 1 | BG10: =_xlfn.MINIFS('Draft Board'!$BD$2:$BD$87,'Draft Board'!$BD$2:$BD$87,">="&BD10,'Draft Board'!$BF$2:$BF$87,1) -> 357.01637 | BH10: =IF(BE10<>_xlfn.MINIFS('Draft Board'!$BE$2:$BE$87,'Draft Board'!$BD$2:$BD$87,"="&BD10),0,IF(OR(BF10=1,IFERROR(FLOOR((BG10-BD10)/BG10/0.25,1),0)<>IFERROR(FLOOR((BG10-_xlfn.MINIFS('Draft Board'!$BD$2:$BD$87,'Draft Board'!$BD$2:$BD$87,">"&BD10))/BG10/0.25,1),0)),1,0)) -> 1 | BI10: =ROUND(1+BD10*'Live Calc'!$D$29,0) -> 9 | BK10: =IF(BJ10<>"",BJ10,ROUND(BI10*INDEX('Live Calc'!$G$454:$G$539,MATCH(BC10,'Live Calc'!$A$454:$A$539,0))*'Live Calc'!$J$543,0)) -> 9
A11: Justin Herbert | B11: LAC | C11: 288.984 | D11: 288.984 | E11: 288.984 | F11: =CHOOSE(MATCH(Setup!$B$7,{"STD","Half-PPR","PPR"},0),C11,D11,E11) -> 288.984 | G11: =COUNTIFS('Draft Board'!$H$2:$H$61,">="&H11,'Draft Board'!$L$2:$L$61,1) -> 5 | H11: =MAX(0,F11-'Live Calc'!$H$19)^'Live Calc'!$E$19 -> 51.514633 | I11: 11 | J11: =IF(I11<>_xlfn.MINIFS('Draft Board'!$I$2:$I$61,'Draft Board'!$H$2:$H$61,"="&H11),0,IF(_xlfn.MINIFS('Draft Board'!$H$2:$H$61,'Draft Board'!$H$2:$H$61,">"&H11)=0,1,IF((_xlfn.MINIFS('Draft Board'!$H$2:$H$61,'Draft Board'!$H$2:$H$61,">"&H11)-H11)/_xlfn.MINIFS('Draft Board'!$H$2:$H$61,'Draft Board'!$H$2:$H$61,">"&H11)>0.08,1,0))) -> 0 | K11: =_xlfn.MINIFS('Draft Board'!$H$2:$H$61,'Draft Board'!$H$2:$H$61,">="&H11,'Draft Board'!$J$2:$J$61,1) -> 59.14997 | L11: =IF(I11<>_xlfn.MINIFS('Draft Board'!$I$2:$I$61,'Draft Board'!$H$2:$H$61,"="&H11),0,IF(OR(J11=1,IFERROR(FLOOR((K11-H11)/K11/0.25,1),0)<>IFERROR(FLOOR((K11-_xlfn.MINIFS('Draft Board'!$H$2:$H$61,'Draft Board'!$H$2:$H$61,">"&H11))/K11/0.25,1),0)),1,0)) -> 0 | M11: =ROUND(1+H11*'Live Calc'!$D$26,0) -> 8 | O11: =IF(N11<>"",N11,ROUND(M11*INDEX('Live Calc'!$G$33:$G$92,MATCH(G11,'Live Calc'!$A$33:$A$92,0))*'Live Calc'!$J$543,0)) -> 8 | Q11: Kenneth Walker III | R11: KC | S11: 208.478 | T11: 233.998 | U11: 257.188 | V11: =CHOOSE(MATCH(Setup!$B$7,{"STD","Half-PPR","PPR"},0),S11,T11,U11) -> 233.998 | W11: =COUNTIFS('Draft Board'!$X$2:$X$162,">="&X11,'Draft Board'!$AB$2:$AB$162,1) -> 3 | X11: =MAX(0,V11-'Live Calc'!$H$20)^'Live Calc'!$E$20 -> 336.80622 | Y11: 11 | Z11: =IF(Y11<>_xlfn.MINIFS('Draft Board'!$Y$2:$Y$162,'Draft Board'!$X$2:$X$162,"="&X11),0,IF(_xlfn.MINIFS('Draft Board'!$X$2:$X$162,'Draft Board'!$X$2:$X$162,">"&X11)=0,1,IF((_xlfn.MINIFS('Draft Board'!$X$2:$X$162,'Draft Board'!$X$2:$X$162,">"&X11)-X11)/_xlfn.MINIFS('Draft Board'!$X$2:$X$162,'Draft Board'!$X$2:$X$162,">"&X11)>0.08,1,0))) -> 0 | AA11: =_xlfn.MINIFS('Draft Board'!$X$2:$X$162,'Draft Board'!$X$2:$X$162,">="&X11,'Draft Board'!$Z$2:$Z$162,1) -> 384.50933 | AB11: =IF(Y11<>_xlfn.MINIFS('Draft Board'!$Y$2:$Y$162,'Draft Board'!$X$2:$X$162,"="&X11),0,IF(OR(Z11=1,IFERROR(FLOOR((AA11-X11)/AA11/0.25,1),0)<>IFERROR(FLOOR((AA11-_xlfn.MINIFS('Draft Board'!$X$2:$X$162,'Draft Board'!$X$2:$X$162,">"&X11))/AA11/0.25,1),0)),1,0)) -> 0 | AC11: =ROUND(1+X11*'Live Calc'!$D$27,0) -> 34 | AE11: =IF(AD11<>"",AD11,ROUND(AC11*INDEX('Live Calc'!$G$96:$G$256,MATCH(W11,'Live Calc'!$A$96:$A$256,0))*'Live Calc'!$J$543,0)) -> 34 | AG11: George Pickens | AH11: DAL | AI11: 164.668 | AJ11: 206.136 | AK11: 247.61 | AL11: =CHOOSE(MATCH(Setup!$B$7,{"STD","Half-PPR","PPR"},0),AI11,AJ11,AK11) -> 206.136 | AM11: =COUNTIFS('Draft Board'!$AN$2:$AN$192,">="&AN11,'Draft Board'!$AR$2:$AR$192,1) -> 5 | AN11: =MAX(0,AL11-'Live Calc'!$H$21)^'Live Calc'!$E$21 -> 1037.4297 | AO11: 11 | AP11: =IF(AO11<>_xlfn.MINIFS('Draft Board'!$AO$2:$AO$192,'Draft Board'!$AN$2:$AN$192,"="&AN11),0,IF(_xlfn.MINIFS('Draft Board'!$AN$2:$AN$192,'Draft Board'!$AN$2:$AN$192,">"&AN11)=0,1,IF((_xlfn.MINIFS('Draft Board'!$AN$2:$AN$192,'Draft Board'!$AN$2:$AN$192,">"&AN11)-AN11)/_xlfn.MINIFS('Draft Board'!$AN$2:$AN$192,'Draft Board'!$AN$2:$AN$192,">"&AN11)>0.08,1,0))) -> 0 | AQ11: =_xlfn.MINIFS('Draft Board'!$AN$2:$AN$192,'Draft Board'!$AN$2:$AN$192,">="&AN11,'Draft Board'!$AP$2:$AP$192,1) -> 1089.9472 | AR11: =IF(AO11<>_xlfn.MINIFS('Draft Board'!$AO$2:$AO$192,'Draft Board'!$AN$2:$AN$192,"="&AN11),0,IF(OR(AP11=1,IFERROR(FLOOR((AQ11-AN11)/AQ11/0.25,1),0)<>IFERROR(FLOOR((AQ11-_xlfn.MINIFS('Draft Board'!$AN$2:$AN$192,'Draft Board'!$AN$2:$AN$192,">"&AN11))/AQ11/0.25,1),0)),1,0)) -> 0 | AS11: =ROUND(1+AN11*'Live Calc'!$D$28,0) -> 29 | AU11: =IF(AT11<>"",AT11,ROUND(AS11*INDEX('Live Calc'!$G$260:$G$450,MATCH(AM11,'Live Calc'!$A$260:$A$450,0))*'Live Calc'!$J$543,0)) -> 29 | AW11: Travis Kelce | AX11: KC | AY11: 102.854 | AZ11: 138.06 | BA11: 173.282 | BB11: =CHOOSE(MATCH(Setup!$B$7,{"STD","Half-PPR","PPR"},0),AY11,AZ11,BA11) -> 138.06 | BC11: =COUNTIFS('Draft Board'!$BD$2:$BD$87,">="&BD11,'Draft Board'!$BH$2:$BH$87,1) -> 7 | BD11: =MAX(0,BB11-'Live Calc'!$H$22)^'Live Calc'!$E$22 -> 321.32227 | BE11: 11 | BF11: =IF(BE11<>_xlfn.MINIFS('Draft Board'!$BE$2:$BE$87,'Draft Board'!$BD$2:$BD$87,"="&BD11),0,IF(_xlfn.MINIFS('Draft Board'!$BD$2:$BD$87,'Draft Board'!$BD$2:$BD$87,">"&BD11)=0,1,IF((_xlfn.MINIFS('Draft Board'!$BD$2:$BD$87,'Draft Board'!$BD$2:$BD$87,">"&BD11)-BD11)/_xlfn.MINIFS('Draft Board'!$BD$2:$BD$87,'Draft Board'!$BD$2:$BD$87,">"&BD11)>0.08,1,0))) -> 1 | BG11: =_xlfn.MINIFS('Draft Board'!$BD$2:$BD$87,'Draft Board'!$BD$2:$BD$87,">="&BD11,'Draft Board'!$BF$2:$BF$87,1) -> 321.32227 | BH11: =IF(BE11<>_xlfn.MINIFS('Draft Board'!$BE$2:$BE$87,'Draft Board'!$BD$2:$BD$87,"="&BD11),0,IF(OR(BF11=1,IFERROR(FLOOR((BG11-BD11)/BG11/0.25,1),0)<>IFERROR(FLOOR((BG11-_xlfn.MINIFS('Draft Board'!$BD$2:$BD$87,'Draft Board'!$BD$2:$BD$87,">"&BD11))/BG11/0.25,1),0)),1,0)) -> 1 | BI11: =ROUND(1+BD11*'Live Calc'!$D$29,0) -> 9 | BK11: =IF(BJ11<>"",BJ11,ROUND(BI11*INDEX('Live Calc'!$G$454:$G$539,MATCH(BC11,'Live Calc'!$A$454:$A$539,0))*'Live Calc'!$J$543,0)) -> 9
A12: Brock Purdy | B12: SF | C12: 287.136 | D12: 287.96 | E12: 287.96 | F12: =CHOOSE(MATCH(Setup!$B$7,{"STD","Half-PPR","PPR"},0),C12,D12,E12) -> 287.96 | G12: =COUNTIFS('Draft Board'!$H$2:$H$61,">="&H12,'Draft Board'!$L$2:$L$61,1) -> 5 | H12: =MAX(0,F12-'Live Calc'!$H$19)^'Live Calc'!$E$19 -> 49.153518 | I12: 12 | J12: =IF(I12<>_xlfn.MINIFS('Draft Board'!$I$2:$I$61,'Draft Board'!$H$2:$H$61,"="&H12),0,IF(_xlfn.MINIFS('Draft Board'!$H$2:$H$61,'Draft Board'!$H$2:$H$61,">"&H12)=0,1,IF((_xlfn.MINIFS('Draft Board'!$H$2:$H$61,'Draft Board'!$H$2:$H$61,">"&H12)-H12)/_xlfn.MINIFS('Draft Board'!$H$2:$H$61,'Draft Board'!$H$2:$H$61,">"&H12)>0.08,1,0))) -> 0 | K12: =_xlfn.MINIFS('Draft Board'!$H$2:$H$61,'Draft Board'!$H$2:$H$61,">="&H12,'Draft Board'!$J$2:$J$61,1) -> 59.14997 | L12: =IF(I12<>_xlfn.MINIFS('Draft Board'!$I$2:$I$61,'Draft Board'!$H$2:$H$61,"="&H12),0,IF(OR(J12=1,IFERROR(FLOOR((K12-H12)/K12/0.25,1),0)<>IFERROR(FLOOR((K12-_xlfn.MINIFS('Draft Board'!$H$2:$H$61,'Draft Board'!$H$2:$H$61,">"&H12))/K12/0.25,1),0)),1,0)) -> 0 | M12: =ROUND(1+H12*'Live Calc'!$D$26,0) -> 8 | O12: =IF(N12<>"",N12,ROUND(M12*INDEX('Live Calc'!$G$33:$G$92,MATCH(G12,'Live Calc'!$A$33:$A$92,0))*'Live Calc'!$J$543,0)) -> 8 | Q12: De'Von Achane | R12: MIA | S12: 207.578 | T12: 233.812 | U12: 264.222 | V12: =CHOOSE(MATCH(Setup!$B$7,{"STD","Half-PPR","PPR"},0),S12,T12,U12) -> 233.812 | W12: =COUNTIFS('Draft Board'!$X$2:$X$162,">="&X12,'Draft Board'!$AB$2:$AB$162,1) -> 3 | X12: =MAX(0,V12-'Live Calc'!$H$20)^'Live Calc'!$E$20 -> 336.21756 | Y12: 12 | Z12: =IF(Y12<>_xlfn.MINIFS('Draft Board'!$Y$2:$Y$162,'Draft Board'!$X$2:$X$162,"="&X12),0,IF(_xlfn.MINIFS('Draft Board'!$X$2:$X$162,'Draft Board'!$X$2:$X$162,">"&X12)=0,1,IF((_xlfn.MINIFS('Draft Board'!$X$2:$X$162,'Draft Board'!$X$2:$X$162,">"&X12)-X12)/_xlfn.MINIFS('Draft Board'!$X$2:$X$162,'Draft Board'!$X$2:$X$162,">"&X12)>0.08,1,0))) -> 0 | AA12: =_xlfn.MINIFS('Draft Board'!$X$2:$X$162,'Draft Board'!$X$2:$X$162,">="&X12,'Draft Board'!$Z$2:$Z$162,1) -> 384.50933 | AB12: =IF(Y12<>_xlfn.MINIFS('Draft Board'!$Y$2:$Y$162,'Draft Board'!$X$2:$X$162,"="&X12),0,IF(OR(Z12=1,IFERROR(FLOOR((AA12-X12)/AA12/0.25,1),0)<>IFERROR(FLOOR((AA12-_xlfn.MINIFS('Draft Board'!$X$2:$X$162,'Draft Board'!$X$2:$X$162,">"&X12))/AA12/0.25,1),0)),1,0)) -> 0 | AC12: =ROUND(1+X12*'Live Calc'!$D$27,0) -> 34 | AE12: =IF(AD12<>"",AD12,ROUND(AC12*INDEX('Live Calc'!$G$96:$G$256,MATCH(W12,'Live Calc'!$A$96:$A$256,0))*'Live Calc'!$J$543,0)) -> 34 | AG12: Rashee Rice | AH12: KC | AI12: 160.158 | AJ12: 203.452 | AK12: 251.298 | AL12: =CHOOSE(MATCH(Setup!$B$7,{"STD","Half-PPR","PPR"},0),AI12,AJ12,AK12) -> 203.452 | AM12: =COUNTIFS('Draft Board'!$AN$2:$AN$192,">="&AN12,'Draft Board'!$AR$2:$AR$192,1) -> 5 | AN12: =MAX(0,AL12-'Live Calc'!$H$21)^'Live Calc'!$E$21 -> 996.94156 | AO12: 12 | AP12: =IF(AO12<>_xlfn.MINIFS('Draft Board'!$AO$2:$AO$192,'Draft Board'!$AN$2:$AN$192,"="&AN12),0,IF(_xlfn.MINIFS('Draft Board'!$AN$2:$AN$192,'Draft Board'!$AN$2:$AN$192,">"&AN12)=0,1,IF((_xlfn.MINIFS('Draft Board'!$AN$2:$AN$192,'Draft Board'!$AN$2:$AN$192,">"&AN12)-AN12)/_xlfn.MINIFS('Draft Board'!$AN$2:$AN$192,'Draft Board'!$AN$2:$AN$192,">"&AN12)>0.08,1,0))) -> 0 | AQ12: =_xlfn.MINIFS('Draft Board'!$AN$2:$AN$192,'Draft Board'!$AN$2:$AN$192,">="&AN12,'Draft Board'!$AP$2:$AP$192,1) -> 1089.9472 | AR12: =IF(AO12<>_xlfn.MINIFS('Draft Board'!$AO$2:$AO$192,'Draft Board'!$AN$2:$AN$192,"="&AN12),0,IF(OR(AP12=1,IFERROR(FLOOR((AQ12-AN12)/AQ12/0.25,1),0)<>IFERROR(FLOOR((AQ12-_xlfn.MINIFS('Draft Board'!$AN$2:$AN$192,'Draft Board'!$AN$2:$AN$192,">"&AN12))/AQ12/0.25,1),0)),1,0)) -> 0 | AS12: =ROUND(1+AN12*'Live Calc'!$D$28,0) -> 28 | AU12: =IF(AT12<>"",AT12,ROUND(AS12*INDEX('Live Calc'!$G$260:$G$450,MATCH(AM12,'Live Calc'!$A$260:$A$450,0))*'Live Calc'!$J$543,0)) -> 28 | AW12: Dallas Goedert | AX12: PHI | AY12: 101.444 | AZ12: 134.192 | BA12: 164.376 | BB12: =CHOOSE(MATCH(Setup!$B$7,{"STD","Half-PPR","PPR"},0),AY12,AZ12,BA12) -> 134.192 | BC12: =COUNTIFS('Draft Board'!$BD$2:$BD$87,">="&BD12,'Draft Board'!$BH$2:$BH$87,1) -> 8 | BD12: =MAX(0,BB12-'Live Calc'!$H$22)^'Live Calc'!$E$22 -> 269.12815 | BE12: 12 | BF12: =IF(BE12<>_xlfn.MINIFS('Draft Board'!$BE$2:$BE$87,'Draft Board'!$BD$2:$BD$87,"="&BD12),0,IF(_xlfn.MINIFS('Draft Board'!$BD$2:$BD$87,'Draft Board'!$BD$2:$BD$87,">"&BD12)=0,1,IF((_xlfn.MINIFS('Draft Board'!$BD$2:$BD$87,'Draft Board'!$BD$2:$BD$87,">"&BD12)-BD12)/_xlfn.MINIFS('Draft Board'!$BD$2:$BD$87,'Draft Board'!$BD$2:$BD$87,">"&BD12)>0.08,1,0))) -> 1 | BG12: =_xlfn.MINIFS('Draft Board'!$BD$2:$BD$87,'Draft Board'!$BD$2:$BD$87,">="&BD12,'Draft Board'!$BF$2:$BF$87,1) -> 269.12815 | BH12: =IF(BE12<>_xlfn.MINIFS('Draft Board'!$BE$2:$BE$87,'Draft Board'!$BD$2:$BD$87,"="&BD12),0,IF(OR(BF12=1,IFERROR(FLOOR((BG12-BD12)/BG12/0.25,1),0)<>IFERROR(FLOOR((BG12-_xlfn.MINIFS('Draft Board'!$BD$2:$BD$87,'Draft Board'!$BD$2:$BD$87,">"&BD12))/BG12/0.25,1),0)),1,0)) -> 1 | BI12: =ROUND(1+BD12*'Live Calc'!$D$29,0) -> 7 | BK12: =IF(BJ12<>"",BJ12,ROUND(BI12*INDEX('Live Calc'!$G$454:$G$539,MATCH(BC12,'Live Calc'!$A$454:$A$539,0))*'Live Calc'!$J$543,0)) -> 7
