Workbook

Sheet Start Here
B2: 2026 PROJECTIONS - DIRECT ENTRY (v2)
B4: What changed from v1
B5: v1: you entered percentages, everything else was derived, and nothing
B6: could exceed the team total. Yards per carry was an output.
B7: v2: you type the real numbers. Rates and shares are computed as
B8: checks. Nothing is auto-balanced - the footer tells you when you've
B9: gone over instead of silently absorbing it.
B11: Colours
B12: BLUE you type here
B13: CREAM what he actually did - 2023/24/25 volume, yards, team, games
B14: GREY computed: rates, shares, per-game, change vs last year
B16: The footer is the control
... B49: dCar, dTgt change vs last season - big jumps stand out

Sheet ARI
A1: ARI - 2026 projections (direct entry)
A3: TEAM TOTALS | D3: all editable - these are your targets, not hard caps
B4: Games | C4: Plays/G | D4: Plays | E4: Pass Rate | F4: Pass Att | G4: Targets | H4: Rush Att | I4: Pass Yds | J4: Pass TD | K4: Int | L4: Rush Yds | M4: Rush TD
B5: 17 | C5: 62.2 | D5: =C5*B5 -> 1057.4 | E5: 0.595 | F5: =ROUND(D5*E5,0) -> 629 | G5: =ROUND(F5*Settings!$B$4,0) -> 600 | H5: =D5-F5 -> 428.4 | I5: 3992 | J5: 25 | K5: 12 | L5: 1940 | M5: 14
A7: VACATED | B7: 24% of targets and 70% of carries left this roster - that volume is yours to reassign.
A8: STAFF | B8: NEW HC Mike LaFleur + OC Nathaniel Hackett. Pass rate projected to DROP 69.4% -> 58%. Biggest scheme change in the league - revisit Pass Rate above.
A10: Pos | B10: Player | C10: Dep | D10: Age | E10: Status | F10: '23 Car | G10: '24 Car | H10: '25 Car | I10: '25 RuYd | J10: '23 Tgt | K10: '24 Tgt | L10: '25 Tgt | M10: '25 ReYd | N10: '25 Tm | O10: '25 G | P10: 3y Y/C | Q10: 3y Y/R | R10: 3y Ctch | S10: 3y Comp% | T10: 3y Y/A | U10: Games | V10: Pass Att | W10: Cmp | X10: Pass Yds | Y10: Pass TD | Z10: Int | AA10: Rush Att | AB10: Rush Yds | AC10: Rush TD | AD10: Targets | AE10: Rec | AF10: Rec Yds | AG10: Rec TD | AH10: Seed | AI10: Y/C | AJ10: Y/R | AK10: Catch% | AL10: Y/A | AM10: Comp% | AN10: Rush % | AO10: Tgt % | AP10: Pass % | AQ10: Car/G | AR10: Tgt/G | AS10: dTgt | AT10: dCar | AU10: Half PPR
A11: QB | B11: Jacoby Brissett | C11: 1 | D11: 33 | E11: ACT | F11: 3 | G11: 12 | H11: 36 | I11: 168 | N11: ARI | O11: 14 | P11: 4.88 | S11: 0.64 | T11: 6.6 | U11: 17 | V11: 509 | W11: 319 | X11: 3366 | Y11: 21 | Z11: 10 | AA11: 44 | AB11: 193 | AC11: 1 | AD11: 0 | AE11: 0 | AF11: 0 | AG11: 0 | AH11: kept | AI11: =IFERROR(AB11/AA11,"") -> 4.3863636 | AJ11: =IFERROR(AF11/AE11,"") | AK11: =IFERROR(AE11/AD11,"") | AL11: =IFERROR(X11/V11,"") -> 6.6129666 | AM11: =IFERROR(W11/V11,"") -> 0.62671906 | AN11: =IFERROR(AA11/$H$5,"") -> 0.10270775 | AO11: =IFERROR(AD11/$G$5,"") -> 0 | AP11: =IFERROR(V11/$F$5,"") -> 0.80922099 | AQ11: =IFERROR(AA11/U11,"") -> 2.5882353 | AR11: =IFERROR(AD11/U11,"") -> 0 | AS11: =IFERROR(AD11-L11,"") -> 0 | AT11: =IFERROR(AA11-H11,"") -> 8 | AU11: =AF11*Settings!$B$7+AG11*Settings!$B$8+AE11*Settings!$B$9+AB11*Settings!$B$10+AC11*Settings!$B$11+X11*Settings!$B$12+Y11*Settings!$B$13+Z11*Settings!$B$14 -> 223.94
A12: QB | B12: Carson Beck | C12: 2 | D12: 23 | E12: ACT | U12: 17 | V12: 101 | W12: 52 | X12: 624 | Y12: 4 | Z12: 2 | AA12: 6 | AB12: 21 | AC12: 0 | AH12: kept | AI12: =IFERROR(AB12/AA12,"") -> 3.5 | AJ12: =IFERROR(AF12/AE12,"") | AK12: =IFERROR(AE12/AD12,"") | AL12: =IFERROR(X12/V12,"") -> 6.1782178 | AM12: =IFERROR(W12/V12,"") -> 0.51485149 | AN12: =IFERROR(AA12/$H$5,"") -> 0.014005602 | AO12: =IFERROR(AD12/$G$5,"") -> 0 | AP12: =IFERROR(V12/$F$5,"") -> 0.16057234 | AQ12: =IFERROR(AA12/U12,"") -> 0.35294118 | AR12: =IFERROR(AD12/U12,"") -> 0 | AS12: =IFERROR(AD12-L12,"") -> 0 | AT12: =IFERROR(AA12-H12,"") -> 6 | AU12: =AF12*Settings!$B$7+AG12*Settings!$B$8+AE12*Settings!$B$9+AB12*Settings!$B$10+AC12*Settings!$B$11+X12*Settings!$B$12+Y12*Settings!$B$13+Z12*Settings!$B$14 -> 39.06
A13: QB | B13: Kedon Slovis | C13: 3 | D13: 25 | E13: ACT | N13: ARI | O13: 2 | S13: 0.5 | U13: 17 | V13: 12 | W13: 8 | X13: 33 | Y13: 0 | Z13: 0 | AA13: 0 | AB13: 0 | AC13: 0 | AD13: 0 | AE13: 0 | AF13: 0 | AG13: 0 | AH13: kept | AI13: =IFERROR(AB13/AA13,"") | AJ13: =IFERROR(AF13/AE13,"") | AK13: =IFERROR(AE13/AD13,"") | AL13: =IFERROR(X13/V13,"") -> 2.75 | AM13: =IFERROR(W13/V13,"") -> 0.66666667 | AN13: =IFERROR(AA13/$H$5,"") -> 0 | AO13: =IFERROR(AD13/$G$5,"") -> 0 | AP13: =IFERROR(V13/$F$5,"") -> 0.019077901 | AQ13: =IFERROR(AA13/U13,"") -> 0 | AR13: =IFERROR(AD13/U13,"") -> 0 | AS13: =IFERROR(AD13-L13,"") -> 0 | AT13: =IFERROR(AA13-H13,"") -> 0 | AU13: =AF13*Settings!$B$7+AG13*Settings!$B$8+AE13*Settings!$B$9+AB13*Settings!$B$10+AC13*Settings!$B$11+X13*Settings!$B$12+Y13*Settings!$B$13+Z13*Settings!$B$14 -> 1.32
A14: QB | B14: Other QBs | U14: 17 | AI14: =IFERROR(AB14/AA14,"") | AJ14: =IFERROR(AF14/AE14,"") | AK14: =IFERROR(AE14/AD14,"") | AL14: =IFERROR(X14/V14,"") | AM14: =IFERROR(W14/V14,"") | AN14: =IFERROR(AA14/$H$5,"") -> 0 | AO14: =IFERROR(AD14/$G$5,"") -> 0 | AP14: =IFERROR(V14/$F$5,"") -> 0 | AQ14: =IFERROR(AA14/U14,"") -> 0 | AR14: =IFERROR(AD14/U14,"") -> 0 | AS14: =IFERROR(AD14-L14,"") -> 0 | AT14: =IFERROR(AA14-H14,"") -> 0 | AU14: =AF14*Settings!$B$7+AG14*Settings!$B$8+AE14*Settings!$B$9+AB14*Settings!$B$10+AC14*Settings!$B$11+X14*Settings!$B$12+Y14*Settings!$B$13+Z14*Settings!$B$14 -> 0
A15: RB | B15: Jeremiyah Love | C15: 1 | D15: 21 | E15: ACT | U15: 17 | AA15: 221 | AB15: 1022 | AC15: 6 | AD15: 67 | AE15: 49 | AF15: 408 | AG15: 2 | AH15: kept | AI15: =IFERROR(AB15/AA15,"") -> 4.6244344 | AJ15: =IFERROR(AF15/AE15,"") -> 8.3265306 | AK15: =IFERROR(AE15/AD15,"") -> 0.73134328 | AL15: =IFERROR(X15/V15,"") | AM15: =IFERROR(W15/V15,"") | AN15: =IFERROR(AA15/$H$5,"") -> 0.51587302 | AO15: =IFERROR(AD15/$G$5,"") -> 0.11166667 | AP15: =IFERROR(V15/$F$5,"") -> 0 | AQ15: =IFERROR(AA15/U15,"") -> 13 | AR15: =IFERROR(AD15/U15,"") -> 3.9411765 | AS15: =IFERROR(AD15-L15,"") -> 67 | AT15: =IFERROR(AA15-H15,"") -> 221 | AU15: =AF15*Settings!$B$7+AG15*Settings!$B$8+AE15*Settings!$B$9+AB15*Settings!$B$10+AC15*Settings!$B$11+X15*Settings!$B$12+Y15*Settings!$B$13+Z15*Settings!$B$14 -> 215.5
A16: RB | B16: Tyler Allgeier | C16: 2 | D16: 26 | E16: ACT | F16: 186 | G16: 137 | H16: 143 | I16: 514 | J16: 23 | K16: 13 | L16: 16 | M16: 96 | N16: ATL | O16: 17 | P16: 3.95 | Q16: 8.38 | R16: 0.865 | U16: 17 | V16: 0 | W16: 0 | X16: 0 | Y16: 0 | Z16: 0 | AA16: 107 | AB16: 485 | AC16: 5 | AD16: 15 | AE16: 9 | AF16: 88 | AG16: 0 | AH16: kept | AI16: =IFERROR(AB16/AA16,"") -> 4.5327103 | AJ16: =IFERROR(AF16/AE16,"") -> 9.7777778 | AK16: =IFERROR(AE16/AD16,"") -> 0.6 | AL16: =IFERROR(X16/V16,"") | AM16: =IFERROR(W16/V16,"") | AN16: =IFERROR(AA16/$H$5,"") -> 0.24976657 | AO16: =IFERROR(AD16/$G$5,"") -> 0.025 | AP16: =IFERROR(V16/$F$5,"") -> 0 | AQ16: =IFERROR(AA16/U16,"") -> 6.2941176 | AR16: =IFERROR(AD16/U16,"") -> 0.88235294 | AS16: =IFERROR(AD16-L16,"") -> -1 | AT16: =IFERROR(AA16-H16,"") -> -36 | AU16: =AF16*Settings!$B$7+AG16*Settings!$B$8+AE16*Settings!$B$9+AB16*Settings!$B$10+AC16*Settings!$B$11+X16*Settings!$B$12+Y16*Settings!$B$13+Z16*Settings!$B$14 -> 91.8
A17: RB | B17: James Conner | C17: 3 | D17: 31 | E17: QUESTIONABLE | F17: 208 | G17: 236 | H17: 32 | I17: 95 | J17: 33 | K17: 55 | L17: 9 | M17: 38 | N17: ARI | O17: 3 | P17: 4.68 | Q17: 7.52 | R17: 0.845 | U17: 17 | V17: 0 | W17: 0 | X17: 0 | Y17: 0 | Z17: 0 | AA17: 33 | AB17: 148 | AC17: 1 | AD17: 16 | AE17: 12 | AF17: 90 | AG17: 1 | AH17: kept | AI17: =IFERROR(AB17/AA17,"") -> 4.4848485 | AJ17: =IFERROR(AF17/AE17,"") -> 7.5 | AK17: =IFERROR(AE17/AD17,"") -> 0.75 | AL17: =IFERROR(X17/V17,"") | AM17: =IFERROR(W17/V17,"") | AN17: =IFERROR(AA17/$H$5,"") -> 0.077030812 | AO17: =IFERROR(AD17/$G$5,"") -> 0.026666667 | AP17: =IFERROR(V17/$F$5,"") -> 0 | AQ17: =IFERROR(AA17/U17,"") -> 1.9411765 | AR17: =IFERROR(AD17/U17,"") -> 0.94117647 | AS17: =IFERROR(AD17-L17,"") -> 7 | AT17: =IFERROR(AA17-H17,"") -> 1 | AU17: =AF17*Settings!$B$7+AG17*Settings!$B$8+AE17*Settings!$B$9+AB17*Settings!$B$10+AC17*Settings!$B$11+X17*Settings!$B$12+Y17*Settings!$B$13+Z17*Settings!$B$14 -> 41.8
A18: RB | B18: Zonovan Knight | C18: 4 | D18: 25 | E18: ACT | F18: 3 | H18: 82 | I18: 269 | J18: 1 | L18: 31 | M18: 160 | N18: ARI | O18: 12 | P18: 3.32 | Q18: 7.3 | R18: 0.719 | U18: 17 | V18: 0 | W18: 0 | X18: 0 | Y18: 0 | Z18: 0 | AA18: 5 | AB18: 21 | AC18: 0 | AD18: 0 | AE18: 0 | AF18: 0 | AG18: 0 | AH18: kept | AI18: =IFERROR(AB18/AA18,"") -> 4.2 | AJ18: =IFERROR(AF18/AE18,"") | AK18: =IFERROR(AE18/AD18,"") | AL18: =IFERROR(X18/V18,"") | AM18: =IFERROR(W18/V18,"") | AN18: =IFERROR(AA18/$H$5,"") -> 0.011671335 | AO18: =IFERROR(AD18/$G$5,"") -> 0 | AP18: =IFERROR(V18/$F$5,"") -> 0 | AQ18: =IFERROR(AA18/U18,"") -> 0.29411765 | AR18: =IFERROR(AD18/U18,"") -> 0 | AS18: =IFERROR(AD18-L18,"") -> -31 | AT18: =IFERROR(AA18-H18,"") -> -77 | AU18: =AF18*Settings!$B$7+AG18*Settings!$B$8+AE18*Settings!$B$9+AB18*Settings!$B$10+AC18*Settings!$B$11+X18*Settings!$B$12+Y18*Settings!$B$13+Z18*Settings!$B$14 -> 2.1
A19: RB | B19: Trey Benson | C19: 5 | D19: 24 | E19: ACT | G19: 63 | H19: 29 | I19: 160 | K19: 6 | L19: 16 | M19: 64 | N19: ARI | O19: 4 | P19: 4.9 | Q19: 6.47 | R19: 0.864 | U19: 17 | V19: 0 | W19: 0 | X19: 0 | Y19: 0 | Z19: 0 | AA19: 11 | AB19: 44 | AC19: 0 | AD19: 5 | AE19: 4 | AF19: 31 | AG19: 0 | AH19: kept | AI19: =IFERROR(AB19/AA19,"") -> 4 | AJ19: =IFERROR(AF19/AE19,"") -> 7.75 | AK19: =IFERROR(AE19/AD19,"") -> 0.8 | AL19: =IFERROR(X19/V19,"") | AM19: =IFERROR(W19/V19,"") | AN19: =IFERROR(AA19/$H$5,"") -> 0.025676937 | AO19: =IFERROR(AD19/$G$5,"") -> 0.0083333333 | AP19: =IFERROR(V19/$F$5,"") -> 0 | AQ19: =IFERROR(AA19/U19,"") -> 0.64705882 | AR19: =IFERROR(AD19/U19,"") -> 0.29411765 | AS19: =IFERROR(AD19-L19,"") -> -11 | AT19: =IFERROR(AA19-H19,"") -> -18 | AU19: =AF19*Settings!$B$7+AG19*Settings!$B$8+AE19*Settings!$B$9+AB19*Settings!$B$10+AC19*Settings!$B$11+X19*Settings!$B$12+Y19*Settings!$B$13+Z19*Settings!$B$14 -> 9.5
A20: RB | B20: Corey Kiner | C20: 6 | D20: 24 | E20: ACT | H20: 12 | I20: 58 | L20: 3 | M20: 15 | N20: ARI | O20: 4 | P20: 4.83 | Q20: 7.5 | R20: 0.667 | U20: 17 | V20: 0 | W20: 0 | X20: 0 | Y20: 0 | Z20: 0 | AA20: 0 | AB20: 0 | AC20: 0 | AD20: 0 | AE20: 0 | AF20: 0 | AG20: 0 | AH20: kept | AI20: =IFERROR(AB20/AA20,"") | AJ20: =IFERROR(AF20/AE20,"") | AK20: =IFERROR(AE20/AD20,"") | AL20: =IFERROR(X20/V20,"") | AM20: =IFERROR(W20/V20,"") | AN20: =IFERROR(AA20/$H$5,"") -> 0 | AO20: =IFERROR(AD20/$G$5,"") -> 0 | AP20: =IFERROR(V20/$F$5,"") -> 0 | AQ20: =IFERROR(AA20/U20,"") -> 0 | AR20: =IFERROR(AD20/U20,"") -> 0 | AS20: =IFERROR(AD20-L20,"") -> -3 | AT20: =IFERROR(AA20-H20,"") -> -12 | AU20: =AF20*Settings!$B$7+AG20*Settings!$B$8+AE20*Settings!$B$9+AB20*Settings!$B$10+AC20*Settings!$B$11+X20*Settings!$B$12+Y20*Settings!$B$13+Z20*Settings!$B$14 -> 0
A21: RB | B21: Other RBs | U21: 17 | AI21: =IFERROR(AB21/AA21,"") | AJ21: =IFERROR(AF21/AE21,"") | AK21: =IFERROR(AE21/AD21,"") | AL21: =IFERROR(X21/V21,"") | AM21: =IFERROR(W21/V21,"") | AN21: =IFERROR(AA21/$H$5,"") -> 0 | AO21: =IFERROR(AD21/$G$5,"") -> 0 | AP21: =IFERROR(V21/$F$5,"") -> 0 | AQ21: =IFERROR(AA21/U21,"") -> 0 | AR21: =IFERROR(AD21/U21,"") -> 0 | AS21: =IFERROR(AD21-L21,"") -> 0 | AT21: =IFERROR(AA21-H21,"") -> 0 | AU21: =AF21*Settings!$B$7+AG21*Settings!$B$8+AE21*Settings!$B$9+AB21*Settings!$B$10+AC21*Settings!$B$11+X21*Settings!$B$12+Y21*Settings!$B$13+Z21*Settings!$B$14 -> 0
A22: WR | B22: Marvin Harrison | C22: 1 | D22: 23 | E22: ACT | K22: 116 | L22: 73 | M22: 608 | N22: ARI | O22: 12 | Q22: 14.5 | R22: 0.545 | U22: 17 | V22: 0 | W22: 0 | X22: 0 | Y22: 0 | Z22: 0 | AA22: 0 | AB22: 1 | AC22: 0 | AD22: 111 | AE22: 61 | AF22: 864 | AG22: 7 | AH22: kept | AI22: =IFERROR(AB22/AA22,"") | AJ22: =IFERROR(AF22/AE22,"") -> 14.163934 | AK22: =IFERROR(AE22/AD22,"") -> 0.54954955 | AL22: =IFERROR(X22/V22,"") | AM22: =IFERROR(W22/V22,"") | AN22: =IFERROR(AA22/$H$5,"") -> 0 | AO22: =IFERROR(AD22/$G$5,"") -> 0.185 | AP22: =IFERROR(V22/$F$5,"") -> 0 | AQ22: =IFERROR(AA22/U22,"") -> 0 | AR22: =IFERROR(AD22/U22,"") -> 6.5294118 | AS22: =IFERROR(AD22-L22,"") -> 38 | AT22: =IFERROR(AA22-H22,"") -> 0 | AU22: =AF22*Settings!$B$7+AG22*Settings!$B$8+AE22*Settings!$B$9+AB22*Settings!$B$10+AC22*Settings!$B$11+X22*Settings!$B$12+Y22*Settings!$B$13+Z22*Settings!$B$14 -> 159
A23: WR | B23: Michael Wilson | C23: 2 | D23: 26 | E23: ACT | G23: 1 | J23: 58 | K23: 71 | L23: 126 | M23: 1006 | N23: ARI | O23: 17 | P23: 7 | Q23: 13 | R23: 0.639 | U23: 17 | V23: 0 | W23: 0 | X23: 0 | Y23: 0 | Z23: 0 | AA23: 0 | AB23: 1 | AC23: 0 | AD23: 101 | AE23: 63 | AF23: 815 | AG23: 6 | AH23: kept | AI23: =IFERROR(AB23/AA23,"") | AJ23: =IFERROR(AF23/AE23,"") -> 12.936508 | AK23: =IFERROR(AE23/AD23,"") -> 0.62376238 | AL23: =IFERROR(X23/V23,"") | AM23: =IFERROR(W23/V23,"") | AN23: =IFERROR(AA23/$H$5,"") -> 0 | AO23: =IFERROR(AD23/$G$5,"") -> 0.16833333 | AP23: =IFERROR(V23/$F$5,"") -> 0 | AQ23: =IFERROR(AA23/U23,"") -> 0 | AR23: =IFERROR(AD23/U23,"") -> 5.9411765 | AS23: =IFERROR(AD23-L23,"") -> -25 | AT23: =IFERROR(AA23-H23,"") -> 0 | AU23: =AF23*Settings!$B$7+AG23*Settings!$B$8+AE23*Settings!$B$9+AB23*Settings!$B$10+AC23*Settings!$B$11+X23*Settings!$B$12+Y23*Settings!$B$13+Z23*Settings!$B$14 -> 149.1
A24: WR | B24: Kendrick Bourne | C24: 3 | D24: 31 | E24: ACT | F24: 1 | G24: 1 | J24: 55 | K24: 38 | L24: 53 | M24: 551 | N24: SF | O24: 16 | P24: 5 | Q24: 12.37 | R24: 0.699 | U24: 17 | V24: 0 | W24: 0 | X24: 0 | Y24: 0 | Z24: 0 | AA24: 0 | AB24: 1 | AC24: 0 | AD24: 42 | AE24: 28 | AF24: 241 | AG24: 1 | AH24: kept | AI24: =IFERROR(AB24/AA24,"") | AJ24: =IFERROR(AF24/AE24,"") -> 8.6071429 | AK24: =IFERROR(AE24/AD24,"") -> 0.66666667 | AL24: =IFERROR(X24/V24,"") | AM24: =IFERROR(W24/V24,"") | AN24: =IFERROR(AA24/$H$5,"") -> 0 | AO24: =IFERROR(AD24/$G$5,"") -> 0.07 | AP24: =IFERROR(V24/$F$5,"") -> 0 | AQ24: =IFERROR(AA24/U24,"") -> 0 | AR24: =IFERROR(AD24/U24,"") -> 2.4705882 | AS24: =IFERROR(AD24-L24,"") -> -11 | AT24: =IFERROR(AA24-H24,"") -> 0 | AU24: =AF24*Settings!$B$7+AG24*Settings!$B$8+AE24*Settings!$B$9+AB24*Settings!$B$10+AC24*Settings!$B$11+X24*Settings!$B$12+Y24*Settings!$B$13+Z24*Settings!$B$14 -> 44.2
A25: WR | B25: Xavier Weaver | C25: 4 | D25: 25 | E25: ACT | K25: 2 | L25: 13 | M25: 67 | N25: ARI | O25: 10 | Q25: 9.57 | R25: 0.467 | U25: 17 | V25: 0 | W25: 0 | X25: 0 | Y25: 0 | Z25: 0 | AA25: 0 | AB25: 1 | AC25: 0 | AD25: 9 | AE25: 5 | AF25: 51 | AG25: 0 | AH25: kept | AI25: =IFERROR(AB25/AA25,"") | AJ25: =IFERROR(AF25/AE25,"") -> 10.2 | AK25: =IFERROR(AE25/AD25,"") -> 0.55555556 | AL25: =IFERROR(X25/V25,"") | AM25: =IFERROR(W25/V25,"") | AN25: =IFERROR(AA25/$H$5,"") -> 0 | AO25: =IFERROR(AD25/$G$5,"") -> 0.015 | AP25: =IFERROR(V25/$F$5,"") -> 0 | AQ25: =IFERROR(AA25/U25,"") -> 0 | AR25: =IFERROR(AD25/U25,"") -> 0.52941176 | AS25: =IFERROR(AD25-L25,"") -> -4 | AT25: =IFERROR(AA25-H25,"") -> 0 | AU25: =AF25*Settings!$B$7+AG25*Settings!$B$8+AE25*Settings!$B$9+AB25*Settings!$B$10+AC25*Settings!$B$11+X25*Settings!$B$12+Y25*Settings!$B$13+Z25*Settings!$B$14 -> 7.7
A26: WR | B26: Reggie Virgil | C26: 5 | D26: 22 | E26: ACT | U26: 17 | AA26: 0 | AB26: 0 | AC26: 0 | AD26: 8 | AE26: 6 | AF26: 78 | AG26: 0 | AH26: kept | AI26: =IFERROR(AB26/AA26,"") | AJ26: =IFERROR(AF26/AE26,"") -> 13 | AK26: =IFERROR(AE26/AD26,"") -> 0.75 | AL26: =IFERROR(X26/V26,"") | AM26: =IFERROR(W26/V26,"") | AN26: =IFERROR(AA26/$H$5,"") -> 0 | AO26: =IFERROR(AD26/$G$5,"") -> 0.013333333 | AP26: =IFERROR(V26/$F$5,"") -> 0 | AQ26: =IFERROR(AA26/U26,"") -> 0 | AR26: =IFERROR(AD26/U26,"") -> 0.47058824 | AS26: =IFERROR(AD26-L26,"") -> 8 | AT26: =IFERROR(AA26-H26,"") -> 0 | AU26: =AF26*Settings!$B$7+AG26*Settings!$B$8+AE26*Settings!$B$9+AB26*Settings!$B$10+AC26*Settings!$B$11+X26*Settings!$B$12+Y26*Settings!$B$13+Z26*Settings!$B$14 -> 10.8
A27: WR | B27: Simi Fehoko | C27: 6 | D27: 28 | E27: ACT | J27: 2 | K27: 16 | Q27: 16.43 | R27: 0.389 | U27: 17 | AA27: 0 | AB27: 0 | AC27: 0 | AD27: 0 | AE27: 0 | AF27: 4 | AG27: 0 | AH27: kept | AI27: =IFERROR(AB27/AA27,"") | AJ27: =IFERROR(AF27/AE27,"") | AK27: =IFERROR(AE27/AD27,"") | AL27: =IFERROR(X27/V27,"") | AM27: =IFERROR(W27/V27,"") | AN27: =IFERROR(AA27/$H$5,"") -> 0 | AO27: =IFERROR(AD27/$G$5,"") -> 0 | AP27: =IFERROR(V27/$F$5,"") -> 0 | AQ27: =IFERROR(AA27/U27,"") -> 0 | AR27: =IFERROR(AD27/U27,"") -> 0 | AS27: =IFERROR(AD27-L27,"") -> 0 | AT27: =IFERROR(AA27-H27,"") -> 0 | AU27: =AF27*Settings!$B$7+AG27*Settings!$B$8+AE27*Settings!$B$9+AB27*Settings!$B$10+AC27*Settings!$B$11+X27*Settings!$B$12+Y27*Settings!$B$13+Z27*Settings!$B$14 -> 0.4
A28: WR | B28: Devin Duvernay | C28: 7 | D28: 28 | E28: ACT | F28: 4 | G28: 4 | J28: 9 | K28: 16 | L28: 5 | M28: 26 | N28: CHI | O28: 17 | P28: 2.25 | Q28: 7.24 | R28: 0.567 | U28: 17 | V28: 0 | W28: 0 | X28: 0 | Y28: 0 | Z28: 0 | AA28: 1 | AB28: 2 | AC28: 0 | AD28: 4 | AE28: 2 | AF28: 13 | AG28: 0 | AH28: kept | AI28: =IFERROR(AB28/AA28,"") -> 2 | AJ28: =IFERROR(AF28/AE28,"") -> 6.5 | AK28: =IFERROR(AE28/AD28,"") -> 0.5 | AL28: =IFERROR(X28/V28,"") | AM28: =IFERROR(W28/V28,"") | AN28: =IFERROR(AA28/$H$5,"") -> 0.002334267 | AO28: =IFERROR(AD28/$G$5,"") -> 0.0066666667 | AP28: =IFERROR(V28/$F$5,"") -> 0 | AQ28: =IFERROR(AA28/U28,"") -> 0.058823529 | AR28: =IFERROR(AD28/U28,"") -> 0.23529412 | AS28: =IFERROR(AD28-L28,"") -> -1 | AT28: =IFERROR(AA28-H28,"") -> 1 | AU28: =AF28*Settings!$B$7+AG28*Settings!$B$8+AE28*Settings!$B$9+AB28*Settings!$B$10+AC28*Settings!$B$11+X28*Settings!$B$12+Y28*Settings!$B$13+Z28*Settings!$B$14 -> 2.5
A29: WR | B29: Ihmir Smith-Marsette | C29: 8 | D29: 26 | E29: ACT | F29: 8 | J29: 10 | P29: 9.25 | Q29: 6.38 | R29: 0.8 | U29: 17 | AI29: =IFERROR(AB29/AA29,"") | AJ29: =IFERROR(AF29/AE29,"") | AK29: =IFERROR(AE29/AD29,"") | AL29: =IFERROR(X29/V29,"") | AM29: =IFERROR(W29/V29,"") | AN29: =IFERROR(AA29/$H$5,"") -> 0 | AO29: =IFERROR(AD29/$G$5,"") -> 0 | AP29: =IFERROR(V29/$F$5,"") -> 0 | AQ29: =IFERROR(AA29/U29,"") -> 0 | AR29: =IFERROR(AD29/U29,"") -> 0 | AS29: =IFERROR(AD29-L29,"") -> 0 | AT29: =IFERROR(AA29-H29,"") -> 0 | AU29: =AF29*Settings!$B$7+AG29*Settings!$B$8+AE29*Settings!$B$9+AB29*Settings!$B$10+AC29*Settings!$B$11+X29*Settings!$B$12+Y29*Settings!$B$13+Z29*Settings!$B$14 -> 0
A30: WR | B30: Other WRs | U30: 17 | AI30: =IFERROR(AB30/AA30,"") | AJ30: =IFERROR(AF30/AE30,"") | AK30: =IFERROR(AE30/AD30,"") | AL30: =IFERROR(X30/V30,"") | AM30: =IFERROR(W30/V30,"") | AN30: =IFERROR(AA30/$H$5,"") -> 0 | AO30: =IFERROR(AD30/$G$5,"") -> 0 | AP30: =IFERROR(V30/$F$5,"") -> 0 | AQ30: =IFERROR(AA30/U30,"") -> 0 | AR30: =IFERROR(AD30/U30,"") -> 0 | AS30: =IFERROR(AD30-L30,"") -> 0 | AT30: =IFERROR(AA30-H30,"") -> 0 | AU30: =AF30*Settings!$B$7+AG30*Settings!$B$8+AE30*Settings!$B$9+AB30*Settings!$B$10+AC30*Settings!$B$11+X30*Settings!$B$12+Y30*Settings!$B$13+Z30*Settings!$B$14 -> 0
A31: TE | B31: Trey McBride | C31: 1 | D31: 26 | E31: ACT | G31: 1 | J31: 106 | K31: 147 | L31: 169 | M31: 1239 | N31: ARI | O31: 17 | P31: 2 | Q31: 10.09 | R31: 0.754 | U31: 17 | V31: 0 | W31: 0 | X31: 0 | Y31: 0 | Z31: 0 | AA31: 0 | AB31: 0 | AC31: 0 | AD31: 143 | AE31: 104 | AF31: 1052 | AG31: 7 | AH31: kept | AI31: =IFERROR(AB31/AA31,"") | AJ31: =IFERROR(AF31/AE31,"") -> 10.115385 | AK31: =IFERROR(AE31/AD31,"") -> 0.72727273 | AL31: =IFERROR(X31/V31,"") | AM31: =IFERROR(W31/V31,"") | AN31: =IFERROR(AA31/$H$5,"") -> 0 | AO31: =IFERROR(AD31/$G$5,"") -> 0.23833333 | AP31: =IFERROR(V31/$F$5,"") -> 0 | AQ31: =IFERROR(AA31/U31,"") -> 0 | AR31: =IFERROR(AD31/U31,"") -> 8.4117647 | AS31: =IFERROR(AD31-L31,"") -> -26 | AT31: =IFERROR(AA31-H31,"") -> 0 | AU31: =AF31*Settings!$B$7+AG31*Settings!$B$8+AE31*Settings!$B$9+AB31*Settings!$B$10+AC31*Settings!$B$11+X31*Settings!$B$12+Y31*Settings!$B$13+Z31*Settings!$B$14 -> 199.2
A32: TE | B32: Elijah Higgins | C32: 2 | D32: 25 | E32: ACT | J32: 19 | K32: 24 | L32: 37 | M32: 301 | N32: ARI | O32: 17 | Q32: 9.94 | R32: 0.8 | U32: 17 | V32: 0 | W32: 0 | X32: 0 | Y32: 0 | Z32: 0 | AA32: 0 | AB32: 0 | AC32: 0 | AD32: 26 | AE32: 20 | AF32: 185 | AG32: 1 | AH32: kept | AI32: =IFERROR(AB32/AA32,"") | AJ32: =IFERROR(AF32/AE32,"") -> 9.25 | AK32: =IFERROR(AE32/AD32,"") -> 0.76923077 | AL32: =IFERROR(X32/V32,"") | AM32: =IFERROR(W32/V32,"") | AN32: =IFERROR(AA32/$H$5,"") -> 0 | AO32: =IFERROR(AD32/$G$5,"") -> 0.043333333 | AP32: =IFERROR(V32/$F$5,"") -> 0 | AQ32: =IFERROR(AA32/U32,"") -> 0 | AR32: =IFERROR(AD32/U32,"") -> 1.5294118 | AS32: =IFERROR(AD32-L32,"") -> -11 | AT32: =IFERROR(AA32-H32,"") -> 0 | AU32: =AF32*Settings!$B$7+AG32*Settings!$B$8+AE32*Settings!$B$9+AB32*Settings!$B$10+AC32*Settings!$B$11+X32*Settings!$B$12+Y32*Settings!$B$13+Z32*Settings!$B$14 -> 34.5
A33: TE | B33: Teagan Quitoriano | C33: 3 | D33: 26 | E33: ACT | J33: 3 | Q33: 16.5 | R33: 0.667 | U33: 17 | AA33: 0 | AB33: 0 | AC33: 0 | AD33: 5 | AE33: 4 | AF33: 36 | AG33: 0 | AH33: kept | AI33: =IFERROR(AB33/AA33,"") | AJ33: =IFERROR(AF33/AE33,"") -> 9 | AK33: =IFERROR(AE33/AD33,"") -> 0.8 | AL33: =IFERROR(X33/V33,"") | AM33: =IFERROR(W33/V33,"") | AN33: =IFERROR(AA33/$H$5,"") -> 0 | AO33: =IFERROR(AD33/$G$5,"") -> 0.0083333333 | AP33: =IFERROR(V33/$F$5,"") -> 0 | AQ33: =IFERROR(AA33/U33,"") -> 0 | AR33: =IFERROR(AD33/U33,"") -> 0.29411765 | AS33: =IFERROR(AD33-L33,"") -> 5 | AT33: =IFERROR(AA33-H33,"") -> 0 | AU33: =AF33*Settings!$B$7+AG33*Settings!$B$8+AE33*Settings!$B$9+AB33*Settings!$B$10+AC33*Settings!$B$11+X33*Settings!$B$12+Y33*Settings!$B$13+Z33*Settings!$B$14 -> 5.6
A34: TE | B34: Rivaldo Fairweather | C34: 4 | D34: 24 | E34: ACT | U34: 17 | AA34: 0 | AB34: 0 | AC34: 0 | AD34: 5 | AE34: 4 | AF34: 36 | AG34: 0 | AH34: kept | AI34: =IFERROR(AB34/AA34,"") | AJ34: =IFERROR(AF34/AE34,"") -> 9 | AK34: =IFERROR(AE34/AD34,"") -> 0.8 | AL34: =IFERROR(X34/V34,"") | AM34: =IFERROR(W34/V34,"") | AN34: =IFERROR(AA34/$H$5,"") -> 0 | AO34: =IFERROR(AD34/$G$5,"") -> 0.0083333333 | AP34: =IFERROR(V34/$F$5,"") -> 0 | AQ34: =IFERROR(AA34/U34,"") -> 0 | AR34: =IFERROR(AD34/U34,"") -> 0.29411765 | AS34: =IFERROR(AD34-L34,"") -> 5 | AT34: =IFERROR(AA34-H34,"") -> 0 | AU34: =AF34*Settings!$B$7+AG34*Settings!$B$8+AE34*Settings!$B$9+AB34*Settings!$B$10+AC34*Settings!$B$11+X34*Settings!$B$12+Y34*Settings!$B$13+Z34*Settings!$B$14 -> 5.6
A35: TE | B35: Other TEs | U35: 17 | AI35: =IFERROR(AB35/AA35,"") | AJ35: =IFERROR(AF35/AE35,"") | AK35: =IFERROR(AE35/AD35,"") | AL35: =IFERROR(X35/V35,"") | AM35: =IFERROR(W35/V35,"") | AN35: =IFERROR(AA35/$H$5,"") -> 0 | AO35: =IFERROR(AD35/$G$5,"") -> 0 | AP35: =IFERROR(V35/$F$5,"") -> 0 | AQ35: =IFERROR(AA35/U35,"") -> 0 | AR35: =IFERROR(AD35/U35,"") -> 0 | AS35: =IFERROR(AD35-L35,"") -> 0 | AT35: =IFERROR(AA35-H35,"") -> 0 | AU35: =AF35*Settings!$B$7+AG35*Settings!$B$8+AE35*Settings!$B$9+AB35*Settings!$B$10+AC35*Settings!$B$11+X35*Settings!$B$12+Y35*Settings!$B$13+Z35*Settings!$B$14 -> 0
A37: YOUR TOTAL | U37: =SUM(U11:U35) -> 425 | V37: =SUM(V11:V35) -> 622 | W37: =SUM(W11:W35) -> 379 | X37: =SUM(X11:X35) -> 4023 | Y37: =SUM(Y11:Y35) -> 25 | Z37: =SUM(Z11:Z35) -> 12 | AA37: =SUM(AA11:AA35) -> 428 | AB37: =SUM(AB11:AB35) -> 1940 | ... AG37: =SUM(AG11:AG35) -> 25
A38: TEAM TARGET | V38: =$F$5 -> 629 | X38: =$I$5 -> 3992 | Y38: =$J$5 -> 25 | Z38: =$K$5 -> 12 | AA38: =$H$5 -> 428.4 | AB38: =$L$5 -> 1940 | AC38: =$M$5 -> 14 | AD38: =$G$5 -> 600 | AF38: =$I$5 -> 3992 | AG38: =$J$5 -> 25
A39: LEFT | V39: =$F$5-V37 -> 7 | X39: =$I$5-X37 -> -31 | Y39: =$J$5-Y37 -> 0 | Z39: =$K$5-Z37 -> 0 | AA39: =$H$5-AA37 -> 0.4 | AB39: =$L$5-AB37 -> 0 | AC39: =$M$5-AC37 -> 1 | AD39: =$G$5-AD37 -> 43 | AF39: =$I$5-AF37 -> 0 | AG39: =$J$5-AG37 -> 0
B40: Red = you have allocated more than the team total. Amber = more than 3% under. These are targets, not hard caps - if you disagree, edit the team total above. | AF40: Rec Yds / Rec TD are checked against the PASSING totals

Sheet ATL
A1: ATL - 2026 projections (direct entry)
A3: TEAM TOTALS | D3: all editable - these are your targets, not hard caps
B4: Games | C4: Plays/G | D4: Plays | E4: Pass Rate | F4: Pass Att | G4: Targets | H4: Rush Att | I4: Pass Yds | J4: Pass TD | K4: Int | L4: Rush Yds | M4: Rush TD
B5: 17 | C5: 62.5 | D5: =C5*B5 -> 1062.5 | E5: 0.5475 | F5: =ROUND(D5*E5,0) -> 582 | G5: =ROUND(F5*Settings!$B$4,0) -> 555 | H5: =D5-F5 -> 480.5 | I5: 3893 | J5: 21 | K5: 13 | L5: 2108 | M5: 16
A7: VACATED | B7: 29% of targets and 33% of carries left this roster - that volume is yours to reassign.
A8: STAFF | B8: NEW HC Kevin Stefanski + OC Tommy Rees. Zone-heavy run game; little pass-rate change expected. Emphasis on Robinson touches.
A10: Pos | B10: Player | C10: Dep | D10: Age | E10: Status | F10: '23 Car | G10: '24 Car | H10: '25 Car | I10: '25 RuYd | J10: '23 Tgt | K10: '24 Tgt | L10: '25 Tgt | M10: '25 ReYd | N10: '25 Tm | O10: '25 G | P10: 3y Y/C | Q10: 3y Y/R | R10: 3y Ctch | S10: 3y Comp% | T10: 3y Y/A | U10: Games | V10: Pass Att | W10: Cmp | X10: Pass Yds | Y10: Pass TD | Z10: Int | AA10: Rush Att | AB10: Rush Yds | AC10: Rush TD | AD10: Targets | AE10: Rec | AF10: Rec Yds | AG10: Rec TD | AH10: Seed | AI10: Y/C | AJ10: Y/R | AK10: Catch% | AL10: Y/A | AM10: Comp% | AN10: Rush % | AO10: Tgt % | AP10: Pass % | AQ10: Car/G | AR10: Tgt/G | AS10: dTgt | AT10: dCar | AU10: Half PPR
A11: QB | B11: Tua Tagovailoa | C11: 1 | D11: 28 | E11: QUESTIONABLE | F11: 24 | G11: 11 | H11: 16 | I11: 43 | N11: MIA | O11: 14 | P11: 3.25 | S11: 0.699 | T11: 7.56 | U11: 17 | V11: 282 | W11: 196 | X11: 2180 | Y11: 12 | Z11: 7 | AA11: 17 | AB11: 40 | AC11: 0 | AD11: 0 | AE11: 0 | AF11: 0 | AG11: 0 | AH11: kept | AI11: =IFERROR(AB11/AA11,"") -> 2.3529412 | AJ11: =IFERROR(AF11/AE11,"") | AK11: =IFERROR(AE11/AD11,"") | AL11: =IFERROR(X11/V11,"") -> 7.7304965 | AM11: =IFERROR(W11/V11,"") -> 0.69503546 | AN11: =IFERROR(AA11/$H$5,"") -> 0.035379813 | AO11: =IFERROR(AD11/$G$5,"") -> 0 | AP11: =IFERROR(V11/$F$5,"") -> 0.48453608 | AQ11: =IFERROR(AA11/U11,"") -> 1 | AR11: =IFERROR(AD11/U11,"") -> 0 | AS11: =IFERROR(AD11-L11,"") -> 0 | AT11: =IFERROR(AA11-H11,"") -> 1 | AU11: =AF11*Settings!$B$7+AG11*Settings!$B$8+AE11*Settings!$B$9+AB11*Settings!$B$10+AC11*Settings!$B$11+X11*Settings!$B$12+Y11*Settings!$B$13+Z11*Settings!$B$14 -> 125.2
A12: QB | B12: Michael Penix | C12: 2 | D12: 26 | E12: QUESTIONABLE | G12: 5 | H12: 14 | I12: 70 | N12: ATL | O12: 9 | P12: 4.26 | S12: 0.596 | T12: 7.24 | U12: 17 | V12: 218 | W12: 138 | X12: 1749 | Y12: 9 | Z12: 5 | AA12: 17 | AB12: 57 | AC12: 1 | AD12: 0 | AE12: 0 | AF12: 0 | AG12: 0 | AH12: kept | AI12: =IFERROR(AB12/AA12,"") -> 3.3529412 | AJ12: =IFERROR(AF12/AE12,"") | AK12: =IFERROR(AE12/AD12,"") | AL12: =IFERROR(X12/V12,"") -> 8.0229358 | AM12: =IFERROR(W12/V12,"") -> 0.63302752 | AN12: =IFERROR(AA12/$H$5,"") -> 0.035379813 | AO12: =IFERROR(AD12/$G$5,"") -> 0 | AP12: =IFERROR(V12/$F$5,"") -> 0.37457045 | AQ12: =IFERROR(AA12/U12,"") -> 1 | AR12: =IFERROR(AD12/U12,"") -> 0 | AS12: =IFERROR(AD12-L12,"") -> 0 | AT12: =IFERROR(AA12-H12,"") -> 3 | AU12: =AF12*Settings!$B$7+AG12*Settings!$B$8+AE12*Settings!$B$9+AB12*Settings!$B$10+AC12*Settings!$B$11+X12*Settings!$B$12+Y12*Settings!$B$13+Z12*Settings!$B$14 -> 107.66
A13: QB | B13: Cooper Rush | C13: 3 | D13: 32 | E13: ACT | F13: 1 | G13: 19 | H13: 1 | I13: -4 | N13: BAL | O13: 4 | P13: 0.43 | S13: 0.622 | T13: 5.97 | U13: 17 | V13: 12 | W13: 8 | X13: 66 | Y13: 0 | Z13: 4 | AA13: 1 | AB13: -4 | AC13: 0 | AD13: 0 | AE13: 0 | AF13: 0 | AG13: 0 | AH13: kept | AI13: =IFERROR(AB13/AA13,"") -> -4 | AJ13: =IFERROR(AF13/AE13,"") | AK13: =IFERROR(AE13/AD13,"") | AL13: =IFERROR(X13/V13,"") -> 5.5 | AM13: =IFERROR(W13/V13,"") -> 0.66666667 | AN13: =IFERROR(AA13/$H$5,"") -> 0.0020811655 | AO13: =IFERROR(AD13/$G$5,"") -> 0 | AP13: =IFERROR(V13/$F$5,"") -> 0.020618557 | AQ13: =IFERROR(AA13/U13,"") -> 0.058823529 | AR13: =IFERROR(AD13/U13,"") -> 0 | AS13: =IFERROR(AD13-L13,"") -> 0 | AT13: =IFERROR(AA13-H13,"") -> 0 | AU13: =AF13*Settings!$B$7+AG13*Settings!$B$8+AE13*Settings!$B$9+AB13*Settings!$B$10+AC13*Settings!$B$11+X13*Settings!$B$12+Y13*Settings!$B$13+Z13*Settings!$B$14 -> -5.76
A14: QB | B14: Other QBs | U14: 17 | AI14: =IFERROR(AB14/AA14,"") | AJ14: =IFERROR(AF14/AE14,"") | AK14: =IFERROR(AE14/AD14,"") | AL14: =IFERROR(X14/V14,"") | AM14: =IFERROR(W14/V14,"") | AN14: =IFERROR(AA14/$H$5,"") -> 0 | AO14: =IFERROR(AD14/$G$5,"") -> 0 | AP14: =IFERROR(V14/$F$5,"") -> 0 | AQ14: =IFERROR(AA14/U14,"") -> 0 | AR14: =IFERROR(AD14/U14,"") -> 0 | AS14: =IFERROR(AD14-L14,"") -> 0 | AT14: =IFERROR(AA14-H14,"") -> 0 | AU14: =AF14*Settings!$B$7+AG14*Settings!$B$8+AE14*Settings!$B$9+AB14*Settings!$B$10+AC14*Settings!$B$11+X14*Settings!$B$12+Y14*Settings!$B$13+Z14*Settings!$B$14 -> 0
A15: RB | B15: Bijan Robinson | C15: 1 | D15: 24 | E15: ACT | F15: 214 | G15: 304 | H15: 287 | I15: 1478 | J15: 86 | K15: 72 | L15: 103 | M15: 820 | N15: ATL | O15: 17 | P15: 4.86 | Q15: 8.78 | R15: 0.759 | U15: 17 | V15: 0 | W15: 0 | X15: 0 | Y15: 0 | Z15: 0 | AA15: 273 | AB15: 1344 | AC15: 9 | AD15: 94 | AE15: 73 | AF15: 680 | AG15: 3 | AH15: kept | AI15: =IFERROR(AB15/AA15,"") -> 4.9230769 | AJ15: =IFERROR(AF15/AE15,"") -> 9.3150685 | AK15: =IFERROR(AE15/AD15,"") -> 0.77659574 | AL15: =IFERROR(X15/V15,"") | AM15: =IFERROR(W15/V15,"") | AN15: =IFERROR(AA15/$H$5,"") -> 0.56815817 | AO15: =IFERROR(AD15/$G$5,"") -> 0.16936937 | AP15: =IFERROR(V15/$F$5,"") -> 0 | AQ15: =IFERROR(AA15/U15,"") -> 16.058824 | AR15: =IFERROR(AD15/U15,"") -> 5.5294118 | AS15: =IFERROR(AD15-L15,"") -> -9 | AT15: =IFERROR(AA15-H15,"") -> -14 | AU15: =AF15*Settings!$B$7+AG15*Settings!$B$8+AE15*Settings!$B$9+AB15*Settings!$B$10+AC15*Settings!$B$11+X15*Settings!$B$12+Y15*Settings!$B$13+Z15*Settings!$B$14 -> 310.9
A16: RB | B16: Brian Robinson | C16: 2 | D16: 27 | E16: ACT | F16: 178 | G16: 187 | H16: 92 | I16: 400 | J16: 43 | K16: 25 | L16: 12 | M16: 25 | N16: SF | O16: 17 | P16: 4.23 | Q16: 8.62 | R16: 0.8 | U16: 17 | V16: 0 | W16: 0 | X16: 0 | Y16: 0 | Z16: 0 | AA16: 117 | AB16: 500 | AC16: 4 | AD16: 11 | AE16: 9 | AF16: 62 | AG16: 0 | AH16: kept | AI16: =IFERROR(AB16/AA16,"") -> 4.2735043 | AJ16: =IFERROR(AF16/AE16,"") -> 6.8888889 | AK16: =IFERROR(AE16/AD16,"") -> 0.81818182 | AL16: =IFERROR(X16/V16,"") | AM16: =IFERROR(W16/V16,"") | AN16: =IFERROR(AA16/$H$5,"") -> 0.24349636 | AO16: =IFERROR(AD16/$G$5,"") -> 0.01981982 | AP16: =IFERROR(V16/$F$5,"") -> 0 | AQ16: =IFERROR(AA16/U16,"") -> 6.8823529 | AR16: =IFERROR(AD16/U16,"") -> 0.64705882 | AS16: =IFERROR(AD16-L16,"") -> -1 | AT16: =IFERROR(AA16-H16,"") -> 25 | AU16: =AF16*Settings!$B$7+AG16*Settings!$B$8+AE16*Settings!$B$9+AB16*Settings!$B$10+AC16*Settings!$B$11+X16*Settings!$B$12+Y16*Settings!$B$13+Z16*Settings!$B$14 -> 84.7
A17: RB | B17: Tyler Goodson | C17: 3 | D17: 25 | E17: ACT | F17: 13 | G17: 32 | H17: 9 | I17: 24 | J17: 9 | K17: 15 | L17: 3 | M17: 8 | N17: IND | O17: 11 | P17: 4.89 | Q17: 5.42 | R17: 0.704 | U17: 17 | V17: 0 | W17: 0 | X17: 0 | Y17: 0 | Z17: 0 | AA17: 22 | AB17: 76 | AC17: 1 | AD17: 4 | AE17: 4 | AF17: 25 | AG17: 0 | AH17: kept | AI17: =IFERROR(AB17/AA17,"") -> 3.4545455 | AJ17: =IFERROR(AF17/AE17,"") -> 6.25 | AK17: =IFERROR(AE17/AD17,"") -> 1 | AL17: =IFERROR(X17/V17,"") | AM17: =IFERROR(W17/V17,"") | AN17: =IFERROR(AA17/$H$5,"") -> 0.04578564 | AO17: =IFERROR(AD17/$G$5,"") -> 0.0072072072 | AP17: =IFERROR(V17/$F$5,"") -> 0 | AQ17: =IFERROR(AA17/U17,"") -> 1.2941176 | AR17: =IFERROR(AD17/U17,"") -> 0.23529412 | AS17: =IFERROR(AD17-L17,"") -> 1 | AT17: =IFERROR(AA17-H17,"") -> 13 | AU17: =AF17*Settings!$B$7+AG17*Settings!$B$8+AE17*Settings!$B$9+AB17*Settings!$B$10+AC17*Settings!$B$11+X17*Settings!$B$12+Y17*Settings!$B$13+Z17*Settings!$B$14 -> 18.1
A18: RB | B18: Nathan Carter | C18: 4 | D18: 24 | E18: ACT | H18: 9 | I18: 60 | N18: ATL | O18: 7 | P18: 6.67 | U18: 17 | V18: 0 | W18: 0 | X18: 0 | Y18: 0 | Z18: 0 | AA18: 10 | AB18: 64 | AC18: 1 | AD18: 0 | AE18: 0 | AF18: 0 | AG18: 0 | AH18: kept | AI18: =IFERROR(AB18/AA18,"") -> 6.4 | AJ18: =IFERROR(AF18/AE18,"") | AK18: =IFERROR(AE18/AD18,"") | AL18: =IFERROR(X18/V18,"") | AM18: =IFERROR(W18/V18,"") | AN18: =IFERROR(AA18/$H$5,"") -> 0.020811655 | AO18: =IFERROR(AD18/$G$5,"") -> 0 | AP18: =IFERROR(V18/$F$5,"") -> 0 | AQ18: =IFERROR(AA18/U18,"") -> 0.58823529 | AR18: =IFERROR(AD18/U18,"") -> 0 | AS18: =IFERROR(AD18-L18,"") -> 0 | AT18: =IFERROR(AA18-H18,"") -> 1 | AU18: =AF18*Settings!$B$7+AG18*Settings!$B$8+AE18*Settings!$B$9+AB18*Settings!$B$10+AC18*Settings!$B$11+X18*Settings!$B$12+Y18*Settings!$B$13+Z18*Settings!$B$14 -> 12.4
A19: RB | B19: Cash Jones | C19: 5 | D19: 24 | E19: ACT | U19: 17 | AI19: =IFERROR(AB19/AA19,"") | AJ19: =IFERROR(AF19/AE19,"") | AK19: =IFERROR(AE19/AD19,"") | AL19: =IFERROR(X19/V19,"") | AM19: =IFERROR(W19/V19,"") | AN19: =IFERROR(AA19/$H$5,"") -> 0 | AO19: =IFERROR(AD19/$G$5,"") -> 0 | AP19: =IFERROR(V19/$F$5,"") -> 0 | AQ19: =IFERROR(AA19/U19,"") -> 0 | AR19: =IFERROR(AD19/U19,"") -> 0 | AS19: =IFERROR(AD19-L19,"") -> 0 | AT19: =IFERROR(AA19-H19,"") -> 0 | AU19: =AF19*Settings!$B$7+AG19*Settings!$B$8+AE19*Settings!$B$9+AB19*Settings!$B$10+AC19*Settings!$B$11+X19*Settings!$B$12+Y19*Settings!$B$13+Z19*Settings!$B$14 -> 0
A20: RB | AI20: =IFERROR(AB20/AA20,"") | AJ20: =IFERROR(AF20/AE20,"") | AK20: =IFERROR(AE20/AD20,"") | AL20: =IFERROR(X20/V20,"") | AM20: =IFERROR(W20/V20,"") | AN20: =IFERROR(AA20/$H$5,"") -> 0 | AO20: =IFERROR(AD20/$G$5,"") -> 0 | AP20: =IFERROR(V20/$F$5,"") -> 0 | AQ20: =IFERROR(AA20/U20,"") | AR20: =IFERROR(AD20/U20,"") | AS20: =IFERROR(AD20-L20,"") -> 0 | AT20: =IFERROR(AA20-H20,"") -> 0 | AU20: =AF20*Settings!$B$7+AG20*Settings!$B$8+AE20*Settings!$B$9+AB20*Settings!$B$10+AC20*Settings!$B$11+X20*Settings!$B$12+Y20*Settings!$B$13+Z20*Settings!$B$14 -> 0
A21: RB | B21: Other RBs | U21: 17 | AI21: =IFERROR(AB21/AA21,"") | AJ21: =IFERROR(AF21/AE21,"") | AK21: =IFERROR(AE21/AD21,"") | AL21: =IFERROR(X21/V21,"") | AM21: =IFERROR(W21/V21,"") | AN21: =IFERROR(AA21/$H$5,"") -> 0 | AO21: =IFERROR(AD21/$G$5,"") -> 0 | AP21: =IFERROR(V21/$F$5,"") -> 0 | AQ21: =IFERROR(AA21/U21,"") -> 0 | AR21: =IFERROR(AD21/U21,"") -> 0 | AS21: =IFERROR(AD21-L21,"") -> 0 | AT21: =IFERROR(AA21-H21,"") -> 0 | AU21: =AF21*Settings!$B$7+AG21*Settings!$B$8+AE21*Settings!$B$9+AB21*Settings!$B$10+AC21*Settings!$B$11+X21*Settings!$B$12+Y21*Settings!$B$13+Z21*Settings!$B$14 -> 0
A22: WR | B22: Drake London | C22: 1 | D22: 25 | E22: ACT | G22: 1 | J22: 110 | K22: 158 | L22: 112 | M22: 919 | N22: ATL | O22: 12 | P22: -3 | Q22: 13.06 | R22: 0.624 | S22: 1 | U22: 17 | V22: 0 | W22: 0 | X22: 0 | Y22: 0 | Z22: 0 | AA22: 0 | AB22: 0 | AC22: 0 | AD22: 148 | AE22: 89 | AF22: 1189 | AG22: 7 | AH22: kept | AI22: =IFERROR(AB22/AA22,"") | AJ22: =IFERROR(AF22/AE22,"") -> 13.359551 | AK22: =IFERROR(AE22/AD22,"") -> 0.60135135 | AL22: =IFERROR(X22/V22,"") | AM22: =IFERROR(W22/V22,"") | AN22: =IFERROR(AA22/$H$5,"") -> 0 | AO22: =IFERROR(AD22/$G$5,"") -> 0.26666667 | AP22: =IFERROR(V22/$F$5,"") -> 0 | AQ22: =IFERROR(AA22/U22,"") -> 0 | AR22: =IFERROR(AD22/U22,"") -> 8.7058824 | AS22: =IFERROR(AD22-L22,"") -> 36 | AT22: =IFERROR(AA22-H22,"") -> 0 | AU22: =AF22*Settings!$B$7+AG22*Settings!$B$8+AE22*Settings!$B$9+AB22*Settings!$B$10+AC22*Settings!$B$11+X22*Settings!$B$12+Y22*Settings!$B$13+Z22*Settings!$B$14 -> 205.4
A23: WR | B23: Zachariah Branch | C23: 2 | D23: 22 | E23: ACT | U23: 17 | AA23: 3 | AB23: 22 | AC23: 0 | AD23: 54 | AE23: 35 | AF23: 415 | AG23: 2 | AH23: kept | AI23: =IFERROR(AB23/AA23,"") -> 7.3333333 | AJ23: =IFERROR(AF23/AE23,"") -> 11.857143 | AK23: =IFERROR(AE23/AD23,"") -> 0.64814815 | AL23: =IFERROR(X23/V23,"") | AM23: =IFERROR(W23/V23,"") | AN23: =IFERROR(AA23/$H$5,"") -> 0.0062434964 | AO23: =IFERROR(AD23/$G$5,"") -> 0.097297297 | AP23: =IFERROR(V23/$F$5,"") -> 0 | AQ23: =IFERROR(AA23/U23,"") -> 0.17647059 | AR23: =IFERROR(AD23/U23,"") -> 3.1764706 | AS23: =IFERROR(AD23-L23,"") -> 54 | AT23: =IFERROR(AA23-H23,"") -> 3 | AU23: =AF23*Settings!$B$7+AG23*Settings!$B$8+AE23*Settings!$B$9+AB23*Settings!$B$10+AC23*Settings!$B$11+X23*Settings!$B$12+Y23*Settings!$B$13+Z23*Settings!$B$14 -> 73.2
A24: WR | B24: Jahan Dotson | C24: 3 | D24: 26 | E24: ACT | G24: 1 | J24: 83 | K24: 33 | L24: 36 | M24: 262 | N24: PHI | O24: 17 | P24: 13 | Q24: 11.58 | R24: 0.566 | U24: 17 | V24: 0 | W24: 0 | X24: 0 | Y24: 0 | Z24: 0 | AA24: 0 | AB24: 1 | AC24: 0 | AD24: 43 | AE24: 25 | AF24: 326 | AG24: 2 | AH24: kept | AI24: =IFERROR(AB24/AA24,"") | AJ24: =IFERROR(AF24/AE24,"") -> 13.04 | AK24: =IFERROR(AE24/AD24,"") -> 0.58139535 | AL24: =IFERROR(X24/V24,"") | AM24: =IFERROR(W24/V24,"") | AN24: =IFERROR(AA24/$H$5,"") -> 0 | AO24: =IFERROR(AD24/$G$5,"") -> 0.077477477 | AP24: =IFERROR(V24/$F$5,"") -> 0 | AQ24: =IFERROR(AA24/U24,"") -> 0 | AR24: =IFERROR(AD24/U24,"") -> 2.5294118 | AS24: =IFERROR(AD24-L24,"") -> 7 | AT24: =IFERROR(AA24-H24,"") -> 0 | AU24: =AF24*Settings!$B$7+AG24*Settings!$B$8+AE24*Settings!$B$9+AB24*Settings!$B$10+AC24*Settings!$B$11+X24*Settings!$B$12+Y24*Settings!$B$13+Z24*Settings!$B$14 -> 57.2
A25: WR | B25: Olamide Zaccheaus | C25: 4 | D25: 29 | E25: ACT | G25: 1 | H25: 4 | I25: 25 | J25: 20 | K25: 64 | L25: 65 | M25: 313 | N25: CHI | O25: 16 | P25: 6.6 | Q25: 10.46 | R25: 0.631 | U25: 17 | V25: 0 | W25: 0 | X25: 0 | Y25: 0 | Z25: 0 | AA25: 1 | AB25: 6 | AC25: 0 | AD25: 44 | AE25: 28 | AF25: 278 | AG25: 2 | AH25: kept | AI25: =IFERROR(AB25/AA25,"") -> 6 | AJ25: =IFERROR(AF25/AE25,"") -> 9.9285714 | AK25: =IFERROR(AE25/AD25,"") -> 0.63636364 | AL25: =IFERROR(X25/V25,"") | AM25: =IFERROR(W25/V25,"") | AN25: =IFERROR(AA25/$H$5,"") -> 0.0020811655 | AO25: =IFERROR(AD25/$G$5,"") -> 0.079279279 | AP25: =IFERROR(V25/$F$5,"") -> 0 | AQ25: =IFERROR(AA25/U25,"") -> 0.058823529 | AR25: =IFERROR(AD25/U25,"") -> 2.5882353 | AS25: =IFERROR(AD25-L25,"") -> -21 | AT25: =IFERROR(AA25-H25,"") -> -3 | AU25: =AF25*Settings!$B$7+AG25*Settings!$B$8+AE25*Settings!$B$9+AB25*Settings!$B$10+AC25*Settings!$B$11+X25*Settings!$B$12+Y25*Settings!$B$13+Z25*Settings!$B$14 -> 54.4
A26: WR | B26: Dylan Drummond | C26: 5 | D26: 26 | E26: ACT | L26: 11 | M26: 42 | N26: ATL | O26: 9 | Q26: 6 | R26: 0.636 | U26: 17 | V26: 0 | W26: 0 | X26: 0 | Y26: 0 | Z26: 0 | AA26: 0 | AB26: 0 | AC26: 0 | AD26: 11 | AE26: 7 | AF26: 42 | AG26: 0 | AH26: kept | AI26: =IFERROR(AB26/AA26,"") | AJ26: =IFERROR(AF26/AE26,"") -> 6 | AK26: =IFERROR(AE26/AD26,"") -> 0.63636364 | AL26: =IFERROR(X26/V26,"") | AM26: =IFERROR(W26/V26,"") | AN26: =IFERROR(AA26/$H$5,"") -> 0 | AO26: =IFERROR(AD26/$G$5,"") -> 0.01981982 | AP26: =IFERROR(V26/$F$5,"") -> 0 | AQ26: =IFERROR(AA26/U26,"") -> 0 | AR26: =IFERROR(AD26/U26,"") -> 0.64705882 | AS26: =IFERROR(AD26-L26,"") -> 0 | AT26: =IFERROR(AA26-H26,"") -> 0 | AU26: =AF26*Settings!$B$7+AG26*Settings!$B$8+AE26*Settings!$B$9+AB26*Settings!$B$10+AC26*Settings!$B$11+X26*Settings!$B$12+Y26*Settings!$B$13+Z26*Settings!$B$14 -> 7.7
A27: WR | B27: Chris Blair | C27: 6 | D27: 28 | E27: ACT | K27: 2 | Q27: 17 | R27: 0.5 | U27: 17 | AI27: =IFERROR(AB27/AA27,"") | AJ27: =IFERROR(AF27/AE27,"") | AK27: =IFERROR(AE27/AD27,"") | AL27: =IFERROR(X27/V27,"") | AM27: =IFERROR(W27/V27,"") | AN27: =IFERROR(AA27/$H$5,"") -> 0 | AO27: =IFERROR(AD27/$G$5,"") -> 0 | AP27: =IFERROR(V27/$F$5,"") -> 0 | AQ27: =IFERROR(AA27/U27,"") -> 0 | AR27: =IFERROR(AD27/U27,"") -> 0 | AS27: =IFERROR(AD27-L27,"") -> 0 | AT27: =IFERROR(AA27-H27,"") -> 0 | AU27: =AF27*Settings!$B$7+AG27*Settings!$B$8+AE27*Settings!$B$9+AB27*Settings!$B$10+AC27*Settings!$B$11+X27*Settings!$B$12+Y27*Settings!$B$13+Z27*Settings!$B$14 -> 0
A28: WR | B28: Antwane Wells | C28: 7 | D28: 25 | E28: ACT | U28: 17 | AI28: =IFERROR(AB28/AA28,"") | AJ28: =IFERROR(AF28/AE28,"") | AK28: =IFERROR(AE28/AD28,"") | AL28: =IFERROR(X28/V28,"") | AM28: =IFERROR(W28/V28,"") | AN28: =IFERROR(AA28/$H$5,"") -> 0 | AO28: =IFERROR(AD28/$G$5,"") -> 0 | AP28: =IFERROR(V28/$F$5,"") -> 0 | AQ28: =IFERROR(AA28/U28,"") -> 0 | AR28: =IFERROR(AD28/U28,"") -> 0 | AS28: =IFERROR(AD28-L28,"") -> 0 | AT28: =IFERROR(AA28-H28,"") -> 0 | AU28: =AF28*Settings!$B$7+AG28*Settings!$B$8+AE28*Settings!$B$9+AB28*Settings!$B$10+AC28*Settings!$B$11+X28*Settings!$B$12+Y28*Settings!$B$13+Z28*Settings!$B$14 -> 0
A29: WR | B29: Vinny Anthony | C29: 8 | E29: ACT | U29: 17 | AA29: 0 | AB29: 0 | AC29: 0 | AD29: 0 | AE29: 2 | AF29: 20 | AG29: 0 | AH29: kept | AI29: =IFERROR(AB29/AA29,"") | AJ29: =IFERROR(AF29/AE29,"") -> 10 | AK29: =IFERROR(AE29/AD29,"") | AL29: =IFERROR(X29/V29,"") | AM29: =IFERROR(W29/V29,"") | AN29: =IFERROR(AA29/$H$5,"") -> 0 | AO29: =IFERROR(AD29/$G$5,"") -> 0 | AP29: =IFERROR(V29/$F$5,"") -> 0 | AQ29: =IFERROR(AA29/U29,"") -> 0 | AR29: =IFERROR(AD29/U29,"") -> 0 | AS29: =IFERROR(AD29-L29,"") -> 0 | AT29: =IFERROR(AA29-H29,"") -> 0 | AU29: =AF29*Settings!$B$7+AG29*Settings!$B$8+AE29*Settings!$B$9+AB29*Settings!$B$10+AC29*Settings!$B$11+X29*Settings!$B$12+Y29*Settings!$B$13+Z29*Settings!$B$14 -> 3
A30: WR | B30: Other WRs | U30: 17 | AI30: =IFERROR(AB30/AA30,"") | AJ30: =IFERROR(AF30/AE30,"") | AK30: =IFERROR(AE30/AD30,"") | AL30: =IFERROR(X30/V30,"") | AM30: =IFERROR(W30/V30,"") | AN30: =IFERROR(AA30/$H$5,"") -> 0 | AO30: =IFERROR(AD30/$G$5,"") -> 0 | AP30: =IFERROR(V30/$F$5,"") -> 0 | AQ30: =IFERROR(AA30/U30,"") -> 0 | AR30: =IFERROR(AD30/U30,"") -> 0 | AS30: =IFERROR(AD30-L30,"") -> 0 | AT30: =IFERROR(AA30-H30,"") -> 0 | AU30: =AF30*Settings!$B$7+AG30*Settings!$B$8+AE30*Settings!$B$9+AB30*Settings!$B$10+AC30*Settings!$B$11+X30*Settings!$B$12+Y30*Settings!$B$13+Z30*Settings!$B$14 -> 0
A31: TE | B31: Kyle Pitts | C31: 1 | D31: 25 | E31: ACT | F31: 1 | J31: 90 | K31: 74 | L31: 118 | M31: 928 | N31: ATL | O31: 17 | P31: -4 | Q31: 11.69 | R31: 0.667 | U31: 17 | V31: 0 | W31: 0 | X31: 0 | Y31: 0 | Z31: 0 | AA31: 0 | AB31: 0 | AC31: 0 | AD31: 106 | AE31: 73 | AF31: 772 | AG31: 4 | AH31: kept | AI31: =IFERROR(AB31/AA31,"") | AJ31: =IFERROR(AF31/AE31,"") -> 10.575342 | AK31: =IFERROR(AE31/AD31,"") -> 0.68867925 | AL31: =IFERROR(X31/V31,"") | AM31: =IFERROR(W31/V31,"") | AN31: =IFERROR(AA31/$H$5,"") -> 0 | AO31: =IFERROR(AD31/$G$5,"") -> 0.19099099 | AP31: =IFERROR(V31/$F$5,"") -> 0 | AQ31: =IFERROR(AA31/U31,"") -> 0 | AR31: =IFERROR(AD31/U31,"") -> 6.2352941 | AS31: =IFERROR(AD31-L31,"") -> -12 | AT31: =IFERROR(AA31-H31,"") -> 0 | AU31: =AF31*Settings!$B$7+AG31*Settings!$B$8+AE31*Settings!$B$9+AB31*Settings!$B$10+AC31*Settings!$B$11+X31*Settings!$B$12+Y31*Settings!$B$13+Z31*Settings!$B$14 -> 137.7
A32: TE | B32: Austin Hooper | C32: 2 | D32: 31 | E32: ACT | J32: 31 | K32: 59 | L32: 26 | M32: 263 | N32: NE | O32: 16 | Q32: 10.69 | R32: 0.784 | U32: 17 | V32: 0 | W32: 0 | X32: 0 | Y32: 0 | Z32: 0 | AA32: 0 | AB32: 0 | AC32: 0 | AD32: 18 | AE32: 15 | AF32: 124 | AG32: 1 | AH32: kept | AI32: =IFERROR(AB32/AA32,"") | AJ32: =IFERROR(AF32/AE32,"") -> 8.2666667 | AK32: =IFERROR(AE32/AD32,"") -> 0.83333333 | AL32: =IFERROR(X32/V32,"") | AM32: =IFERROR(W32/V32,"") | AN32: =IFERROR(AA32/$H$5,"") -> 0 | AO32: =IFERROR(AD32/$G$5,"") -> 0.032432432 | AP32: =IFERROR(V32/$F$5,"") -> 0 | AQ32: =IFERROR(AA32/U32,"") -> 0 | AR32: =IFERROR(AD32/U32,"") -> 1.0588235 | AS32: =IFERROR(AD32-L32,"") -> -8 | AT32: =IFERROR(AA32-H32,"") -> 0 | AU32: =AF32*Settings!$B$7+AG32*Settings!$B$8+AE32*Settings!$B$9+AB32*Settings!$B$10+AC32*Settings!$B$11+X32*Settings!$B$12+Y32*Settings!$B$13+Z32*Settings!$B$14 -> 25.9
A33: TE | B33: Charlie Woerner | C33: 3 | D33: 28 | E33: ACT | J33: 3 | K33: 12 | L33: 9 | M33: 48 | N33: ATL | O33: 17 | Q33: 7 | R33: 0.75 | U33: 17 | V33: 0 | W33: 0 | X33: 0 | Y33: 0 | Z33: 0 | AA33: 0 | AB33: 0 | AC33: 0 | AD33: 13 | AE33: 9 | AF33: 49 | AG33: 0 | AH33: kept | AI33: =IFERROR(AB33/AA33,"") | AJ33: =IFERROR(AF33/AE33,"") -> 5.4444444 | AK33: =IFERROR(AE33/AD33,"") -> 0.69230769 | AL33: =IFERROR(X33/V33,"") | AM33: =IFERROR(W33/V33,"") | AN33: =IFERROR(AA33/$H$5,"") -> 0 | AO33: =IFERROR(AD33/$G$5,"") -> 0.023423423 | AP33: =IFERROR(V33/$F$5,"") -> 0 | AQ33: =IFERROR(AA33/U33,"") -> 0 | AR33: =IFERROR(AD33/U33,"") -> 0.76470588 | AS33: =IFERROR(AD33-L33,"") -> 4 | AT33: =IFERROR(AA33-H33,"") -> 0 | AU33: =AF33*Settings!$B$7+AG33*Settings!$B$8+AE33*Settings!$B$9+AB33*Settings!$B$10+AC33*Settings!$B$11+X33*Settings!$B$12+Y33*Settings!$B$13+Z33*Settings!$B$14 -> 9.4
A34: TE | B34: Joshua Simon | C34: 4 | D34: 25 | E34: ACT | U34: 17 | AI34: =IFERROR(AB34/AA34,"") | AJ34: =IFERROR(AF34/AE34,"") | AK34: =IFERROR(AE34/AD34,"") | AL34: =IFERROR(X34/V34,"") | AM34: =IFERROR(W34/V34,"") | AN34: =IFERROR(AA34/$H$5,"") -> 0 | AO34: =IFERROR(AD34/$G$5,"") -> 0 | AP34: =IFERROR(V34/$F$5,"") -> 0 | AQ34: =IFERROR(AA34/U34,"") -> 0 | AR34: =IFERROR(AD34/U34,"") -> 0 | AS34: =IFERROR(AD34-L34,"") -> 0 | AT34: =IFERROR(AA34-H34,"") -> 0 | AU34: =AF34*Settings!$B$7+AG34*Settings!$B$8+AE34*Settings!$B$9+AB34*Settings!$B$10+AC34*Settings!$B$11+X34*Settings!$B$12+Y34*Settings!$B$13+Z34*Settings!$B$14 -> 0
A35: TE | B35: Other TEs | U35: 17 | AI35: =IFERROR(AB35/AA35,"") | AJ35: =IFERROR(AF35/AE35,"") | AK35: =IFERROR(AE35/AD35,"") | AL35: =IFERROR(X35/V35,"") | AM35: =IFERROR(W35/V35,"") | AN35: =IFERROR(AA35/$H$5,"") -> 0 | AO35: =IFERROR(AD35/$G$5,"") -> 0 | AP35: =IFERROR(V35/$F$5,"") -> 0 | AQ35: =IFERROR(AA35/U35,"") -> 0 | AR35: =IFERROR(AD35/U35,"") -> 0 | AS35: =IFERROR(AD35-L35,"") -> 0 | AT35: =IFERROR(AA35-H35,"") -> 0 | AU35: =AF35*Settings!$B$7+AG35*Settings!$B$8+AE35*Settings!$B$9+AB35*Settings!$B$10+AC35*Settings!$B$11+X35*Settings!$B$12+Y35*Settings!$B$13+Z35*Settings!$B$14 -> 0
A37: YOUR TOTAL | U37: =SUM(U11:U35) -> 408 | V37: =SUM(V11:V35) -> 512 | W37: =SUM(W11:W35) -> 342 | X37: =SUM(X11:X35) -> 3995 | Y37: =SUM(Y11:Y35) -> 21 | Z37: =SUM(Z11:Z35) -> 16 | AA37: =SUM(AA11:AA35) -> 461 | AB37: =SUM(AB11:AB35) -> 2106 | ... AG37: =SUM(AG11:AG35) -> 21
A38: TEAM TARGET | V38: =$F$5 -> 582 | X38: =$I$5 -> 3893 | Y38: =$J$5 -> 21 | Z38: =$K$5 -> 13 | AA38: =$H$5 -> 480.5 | AB38: =$L$5 -> 2108 | AC38: =$M$5 -> 16 | AD38: =$G$5 -> 555 | AF38: =$I$5 -> 3893 | AG38: =$J$5 -> 21
A39: LEFT | V39: =$F$5-V37 -> 70 | X39: =$I$5-X37 -> -102 | Y39: =$J$5-Y37 -> 0 | Z39: =$K$5-Z37 -> -3 | AA39: =$H$5-AA37 -> 19.5 | AB39: =$L$5-AB37 -> 2 | AC39: =$M$5-AC37 -> 0 | AD39: =$G$5-AD37 -> 9 | AF39: =$I$5-AF37 -> -89 | AG39: =$J$5-AG37 -> 0
B40: Red = you have allocated more than the team total. Amber = more than 3% under. These are targets, not hard caps - if you disagree, edit the team total above. | AF40: Rec Yds / Rec TD are checked against the PASSING totals

Sheet BAL
A1: BAL - 2026 projections (direct entry)
A3: TEAM TOTALS | D3: all editable - these are your targets, not hard caps
B4: Games | C4: Plays/G | D4: Plays | E4: Pass Rate | F4: Pass Att | G4: Targets | H4: Rush Att | I4: Pass Yds | J4: Pass TD | K4: Int | L4: Rush Yds | M4: Rush TD
B5: 17 | C5: 60.7 | D5: =C5*B5 -> 1031.9 | E5: 0.5063 | F5: =ROUND(D5*E5,0) -> 522 | G5: =ROUND(F5*Settings!$B$4,0) -> 498 | H5: =D5-F5 -> 509.9 | I5: 3763 | J5: 28 | K5: 10 | L5: 2551 | M5: 20
A7: VACATED | B7: 27% of targets and 12% of carries left this roster - that volume is yours to reassign.
A8: STAFF | B8: NEW HC Jesse Minter + OC Declan Doyle. More explosive plays expected - Doyle brings creativity and detail.
A10: Pos | B10: Player | C10: Dep | D10: Age | E10: Status | F10: '23 Car | G10: '24 Car | H10: '25 Car | I10: '25 RuYd | J10: '23 Tgt | K10: '24 Tgt | L10: '25 Tgt | M10: '25 ReYd | N10: '25 Tm | O10: '25 G | P10: 3y Y/C | Q10: 3y Y/R | R10: 3y Ctch | S10: 3y Comp% | T10: 3y Y/A | U10: Games | V10: Pass Att | W10: Cmp | X10: Pass Yds | Y10: Pass TD | Z10: Int | AA10: Rush Att | AB10: Rush Yds | AC10: Rush TD | AD10: Targets | AE10: Rec | AF10: Rec Yds | AG10: Rec TD | AH10: Seed | AI10: Y/C | AJ10: Y/R | AK10: Catch% | AL10: Y/A | AM10: Comp% | AN10: Rush % | AO10: Tgt % | AP10: Pass % | AQ10: Car/G | AR10: Tgt/G | AS10: dTgt | AT10: dCar | AU10: Half PPR
A11: QB | B11: Lamar Jackson | C11: 1 | D11: 29 | E11: ACT | F11: 139 | G11: 127 | H11: 58 | I11: 349 | N11: BAL | O11: 13 | P11: 6.44 | S11: 0.661 | T11: 8.43 | U11: 17 | V11: 450 | W11: 291 | X11: 3599 | Y11: 27 | Z11: 9 | AA11: 117 | AB11: 639 | AC11: 3 | AD11: 0 | AE11: 0 | AF11: 0 | AG11: 0 | AH11: kept | AI11: =IFERROR(AB11/AA11,"") -> 5.4615385 | AJ11: =IFERROR(AF11/AE11,"") | AK11: =IFERROR(AE11/AD11,"") | AL11: =IFERROR(X11/V11,"") -> 7.9977778 | AM11: =IFERROR(W11/V11,"") -> 0.64666667 | AN11: =IFERROR(AA11/$H$5,"") -> 0.22945676 | AO11: =IFERROR(AD11/$G$5,"") -> 0 | AP11: =IFERROR(V11/$F$5,"") -> 0.86206897 | AQ11: =IFERROR(AA11/U11,"") -> 6.8823529 | AR11: =IFERROR(AD11/U11,"") -> 0 | AS11: =IFERROR(AD11-L11,"") -> 0 | AT11: =IFERROR(AA11-H11,"") -> 59 | AU11: =AF11*Settings!$B$7+AG11*Settings!$B$8+AE11*Settings!$B$9+AB11*Settings!$B$10+AC11*Settings!$B$11+X11*Settings!$B$12+Y11*Settings!$B$13+Z11*Settings!$B$14 -> 315.86
A12: QB | B12: Tyler Huntley | C12: 2 | D12: 28 | E12: ACT | F12: 11 | G12: 25 | H12: 19 | I12: 151 | N12: BAL | O12: 5 | P12: 6.2 | S12: 0.671 | T12: 6.15 | U12: 17 | V12: 30 | W12: 20 | X12: 200 | Y12: 1 | Z12: 1 | AA12: 4 | AB12: 21 | AC12: 0 | AD12: 0 | AE12: 0 | AF12: 0 | AG12: 0 | AH12: kept | AI12: =IFERROR(AB12/AA12,"") -> 5.25 | AJ12: =IFERROR(AF12/AE12,"") | AK12: =IFERROR(AE12/AD12,"") | AL12: =IFERROR(X12/V12,"") -> 6.6666667 | AM12: =IFERROR(W12/V12,"") -> 0.66666667 | AN12: =IFERROR(AA12/$H$5,"") -> 0.0078446754 | AO12: =IFERROR(AD12/$G$5,"") -> 0 | AP12: =IFERROR(V12/$F$5,"") -> 0.057471264 | AQ12: =IFERROR(AA12/U12,"") -> 0.23529412 | AR12: =IFERROR(AD12/U12,"") -> 0 | AS12: =IFERROR(AD12-L12,"") -> 0 | AT12: =IFERROR(AA12-H12,"") -> -15 | AU12: =AF12*Settings!$B$7+AG12*Settings!$B$8+AE12*Settings!$B$9+AB12*Settings!$B$10+AC12*Settings!$B$11+X12*Settings!$B$12+Y12*Settings!$B$13+Z12*Settings!$B$14 -> 12.1
A13: QB | B13: Skylar Thompson | C13: 3 | D13: 29 | E13: ACT | G13: 1 | P13: 4 | S13: 0.636 | T13: 5.67 | U13: 17 | AI13: =IFERROR(AB13/AA13,"") | AJ13: =IFERROR(AF13/AE13,"") | AK13: =IFERROR(AE13/AD13,"") | AL13: =IFERROR(X13/V13,"") | AM13: =IFERROR(W13/V13,"") | AN13: =IFERROR(AA13/$H$5,"") -> 0 | AO13: =IFERROR(AD13/$G$5,"") -> 0 | AP13: =IFERROR(V13/$F$5,"") -> 0 | AQ13: =IFERROR(AA13/U13,"") -> 0 | AR13: =IFERROR(AD13/U13,"") -> 0 | AS13: =IFERROR(AD13-L13,"") -> 0 | AT13: =IFERROR(AA13-H13,"") -> 0 | AU13: =AF13*Settings!$B$7+AG13*Settings!$B$8+AE13*Settings!$B$9+AB13*Settings!$B$10+AC13*Settings!$B$11+X13*Settings!$B$12+Y13*Settings!$B$13+Z13*Settings!$B$14 -> 0
A14: QB | B14: Other QBs | U14: 17 | AI14: =IFERROR(AB14/AA14,"") | AJ14: =IFERROR(AF14/AE14,"") | AK14: =IFERROR(AE14/AD14,"") | AL14: =IFERROR(X14/V14,"") | AM14: =IFERROR(W14/V14,"") | AN14: =IFERROR(AA14/$H$5,"") -> 0 | AO14: =IFERROR(AD14/$G$5,"") -> 0 | AP14: =IFERROR(V14/$F$5,"") -> 0 | AQ14: =IFERROR(AA14/U14,"") -> 0 | AR14: =IFERROR(AD14/U14,"") -> 0 | AS14: =IFERROR(AD14-L14,"") -> 0 | AT14: =IFERROR(AA14-H14,"") -> 0 | AU14: =AF14*Settings!$B$7+AG14*Settings!$B$8+AE14*Settings!$B$9+AB14*Settings!$B$10+AC14*Settings!$B$11+X14*Settings!$B$12+Y14*Settings!$B$13+Z14*Settings!$B$14 -> 0
A15: RB | B15: Derrick Henry | C15: 1 | D15: 32 | E15: ACT | F15: 280 | G15: 325 | H15: 307 | I15: 1595 | J15: 36 | K15: 22 | L15: 21 | M15: 150 | N15: BAL | O15: 17 | P15: 5.13 | Q15: 8.98 | R15: 0.785 | S15: 0.5 | U15: 17 | V15: 1 | W15: 0 | X15: 0 | Y15: 0 | Z15: 0 | AA15: 289 | AB15: 1447 | AC15: 12 | AD15: 23 | AE15: 17 | AF15: 162 | AG15: 1 | AH15: kept | AI15: =IFERROR(AB15/AA15,"") -> 5.0069204 | AJ15: =IFERROR(AF15/AE15,"") -> 9.5294118 | AK15: =IFERROR(AE15/AD15,"") -> 0.73913043 | AL15: =IFERROR(X15/V15,"") -> 0 | AM15: =IFERROR(W15/V15,"") -> 0 | AN15: =IFERROR(AA15/$H$5,"") -> 0.5667778 | AO15: =IFERROR(AD15/$G$5,"") -> 0.046184739 | AP15: =IFERROR(V15/$F$5,"") -> 0.0019157088 | AQ15: =IFERROR(AA15/U15,"") -> 17 | AR15: =IFERROR(AD15/U15,"") -> 1.3529412 | AS15: =IFERROR(AD15-L15,"") -> 2 | AT15: =IFERROR(AA15-H15,"") -> -18 | AU15: =AF15*Settings!$B$7+AG15*Settings!$B$8+AE15*Settings!$B$9+AB15*Settings!$B$10+AC15*Settings!$B$11+X15*Settings!$B$12+Y15*Settings!$B$13+Z15*Settings!$B$14 -> 247.4
A16: RB | B16: Justice Hill | C16: 2 | D16: 28 | E16: ACT | F16: 84 | G16: 47 | H16: 18 | I16: 93 | J16: 39 | K16: 51 | L16: 27 | M16: 169 | N16: BAL | O16: 10 | P16: 4.75 | Q16: 8.33 | R16: 0.778 | U16: 17 | V16: 0 | W16: 0 | X16: 0 | Y16: 0 | Z16: 0 | AA16: 43 | AB16: 202 | AC16: 2 | AD16: 39 | AE16: 31 | AF16: 260 | AG16: 2 | AH16: kept | AI16: =IFERROR(AB16/AA16,"") -> 4.6976744 | AJ16: =IFERROR(AF16/AE16,"") -> 8.3870968 | AK16: =IFERROR(AE16/AD16,"") -> 0.79487179 | AL16: =IFERROR(X16/V16,"") | AM16: =IFERROR(W16/V16,"") | AN16: =IFERROR(AA16/$H$5,"") -> 0.084330261 | AO16: =IFERROR(AD16/$G$5,"") -> 0.078313253 | AP16: =IFERROR(V16/$F$5,"") -> 0 | AQ16: =IFERROR(AA16/U16,"") -> 2.5294118 | AR16: =IFERROR(AD16/U16,"") -> 2.2941176 | AS16: =IFERROR(AD16-L16,"") -> 12 | AT16: =IFERROR(AA16-H16,"") -> 25 | AU16: =AF16*Settings!$B$7+AG16*Settings!$B$8+AE16*Settings!$B$9+AB16*Settings!$B$10+AC16*Settings!$B$11+X16*Settings!$B$12+Y16*Settings!$B$13+Z16*Settings!$B$14 -> 85.7
A17: RB | B17: Adam Randall | C17: 3 | D17: 22 | E17: ACT | U17: 17 | AA17: 42 | AB17: 191 | AC17: 1 | AD17: 10 | AE17: 8 | AF17: 72 | AG17: 0 | AH17: kept | AI17: =IFERROR(AB17/AA17,"") -> 4.547619 | AJ17: =IFERROR(AF17/AE17,"") -> 9 | AK17: =IFERROR(AE17/AD17,"") -> 0.8 | AL17: =IFERROR(X17/V17,"") | AM17: =IFERROR(W17/V17,"") | AN17: =IFERROR(AA17/$H$5,"") -> 0.082369092 | AO17: =IFERROR(AD17/$G$5,"") -> 0.020080321 | AP17: =IFERROR(V17/$F$5,"") -> 0 | AQ17: =IFERROR(AA17/U17,"") -> 2.4705882 | AR17: =IFERROR(AD17/U17,"") -> 0.58823529 | AS17: =IFERROR(AD17-L17,"") -> 10 | AT17: =IFERROR(AA17-H17,"") -> 42 | AU17: =AF17*Settings!$B$7+AG17*Settings!$B$8+AE17*Settings!$B$9+AB17*Settings!$B$10+AC17*Settings!$B$11+X17*Settings!$B$12+Y17*Settings!$B$13+Z17*Settings!$B$14 -> 36.3
A18: RB | B18: Rasheen Ali | C18: 4 | D18: 25 | E18: ACT | G18: 10 | H18: 7 | I18: 24 | K18: 2 | L18: 11 | M18: 68 | N18: BAL | O18: 15 | P18: 3.24 | Q18: 7.56 | R18: 0.692 | U18: 17 | V18: 0 | W18: 0 | X18: 0 | Y18: 0 | Z18: 0 | AA18: 24 | AB18: 91 | AC18: 1 | AD18: 7 | AE18: 5 | AF18: 40 | AG18: 0 | AH18: kept | AI18: =IFERROR(AB18/AA18,"") -> 3.7916667 | AJ18: =IFERROR(AF18/AE18,"") -> 8 | AK18: =IFERROR(AE18/AD18,"") -> 0.71428571 | AL18: =IFERROR(X18/V18,"") | AM18: =IFERROR(W18/V18,"") | AN18: =IFERROR(AA18/$H$5,"") -> 0.047068053 | AO18: =IFERROR(AD18/$G$5,"") -> 0.014056225 | AP18: =IFERROR(V18/$F$5,"") -> 0 | AQ18: =IFERROR(AA18/U18,"") -> 1.4117647 | AR18: =IFERROR(AD18/U18,"") -> 0.41176471 | AS18: =IFERROR(AD18-L18,"") -> -4 | AT18: =IFERROR(AA18-H18,"") -> 17 | AU18: =AF18*Settings!$B$7+AG18*Settings!$B$8+AE18*Settings!$B$9+AB18*Settings!$B$10+AC18*Settings!$B$11+X18*Settings!$B$12+Y18*Settings!$B$13+Z18*Settings!$B$14 -> 21.6
A19: RB | B19: Dontae McMillan | C19: 5 | D19: 24 | E19: ACT | U19: 17 | AI19: =IFERROR(AB19/AA19,"") | AJ19: =IFERROR(AF19/AE19,"") | AK19: =IFERROR(AE19/AD19,"") | AL19: =IFERROR(X19/V19,"") | AM19: =IFERROR(W19/V19,"") | AN19: =IFERROR(AA19/$H$5,"") -> 0 | AO19: =IFERROR(AD19/$G$5,"") -> 0 | AP19: =IFERROR(V19/$F$5,"") -> 0 | AQ19: =IFERROR(AA19/U19,"") -> 0 | AR19: =IFERROR(AD19/U19,"") -> 0 | AS19: =IFERROR(AD19-L19,"") -> 0 | AT19: =IFERROR(AA19-H19,"") -> 0 | AU19: =AF19*Settings!$B$7+AG19*Settings!$B$8+AE19*Settings!$B$9+AB19*Settings!$B$10+AC19*Settings!$B$11+X19*Settings!$B$12+Y19*Settings!$B$13+Z19*Settings!$B$14 -> 0
A20: RB | B20: Elijah Tau-Tolliver | C20: 6 | D20: 23 | E20: ACT | U20: 17 | AI20: =IFERROR(AB20/AA20,"") | AJ20: =IFERROR(AF20/AE20,"") | AK20: =IFERROR(AE20/AD20,"") | AL20: =IFERROR(X20/V20,"") | AM20: =IFERROR(W20/V20,"") | AN20: =IFERROR(AA20/$H$5,"") -> 0 | AO20: =IFERROR(AD20/$G$5,"") -> 0 | AP20: =IFERROR(V20/$F$5,"") -> 0 | AQ20: =IFERROR(AA20/U20,"") -> 0 | AR20: =IFERROR(AD20/U20,"") -> 0 | AS20: =IFERROR(AD20-L20,"") -> 0 | AT20: =IFERROR(AA20-H20,"") -> 0 | AU20: =AF20*Settings!$B$7+AG20*Settings!$B$8+AE20*Settings!$B$9+AB20*Settings!$B$10+AC20*Settings!$B$11+X20*Settings!$B$12+Y20*Settings!$B$13+Z20*Settings!$B$14 -> 0
A21: RB | B21: Other RBs | U21: 17 | AI21: =IFERROR(AB21/AA21,"") | AJ21: =IFERROR(AF21/AE21,"") | AK21: =IFERROR(AE21/AD21,"") | AL21: =IFERROR(X21/V21,"") | AM21: =IFERROR(W21/V21,"") | AN21: =IFERROR(AA21/$H$5,"") -> 0 | AO21: =IFERROR(AD21/$G$5,"") -> 0 | AP21: =IFERROR(V21/$F$5,"") -> 0 | AQ21: =IFERROR(AA21/U21,"") -> 0 | AR21: =IFERROR(AD21/U21,"") -> 0 | AS21: =IFERROR(AD21-L21,"") -> 0 | AT21: =IFERROR(AA21-H21,"") -> 0 | AU21: =AF21*Settings!$B$7+AG21*Settings!$B$8+AE21*Settings!$B$9+AB21*Settings!$B$10+AC21*Settings!$B$11+X21*Settings!$B$12+Y21*Settings!$B$13+Z21*Settings!$B$14 -> 0
A22: WR | B22: Zay Flowers | C22: 1 | D22: 25 | E22: ACT | F22: 8 | G22: 9 | H22: 10 | I22: 62 | J22: 108 | K22: 116 | L22: 118 | M22: 1211 | N22: BAL | O22: 17 | P22: 6.44 | Q22: 13.2 | R22: 0.693 | U22: 17 | V22: 0 | W22: 0 | X22: 0 | Y22: 0 | Z22: 0 | AA22: 9 | AB22: 56 | AC22: 0 | AD22: 118 | AE22: 81 | AF22: 1140 | AG22: 6 | AH22: kept | AI22: =IFERROR(AB22/AA22,"") -> 6.2222222 | AJ22: =IFERROR(AF22/AE22,"") -> 14.074074 | AK22: =IFERROR(AE22/AD22,"") -> 0.68644068 | AL22: =IFERROR(X22/V22,"") | AM22: =IFERROR(W22/V22,"") | AN22: =IFERROR(AA22/$H$5,"") -> 0.01765052 | AO22: =IFERROR(AD22/$G$5,"") -> 0.23694779 | AP22: =IFERROR(V22/$F$5,"") -> 0 | AQ22: =IFERROR(AA22/U22,"") -> 0.52941176 | AR22: =IFERROR(AD22/U22,"") -> 6.9411765 | AS22: =IFERROR(AD22-L22,"") -> 0 | AT22: =IFERROR(AA22-H22,"") -> -1 | AU22: =AF22*Settings!$B$7+AG22*Settings!$B$8+AE22*Settings!$B$9+AB22*Settings!$B$10+AC22*Settings!$B$11+X22*Settings!$B$12+Y22*Settings!$B$13+Z22*Settings!$B$14 -> 196.1
A23: WR | B23: Rashod Bateman | C23: 2 | D23: 26 | E23: ACT | F23: 1 | J23: 56 | K23: 72 | L23: 38 | M23: 224 | N23: BAL | O23: 13 | P23: 18 | Q23: 14.03 | R23: 0.578 | U23: 17 | V23: 0 | W23: 0 | X23: 0 | Y23: 0 | Z23: 0 | AA23: 0 | AB23: 1 | AC23: 0 | AD23: 59 | AE23: 35 | AF23: 492 | AG23: 4 | AH23: kept | AI23: =IFERROR(AB23/AA23,"") | AJ23: =IFERROR(AF23/AE23,"") -> 14.057143 | AK23: =IFERROR(AE23/AD23,"") -> 0.59322034 | AL23: =IFERROR(X23/V23,"") | AM23: =IFERROR(W23/V23,"") | AN23: =IFERROR(AA23/$H$5,"") -> 0 | AO23: =IFERROR(AD23/$G$5,"") -> 0.1184739 | AP23: =IFERROR(V23/$F$5,"") -> 0 | AQ23: =IFERROR(AA23/U23,"") -> 0 | AR23: =IFERROR(AD23/U23,"") -> 3.4705882 | AS23: =IFERROR(AD23-L23,"") -> 21 | AT23: =IFERROR(AA23-H23,"") -> 0 | AU23: =AF23*Settings!$B$7+AG23*Settings!$B$8+AE23*Settings!$B$9+AB23*Settings!$B$10+AC23*Settings!$B$11+X23*Settings!$B$12+Y23*Settings!$B$13+Z23*Settings!$B$14 -> 90.8
A24: WR | B24: Ja'Kobi Lane | C24: 3 | D24: 22 | E24: ACT | U24: 17 | AA24: 1 | AB24: 3 | AC24: 0 | AD24: 49 | AE24: 30 | AF24: 427 | AG24: 3 | AH24: kept | AI24: =IFERROR(AB24/AA24,"") -> 3 | AJ24: =IFERROR(AF24/AE24,"") -> 14.233333 | AK24: =IFERROR(AE24/AD24,"") -> 0.6122449 | AL24: =IFERROR(X24/V24,"") | AM24: =IFERROR(W24/V24,"") | AN24: =IFERROR(AA24/$H$5,"") -> 0.0019611689 | AO24: =IFERROR(AD24/$G$5,"") -> 0.098393574 | AP24: =IFERROR(V24/$F$5,"") -> 0 | AQ24: =IFERROR(AA24/U24,"") -> 0.058823529 | AR24: =IFERROR(AD24/U24,"") -> 2.8823529 | AS24: =IFERROR(AD24-L24,"") -> 49 | AT24: =IFERROR(AA24-H24,"") -> 1 | AU24: =AF24*Settings!$B$7+AG24*Settings!$B$8+AE24*Settings!$B$9+AB24*Settings!$B$10+AC24*Settings!$B$11+X24*Settings!$B$12+Y24*Settings!$B$13+Z24*Settings!$B$14 -> 76
A25: WR | B25: Elijah Sarratt | C25: 4 | D25: 23 | E25: ACT | U25: 17 | AA25: 0 | AB25: 0 | AC25: 0 | AD25: 32 | AE25: 20 | AF25: 272 | AG25: 2 | AH25: kept | AI25: =IFERROR(AB25/AA25,"") | AJ25: =IFERROR(AF25/AE25,"") -> 13.6 | AK25: =IFERROR(AE25/AD25,"") -> 0.625 | AL25: =IFERROR(X25/V25,"") | AM25: =IFERROR(W25/V25,"") | AN25: =IFERROR(AA25/$H$5,"") -> 0 | AO25: =IFERROR(AD25/$G$5,"") -> 0.064257028 | AP25: =IFERROR(V25/$F$5,"") -> 0 | AQ25: =IFERROR(AA25/U25,"") -> 0 | AR25: =IFERROR(AD25/U25,"") -> 1.8823529 | AS25: =IFERROR(AD25-L25,"") -> 32 | AT25: =IFERROR(AA25-H25,"") -> 0 | AU25: =AF25*Settings!$B$7+AG25*Settings!$B$8+AE25*Settings!$B$9+AB25*Settings!$B$10+AC25*Settings!$B$11+X25*Settings!$B$12+Y25*Settings!$B$13+Z25*Settings!$B$14 -> 49.2
