Workbook

Sheet Start Here
B2: 2026 PROJECTIONS - v3 (market share)
B4: How it works
B5: You set two kinds of number per player:
B6: SHARE his % of the team's pass attempts / carries / targets / TDs
B7: RATE his yards per carry, catch rate, yards per catch
B8: Everything else is calculated. Nothing has to be balanced by hand.
B10: The team block up top drives everything
B11: Team Plays x Pass Play % -> pass attempts and rush attempts
B12: Total TD x Rush TD % -> rushing TDs and passing TDs
B13: Both are editable. Change the play total or the pass rate and every
B14: player's opportunity moves with it.
B16: Where the team numbers come from
... B53: A plain rebuild refuses once Excel has saved this file.

Sheet ARI
A1: ARI - 2026
A2: TEAM VOLUME | C2: blue = you set it; grey = calculated | L2: 2025 ACTUAL
B3: Games | C3: Team Plays | D3: Plays/G | E3: Pass Play % | F3: Pass Att | G3: Rush Att | H3: Targets | L3: Plays | M3: Plays/G | N3: Pass% | O3: PassAtt | P3: RushAtt | Q3: Y/A
B4: 17 | C4: 1025 | D4: =$C$4/$B$4 | E4: 0.595 | F4: =ROUND($C$4*$E$4,0) | G4: =$C$4-$F$4 | H4: =ROUND($F$4*Settings!$B$4,0) | L4: 1074 | M4: 63.1765 | N4: 0.6592 | O4: 649 | P4: 366 | Q4: 6.7088
A5: TEAM SCORING & YARDS | C5: TDs from Vegas implied points; yards are a historical REFERENCE, not a cap
B6: Total TD | C6: Rush TD % | D6: Rush TD | E6: Pass TD | F6: ~Pass Yds | G6: ~Rush Yds | H6: ~Rec Yds | L6: PassYds | M6: RushYds | N6: PassTD | O6: RushTD | P6: TotTD | Q6: RuTD%
B7: 32.7 | C7: 0.31 | D7: =$B$7*$C$7 | E7: =$B$7-$D$7 | F7: 3992 | G7: 1978 | H7: =$F$7 | L7: 4354 | M7: 1583 | N7: 29 | O7: 9 | P7: 38 | Q7: 0.23684211
A9: NOTES | B9: 30% of targets and 90% of carries left this roster. NEW HC Mike LaFleur + OC Nathaniel Hackett. Pass rate projected to DROP 69.4% -> 58%. Biggest scheme change in the league - revisit Pass Rate above.
A11: Pos | B11: Player | C11: Dep | D11: Age | E11: Status | F11: '25 Tm | G11: '25 G | H11: Snap% | I11: '25 Pass% | J11: 3y Cmp% | K11: 3y Y/A | L11: 3y Int% | M11: '25 Rush% | N11: 3y Y/C | O11: '25 RZRu% | P11: '25 RuTD% | Q11: '24 Tgt% | R11: '25 Tgt% | S11: 3y Ctch | T11: 3y Y/R | U11: '25 RZTg% | V11: '25 ReTD% | W11: Games | X11: Pass % | Y11: Comp % | Z11: Int Rate | AA11: Rush % | AB11: Y/C | AC11: Rush TD % | AD11: Tgt % | AE11: Catch % | AF11: Y/R | AG11: Rec TD % | AH11: Pass Att | AI11: Cmp | AJ11: Pass Yds | AK11: Pass TD | AL11: Int | AM11: Rush Att | AN11: Rush Yds | AO11: Rush TD | AP11: Targets | AQ11: Rec | AR11: Rec Yds | AS11: Rec TD | AT11: STD | AU11: Half | AV11: PPR
A12: QB | B12: Jacoby Brissett | C12: 1 | D12: 33 | E12: ACT | F12: ARI | G12: 14 | H12: 0.689 | I12: 0.7473 | J12: 0.643 | K12: 6.67 | L12: 0.013 | M12: 0.0992 | N12: 4.67 | O12: 0.1042 | P12: 0.1111 | W12: 17 | X12: 0.85 | Y12: 0.645 | Z12: 0.013 | AA12: 0.0727 | AB12: 4.66 | AC12: 0.11 | AH12: =IFERROR(X12*$F$4,0) | AI12: =IFERROR(AH12*Y12,0) | AJ12: =IFERROR(X12*SUM($AR$12:$AR$36),0) | AK12: =IFERROR(X12*$E$7,0) | AL12: =IFERROR(AH12*Z12,0) | AM12: =IFERROR(AA12*$G$4,0) | AN12: =IFERROR(AM12*AB12,0) | AO12: =IFERROR(AC12*$D$7,0) | AP12: =IFERROR(AD12*$H$4,0) | AQ12: =IFERROR(AP12*AE12,0) | AR12: =IFERROR(AQ12*AF12,0) | AS12: =IFERROR(AG12*$E$7,0) | AT12: =AN12*Settings!$B$10+AO12*Settings!$B$11+AR12*Settings!$B$7+AS12*Settings!$B$8+AJ12*Settings!$B$12+AK12*Settings!$B$13+AL12*Settings!$B$14 | AU12: =AN12*Settings!$B$10+AO12*Settings!$B$11+AR12*Settings!$B$7+AS12*Settings!$B$8+AJ12*Settings!$B$12+AK12*Settings!$B$13+AL12*Settings!$B$14+AQ12*Settings!$B$9 | AV12: =AN12*Settings!$B$10+AO12*Settings!$B$11+AR12*Settings!$B$7+AS12*Settings!$B$8+AJ12*Settings!$B$12+AK12*Settings!$B$13+AL12*Settings!$B$14+AQ12*Settings!$B$15
A13: QB | B13: Carson Beck | C13: 2 | D13: 23 | E13: QUESTIONABLE | W13: 17 | X13: 0.145 | Y13: 0.64 | Z13: 0.022 | AA13: 0.012 | AB13: 4.8 | AH13: =IFERROR(X13*$F$4,0) | AI13: =IFERROR(AH13*Y13,0) | AJ13: =IFERROR(X13*SUM($AR$12:$AR$36),0) | AK13: =IFERROR(X13*$E$7,0) | AL13: =IFERROR(AH13*Z13,0) | AM13: =IFERROR(AA13*$G$4,0) | AN13: =IFERROR(AM13*AB13,0) | AO13: =IFERROR(AC13*$D$7,0) | AP13: =IFERROR(AD13*$H$4,0) | AQ13: =IFERROR(AP13*AE13,0) | AR13: =IFERROR(AQ13*AF13,0) | AS13: =IFERROR(AG13*$E$7,0) | AT13: =AN13*Settings!$B$10+AO13*Settings!$B$11+AR13*Settings!$B$7+AS13*Settings!$B$8+AJ13*Settings!$B$12+AK13*Settings!$B$13+AL13*Settings!$B$14 | AU13: =AN13*Settings!$B$10+AO13*Settings!$B$11+AR13*Settings!$B$7+AS13*Settings!$B$8+AJ13*Settings!$B$12+AK13*Settings!$B$13+AL13*Settings!$B$14+AQ13*Settings!$B$9 | AV13: =AN13*Settings!$B$10+AO13*Settings!$B$11+AR13*Settings!$B$7+AS13*Settings!$B$8+AJ13*Settings!$B$12+AK13*Settings!$B$13+AL13*Settings!$B$14+AQ13*Settings!$B$15
A14: QB | B14: Gardner Minshew | C14: 3 | D14: 30 | E14: ACT | F14: KC | G14: 4 | H14: 0.523 | I14: 0.0223 | J14: 0.642 | K14: 6.67 | L14: 0.025 | M14: 0.0024 | N14: 4.35 | W14: 17 | X14: 0.005 | Y14: 0.64 | Z14: 0.025 | AA14: 0 | AB14: 4.35 | AC14: 0 | AH14: =IFERROR(X14*$F$4,0) | AI14: =IFERROR(AH14*Y14,0) | AJ14: =IFERROR(X14*SUM($AR$12:$AR$36),0) | AK14: =IFERROR(X14*$E$7,0) | AL14: =IFERROR(AH14*Z14,0) | AM14: =IFERROR(AA14*$G$4,0) | AN14: =IFERROR(AM14*AB14,0) | AO14: =IFERROR(AC14*$D$7,0) | AP14: =IFERROR(AD14*$H$4,0) | AQ14: =IFERROR(AP14*AE14,0) | AR14: =IFERROR(AQ14*AF14,0) | AS14: =IFERROR(AG14*$E$7,0) | AT14: =AN14*Settings!$B$10+AO14*Settings!$B$11+AR14*Settings!$B$7+AS14*Settings!$B$8+AJ14*Settings!$B$12+AK14*Settings!$B$13+AL14*Settings!$B$14 | AU14: =AN14*Settings!$B$10+AO14*Settings!$B$11+AR14*Settings!$B$7+AS14*Settings!$B$8+AJ14*Settings!$B$12+AK14*Settings!$B$13+AL14*Settings!$B$14+AQ14*Settings!$B$9 | AV14: =AN14*Settings!$B$10+AO14*Settings!$B$11+AR14*Settings!$B$7+AS14*Settings!$B$8+AJ14*Settings!$B$12+AK14*Settings!$B$13+AL14*Settings!$B$14+AQ14*Settings!$B$15
A15: QB | B15: Other QBs | W15: 17 | AH15: =IFERROR(X15*$F$4,0) | AI15: =IFERROR(AH15*Y15,0) | AJ15: =IFERROR(X15*SUM($AR$12:$AR$36),0) | AK15: =IFERROR(X15*$E$7,0) | AL15: =IFERROR(AH15*Z15,0) | AM15: =IFERROR(AA15*$G$4,0) | AN15: =IFERROR(AM15*AB15,0) | AO15: =IFERROR(AC15*$D$7,0) | AP15: =IFERROR(AD15*$H$4,0) | AQ15: =IFERROR(AP15*AE15,0) | AR15: =IFERROR(AQ15*AF15,0) | AS15: =IFERROR(AG15*$E$7,0) | AT15: =AN15*Settings!$B$10+AO15*Settings!$B$11+AR15*Settings!$B$7+AS15*Settings!$B$8+AJ15*Settings!$B$12+AK15*Settings!$B$13+AL15*Settings!$B$14 | AU15: =AN15*Settings!$B$10+AO15*Settings!$B$11+AR15*Settings!$B$7+AS15*Settings!$B$8+AJ15*Settings!$B$12+AK15*Settings!$B$13+AL15*Settings!$B$14+AQ15*Settings!$B$9 | AV15: =AN15*Settings!$B$10+AO15*Settings!$B$11+AR15*Settings!$B$7+AS15*Settings!$B$8+AJ15*Settings!$B$12+AK15*Settings!$B$13+AL15*Settings!$B$14+AQ15*Settings!$B$15
A16: RB | B16: Jeremiyah Love | C16: 1 | D16: 21 | E16: QUESTIONABLE | W16: 17 | AA16: 0.49 | AB16: 4.65 | AC16: 0.44 | AD16: 0.13 | AE16: 0.79 | AF16: 6.5 | AG16: 0.085 | AH16: =IFERROR(X16*$F$4,0) | AI16: =IFERROR(AH16*Y16,0) | AJ16: =IFERROR(X16*SUM($AR$12:$AR$36),0) | AK16: =IFERROR(X16*$E$7,0) | AL16: =IFERROR(AH16*Z16,0) | AM16: =IFERROR(AA16*$G$4,0) | AN16: =IFERROR(AM16*AB16,0) | AO16: =IFERROR(AC16*$D$7,0) | AP16: =IFERROR(AD16*$H$4,0) | AQ16: =IFERROR(AP16*AE16,0) | AR16: =IFERROR(AQ16*AF16,0) | AS16: =IFERROR(AG16*$E$7,0) | AT16: =AN16*Settings!$B$10+AO16*Settings!$B$11+AR16*Settings!$B$7+AS16*Settings!$B$8+AJ16*Settings!$B$12+AK16*Settings!$B$13+AL16*Settings!$B$14 | AU16: =AN16*Settings!$B$10+AO16*Settings!$B$11+AR16*Settings!$B$7+AS16*Settings!$B$8+AJ16*Settings!$B$12+AK16*Settings!$B$13+AL16*Settings!$B$14+AQ16*Settings!$B$9 | AV16: =AN16*Settings!$B$10+AO16*Settings!$B$11+AR16*Settings!$B$7+AS16*Settings!$B$8+AJ16*Settings!$B$12+AK16*Settings!$B$13+AL16*Settings!$B$14+AQ16*Settings!$B$15
A17: RB | B17: Tyler Allgeier | C17: 2 | D17: 26 | E17: ACT | F17: ATL | G17: 17 | H17: 0.29 | M17: 0.3082 | N17: 3.94 | O17: 0.4627 | P17: 0.4706 | Q17: 0.0241 | R17: 0.0308 | S17: 0.849 | T17: 7.6 | U17: 0.0179 | W17: 17 | AA17: 0.253 | AB17: 4.45 | AC17: 0.27 | AD17: 0.01 | AE17: 0.76 | AF17: 4.2 | AG17: 0.01 | AH17: =IFERROR(X17*$F$4,0) | AI17: =IFERROR(AH17*Y17,0) | AJ17: =IFERROR(X17*SUM($AR$12:$AR$36),0) | AK17: =IFERROR(X17*$E$7,0) | AL17: =IFERROR(AH17*Z17,0) | AM17: =IFERROR(AA17*$G$4,0) | AN17: =IFERROR(AM17*AB17,0) | AO17: =IFERROR(AC17*$D$7,0) | AP17: =IFERROR(AD17*$H$4,0) | AQ17: =IFERROR(AP17*AE17,0) | AR17: =IFERROR(AQ17*AF17,0) | AS17: =IFERROR(AG17*$E$7,0) | AT17: =AN17*Settings!$B$10+AO17*Settings!$B$11+AR17*Settings!$B$7+AS17*Settings!$B$8+AJ17*Settings!$B$12+AK17*Settings!$B$13+AL17*Settings!$B$14 | AU17: =AN17*Settings!$B$10+AO17*Settings!$B$11+AR17*Settings!$B$7+AS17*Settings!$B$8+AJ17*Settings!$B$12+AK17*Settings!$B$13+AL17*Settings!$B$14+AQ17*Settings!$B$9 | AV17: =AN17*Settings!$B$10+AO17*Settings!$B$11+AR17*Settings!$B$7+AS17*Settings!$B$8+AJ17*Settings!$B$12+AK17*Settings!$B$13+AL17*Settings!$B$14+AQ17*Settings!$B$15
A18: RB | B18: Zonovan Knight | C18: 3 | D18: 25 | E18: ACT | F18: ARI | G18: 12 | H18: 0.302 | M18: 0.2259 | N18: 3.28 | O18: 0.3333 | P18: 0.4444 | R18: 0.0502 | S18: 0.71 | T18: 7.27 | U18: 0.0625 | V18: 0.0345 | W18: 17 | AA18: 0.051 | AB18: 3.75 | AC18: 0.021 | AD18: 0.0305 | AE18: 0.7 | AF18: 7.3 | AG18: 0.01 | AH18: =IFERROR(X18*$F$4,0) | AI18: =IFERROR(AH18*Y18,0) | AJ18: =IFERROR(X18*SUM($AR$12:$AR$36),0) | AK18: =IFERROR(X18*$E$7,0) | AL18: =IFERROR(AH18*Z18,0) | AM18: =IFERROR(AA18*$G$4,0) | AN18: =IFERROR(AM18*AB18,0) | AO18: =IFERROR(AC18*$D$7,0) | AP18: =IFERROR(AD18*$H$4,0) | AQ18: =IFERROR(AP18*AE18,0) | AR18: =IFERROR(AQ18*AF18,0) | AS18: =IFERROR(AG18*$E$7,0) | AT18: =AN18*Settings!$B$10+AO18*Settings!$B$11+AR18*Settings!$B$7+AS18*Settings!$B$8+AJ18*Settings!$B$12+AK18*Settings!$B$13+AL18*Settings!$B$14 | AU18: =AN18*Settings!$B$10+AO18*Settings!$B$11+AR18*Settings!$B$7+AS18*Settings!$B$8+AJ18*Settings!$B$12+AK18*Settings!$B$13+AL18*Settings!$B$14+AQ18*Settings!$B$9 | AV18: =AN18*Settings!$B$10+AO18*Settings!$B$11+AR18*Settings!$B$7+AS18*Settings!$B$8+AJ18*Settings!$B$12+AK18*Settings!$B$13+AL18*Settings!$B$14+AQ18*Settings!$B$15
A19: RB | B19: Tavien Feaster | C19: 4 | D19: 24 | E19: ACT | W19: 17 | AA19: 0.04 | AB19: 4.13 | AD19: 0.0104 | AE19: 0.75 | AF19: 7.13 | AH19: =IFERROR(X19*$F$4,0) | AI19: =IFERROR(AH19*Y19,0) | AJ19: =IFERROR(X19*SUM($AR$12:$AR$36),0) | AK19: =IFERROR(X19*$E$7,0) | AL19: =IFERROR(AH19*Z19,0) | AM19: =IFERROR(AA19*$G$4,0) | AN19: =IFERROR(AM19*AB19,0) | AO19: =IFERROR(AC19*$D$7,0) | AP19: =IFERROR(AD19*$H$4,0) | AQ19: =IFERROR(AP19*AE19,0) | AR19: =IFERROR(AQ19*AF19,0) | AS19: =IFERROR(AG19*$E$7,0) | AT19: =AN19*Settings!$B$10+AO19*Settings!$B$11+AR19*Settings!$B$7+AS19*Settings!$B$8+AJ19*Settings!$B$12+AK19*Settings!$B$13+AL19*Settings!$B$14 | AU19: =AN19*Settings!$B$10+AO19*Settings!$B$11+AR19*Settings!$B$7+AS19*Settings!$B$8+AJ19*Settings!$B$12+AK19*Settings!$B$13+AL19*Settings!$B$14+AQ19*Settings!$B$9 | AV19: =AN19*Settings!$B$10+AO19*Settings!$B$11+AR19*Settings!$B$7+AS19*Settings!$B$8+AJ19*Settings!$B$12+AK19*Settings!$B$13+AL19*Settings!$B$14+AQ19*Settings!$B$15
A20: RB | AH20: =IFERROR(X20*$F$4,0) | AI20: =IFERROR(AH20*Y20,0) | AJ20: =IFERROR(X20*SUM($AR$12:$AR$36),0) | AK20: =IFERROR(X20*$E$7,0) | AL20: =IFERROR(AH20*Z20,0) | AM20: =IFERROR(AA20*$G$4,0) | AN20: =IFERROR(AM20*AB20,0) | AO20: =IFERROR(AC20*$D$7,0) | AP20: =IFERROR(AD20*$H$4,0) | AQ20: =IFERROR(AP20*AE20,0) | AR20: =IFERROR(AQ20*AF20,0) | AS20: =IFERROR(AG20*$E$7,0) | AT20: =AN20*Settings!$B$10+AO20*Settings!$B$11+AR20*Settings!$B$7+AS20*Settings!$B$8+AJ20*Settings!$B$12+AK20*Settings!$B$13+AL20*Settings!$B$14 | AU20: =AN20*Settings!$B$10+AO20*Settings!$B$11+AR20*Settings!$B$7+AS20*Settings!$B$8+AJ20*Settings!$B$12+AK20*Settings!$B$13+AL20*Settings!$B$14+AQ20*Settings!$B$9 | AV20: =AN20*Settings!$B$10+AO20*Settings!$B$11+AR20*Settings!$B$7+AS20*Settings!$B$8+AJ20*Settings!$B$12+AK20*Settings!$B$13+AL20*Settings!$B$14+AQ20*Settings!$B$15
A21: RB | AH21: =IFERROR(X21*$F$4,0) | AI21: =IFERROR(AH21*Y21,0) | AJ21: =IFERROR(X21*SUM($AR$12:$AR$36),0) | AK21: =IFERROR(X21*$E$7,0) | AL21: =IFERROR(AH21*Z21,0) | AM21: =IFERROR(AA21*$G$4,0) | AN21: =IFERROR(AM21*AB21,0) | AO21: =IFERROR(AC21*$D$7,0) | AP21: =IFERROR(AD21*$H$4,0) | AQ21: =IFERROR(AP21*AE21,0) | AR21: =IFERROR(AQ21*AF21,0) | AS21: =IFERROR(AG21*$E$7,0) | AT21: =AN21*Settings!$B$10+AO21*Settings!$B$11+AR21*Settings!$B$7+AS21*Settings!$B$8+AJ21*Settings!$B$12+AK21*Settings!$B$13+AL21*Settings!$B$14 | AU21: =AN21*Settings!$B$10+AO21*Settings!$B$11+AR21*Settings!$B$7+AS21*Settings!$B$8+AJ21*Settings!$B$12+AK21*Settings!$B$13+AL21*Settings!$B$14+AQ21*Settings!$B$9 | AV21: =AN21*Settings!$B$10+AO21*Settings!$B$11+AR21*Settings!$B$7+AS21*Settings!$B$8+AJ21*Settings!$B$12+AK21*Settings!$B$13+AL21*Settings!$B$14+AQ21*Settings!$B$15
A22: RB | B22: Other RBs | W22: 17 | AH22: =IFERROR(X22*$F$4,0) | AI22: =IFERROR(AH22*Y22,0) | AJ22: =IFERROR(X22*SUM($AR$12:$AR$36),0) | AK22: =IFERROR(X22*$E$7,0) | AL22: =IFERROR(AH22*Z22,0) | AM22: =IFERROR(AA22*$G$4,0) | AN22: =IFERROR(AM22*AB22,0) | AO22: =IFERROR(AC22*$D$7,0) | AP22: =IFERROR(AD22*$H$4,0) | AQ22: =IFERROR(AP22*AE22,0) | AR22: =IFERROR(AQ22*AF22,0) | AS22: =IFERROR(AG22*$E$7,0) | AT22: =AN22*Settings!$B$10+AO22*Settings!$B$11+AR22*Settings!$B$7+AS22*Settings!$B$8+AJ22*Settings!$B$12+AK22*Settings!$B$13+AL22*Settings!$B$14 | AU22: =AN22*Settings!$B$10+AO22*Settings!$B$11+AR22*Settings!$B$7+AS22*Settings!$B$8+AJ22*Settings!$B$12+AK22*Settings!$B$13+AL22*Settings!$B$14+AQ22*Settings!$B$9 | AV22: =AN22*Settings!$B$10+AO22*Settings!$B$11+AR22*Settings!$B$7+AS22*Settings!$B$8+AJ22*Settings!$B$12+AK22*Settings!$B$13+AL22*Settings!$B$14+AQ22*Settings!$B$15
A23: WR | B23: Marvin Harrison | C23: 1 | D23: 24 | E23: ACT | F23: ARI | G23: 12 | H23: 0.74 | Q23: 0.2218 | R23: 0.1183 | S23: 0.549 | T23: 14.57 | U23: 0.0938 | V23: 0.1379 | W23: 17 | AD23: 0.205 | AE23: 0.539 | AF23: 14.5 | AG23: 0.2238 | AH23: =IFERROR(X23*$F$4,0) | AI23: =IFERROR(AH23*Y23,0) | AJ23: =IFERROR(X23*SUM($AR$12:$AR$36),0) | AK23: =IFERROR(X23*$E$7,0) | AL23: =IFERROR(AH23*Z23,0) | AM23: =IFERROR(AA23*$G$4,0) | AN23: =IFERROR(AM23*AB23,0) | AO23: =IFERROR(AC23*$D$7,0) | AP23: =IFERROR(AD23*$H$4,0) | AQ23: =IFERROR(AP23*AE23,0) | AR23: =IFERROR(AQ23*AF23,0) | AS23: =IFERROR(AG23*$E$7,0) | AT23: =AN23*Settings!$B$10+AO23*Settings!$B$11+AR23*Settings!$B$7+AS23*Settings!$B$8+AJ23*Settings!$B$12+AK23*Settings!$B$13+AL23*Settings!$B$14 | AU23: =AN23*Settings!$B$10+AO23*Settings!$B$11+AR23*Settings!$B$7+AS23*Settings!$B$8+AJ23*Settings!$B$12+AK23*Settings!$B$13+AL23*Settings!$B$14+AQ23*Settings!$B$9 | AV23: =AN23*Settings!$B$10+AO23*Settings!$B$11+AR23*Settings!$B$7+AS23*Settings!$B$8+AJ23*Settings!$B$12+AK23*Settings!$B$13+AL23*Settings!$B$14+AQ23*Settings!$B$15
A24: WR | B24: Michael Wilson | C24: 2 | D24: 26 | E24: ACT | F24: ARI | G24: 17 | H24: 0.805 | Q24: 0.1358 | R24: 0.2042 | S24: 0.638 | T24: 12.85 | U24: 0.1562 | V24: 0.2414 | W24: 17 | AD24: 0.187 | AE24: 0.62 | AF24: 12.5 | AG24: 0.1917 | AH24: =IFERROR(X24*$F$4,0) | AI24: =IFERROR(AH24*Y24,0) | AJ24: =IFERROR(X24*SUM($AR$12:$AR$36),0) | AK24: =IFERROR(X24*$E$7,0) | AL24: =IFERROR(AH24*Z24,0) | AM24: =IFERROR(AA24*$G$4,0) | AN24: =IFERROR(AM24*AB24,0) | AO24: =IFERROR(AC24*$D$7,0) | AP24: =IFERROR(AD24*$H$4,0) | AQ24: =IFERROR(AP24*AE24,0) | AR24: =IFERROR(AQ24*AF24,0) | AS24: =IFERROR(AG24*$E$7,0) | AT24: =AN24*Settings!$B$10+AO24*Settings!$B$11+AR24*Settings!$B$7+AS24*Settings!$B$8+AJ24*Settings!$B$12+AK24*Settings!$B$13+AL24*Settings!$B$14 | AU24: =AN24*Settings!$B$10+AO24*Settings!$B$11+AR24*Settings!$B$7+AS24*Settings!$B$8+AJ24*Settings!$B$12+AK24*Settings!$B$13+AL24*Settings!$B$14+AQ24*Settings!$B$9 | AV24: =AN24*Settings!$B$10+AO24*Settings!$B$11+AR24*Settings!$B$7+AS24*Settings!$B$8+AJ24*Settings!$B$12+AK24*Settings!$B$13+AL24*Settings!$B$14+AQ24*Settings!$B$15
A25: WR | B25: Kendrick Bourne | C25: 3 | D25: 31 | E25: ACT | F25: SF | G25: 16 | H25: 0.604 | Q25: 0.076 | R25: 0.0964 | S25: 0.706 | T25: 13.33 | U25: 0.0241 | W25: 17 | AD25: 0.066 | AE25: 0.65 | AF25: 12.37 | AG25: 0.1035 | AH25: =IFERROR(X25*$F$4,0) | AI25: =IFERROR(AH25*Y25,0) | AJ25: =IFERROR(X25*SUM($AR$12:$AR$36),0) | AK25: =IFERROR(X25*$E$7,0) | AL25: =IFERROR(AH25*Z25,0) | AM25: =IFERROR(AA25*$G$4,0) | AN25: =IFERROR(AM25*AB25,0) | AO25: =IFERROR(AC25*$D$7,0) | AP25: =IFERROR(AD25*$H$4,0) | AQ25: =IFERROR(AP25*AE25,0) | AR25: =IFERROR(AQ25*AF25,0) | AS25: =IFERROR(AG25*$E$7,0) | AT25: =AN25*Settings!$B$10+AO25*Settings!$B$11+AR25*Settings!$B$7+AS25*Settings!$B$8+AJ25*Settings!$B$12+AK25*Settings!$B$13+AL25*Settings!$B$14 | AU25: =AN25*Settings!$B$10+AO25*Settings!$B$11+AR25*Settings!$B$7+AS25*Settings!$B$8+AJ25*Settings!$B$12+AK25*Settings!$B$13+AL25*Settings!$B$14+AQ25*Settings!$B$9 | AV25: =AN25*Settings!$B$10+AO25*Settings!$B$11+AR25*Settings!$B$7+AS25*Settings!$B$8+AJ25*Settings!$B$12+AK25*Settings!$B$13+AL25*Settings!$B$14+AQ25*Settings!$B$15
A26: WR | B26: Reggie Virgil | C26: 4 | D26: 22 | E26: ACT | W26: 17 | AD26: 0.015 | AE26: 0.48 | AF26: 12.84 | AH26: =IFERROR(X26*$F$4,0) | AI26: =IFERROR(AH26*Y26,0) | AJ26: =IFERROR(X26*SUM($AR$12:$AR$36),0) | AK26: =IFERROR(X26*$E$7,0) | AL26: =IFERROR(AH26*Z26,0) | AM26: =IFERROR(AA26*$G$4,0) | AN26: =IFERROR(AM26*AB26,0) | AO26: =IFERROR(AC26*$D$7,0) | AP26: =IFERROR(AD26*$H$4,0) | AQ26: =IFERROR(AP26*AE26,0) | AR26: =IFERROR(AQ26*AF26,0) | AS26: =IFERROR(AG26*$E$7,0) | AT26: =AN26*Settings!$B$10+AO26*Settings!$B$11+AR26*Settings!$B$7+AS26*Settings!$B$8+AJ26*Settings!$B$12+AK26*Settings!$B$13+AL26*Settings!$B$14 | AU26: =AN26*Settings!$B$10+AO26*Settings!$B$11+AR26*Settings!$B$7+AS26*Settings!$B$8+AJ26*Settings!$B$12+AK26*Settings!$B$13+AL26*Settings!$B$14+AQ26*Settings!$B$9 | AV26: =AN26*Settings!$B$10+AO26*Settings!$B$11+AR26*Settings!$B$7+AS26*Settings!$B$8+AJ26*Settings!$B$12+AK26*Settings!$B$13+AL26*Settings!$B$14+AQ26*Settings!$B$15
A27: WR | B27: Jalen Brooks | C27: 5 | D27: 26 | E27: ACT | F27: ARI | G27: 5 | H27: 0.295 | Q27: 0.0482 | R27: 0.0097 | S27: 0.4 | T27: 14.75 | W27: 17 | AH27: =IFERROR(X27*$F$4,0) | AI27: =IFERROR(AH27*Y27,0) | AJ27: =IFERROR(X27*SUM($AR$12:$AR$36),0) | AK27: =IFERROR(X27*$E$7,0) | AL27: =IFERROR(AH27*Z27,0) | AM27: =IFERROR(AA27*$G$4,0) | AN27: =IFERROR(AM27*AB27,0) | AO27: =IFERROR(AC27*$D$7,0) | AP27: =IFERROR(AD27*$H$4,0) | AQ27: =IFERROR(AP27*AE27,0) | AR27: =IFERROR(AQ27*AF27,0) | AS27: =IFERROR(AG27*$E$7,0) | AT27: =AN27*Settings!$B$10+AO27*Settings!$B$11+AR27*Settings!$B$7+AS27*Settings!$B$8+AJ27*Settings!$B$12+AK27*Settings!$B$13+AL27*Settings!$B$14 | AU27: =AN27*Settings!$B$10+AO27*Settings!$B$11+AR27*Settings!$B$7+AS27*Settings!$B$8+AJ27*Settings!$B$12+AK27*Settings!$B$13+AL27*Settings!$B$14+AQ27*Settings!$B$9 | AV27: =AN27*Settings!$B$10+AO27*Settings!$B$11+AR27*Settings!$B$7+AS27*Settings!$B$8+AJ27*Settings!$B$12+AK27*Settings!$B$13+AL27*Settings!$B$14+AQ27*Settings!$B$15
A28: WR | B28: Simi Fehoko | C28: 6 | D28: 28 | E28: ACT | H28: 0.213 | Q28: 0.0326 | S28: 0.375 | W28: 17 | AD28: 0.015 | AE28: 0.41 | AF28: 16.43 | AG28: 0.0374 | AH28: =IFERROR(X28*$F$4,0) | AI28: =IFERROR(AH28*Y28,0) | AJ28: =IFERROR(X28*SUM($AR$12:$AR$36),0) | AK28: =IFERROR(X28*$E$7,0) | AL28: =IFERROR(AH28*Z28,0) | AM28: =IFERROR(AA28*$G$4,0) | AN28: =IFERROR(AM28*AB28,0) | AO28: =IFERROR(AC28*$D$7,0) | AP28: =IFERROR(AD28*$H$4,0) | AQ28: =IFERROR(AP28*AE28,0) | AR28: =IFERROR(AQ28*AF28,0) | AS28: =IFERROR(AG28*$E$7,0) | AT28: =AN28*Settings!$B$10+AO28*Settings!$B$11+AR28*Settings!$B$7+AS28*Settings!$B$8+AJ28*Settings!$B$12+AK28*Settings!$B$13+AL28*Settings!$B$14 | AU28: =AN28*Settings!$B$10+AO28*Settings!$B$11+AR28*Settings!$B$7+AS28*Settings!$B$8+AJ28*Settings!$B$12+AK28*Settings!$B$13+AL28*Settings!$B$14+AQ28*Settings!$B$9 | AV28: =AN28*Settings!$B$10+AO28*Settings!$B$11+AR28*Settings!$B$7+AS28*Settings!$B$8+AJ28*Settings!$B$12+AK28*Settings!$B$13+AL28*Settings!$B$14+AQ28*Settings!$B$15
A29: WR | B29: Devin Duvernay | C29: 7 | D29: 28 | E29: ACT | F29: CHI | G29: 17 | H29: 0.159 | Q29: 0.0307 | R29: 0.0094 | S29: 0.688 | U29: 0.0149 | W29: 17 | AD29: 0.004 | AE29: 0.45 | AF29: 7.24 | AH29: =IFERROR(X29*$F$4,0) | AI29: =IFERROR(AH29*Y29,0) | AJ29: =IFERROR(X29*SUM($AR$12:$AR$36),0) | AK29: =IFERROR(X29*$E$7,0) | AL29: =IFERROR(AH29*Z29,0) | AM29: =IFERROR(AA29*$G$4,0) | AN29: =IFERROR(AM29*AB29,0) | AO29: =IFERROR(AC29*$D$7,0) | AP29: =IFERROR(AD29*$H$4,0) | AQ29: =IFERROR(AP29*AE29,0) | AR29: =IFERROR(AQ29*AF29,0) | AS29: =IFERROR(AG29*$E$7,0) | AT29: =AN29*Settings!$B$10+AO29*Settings!$B$11+AR29*Settings!$B$7+AS29*Settings!$B$8+AJ29*Settings!$B$12+AK29*Settings!$B$13+AL29*Settings!$B$14 | AU29: =AN29*Settings!$B$10+AO29*Settings!$B$11+AR29*Settings!$B$7+AS29*Settings!$B$8+AJ29*Settings!$B$12+AK29*Settings!$B$13+AL29*Settings!$B$14+AQ29*Settings!$B$9 | AV29: =AN29*Settings!$B$10+AO29*Settings!$B$11+AR29*Settings!$B$7+AS29*Settings!$B$8+AJ29*Settings!$B$12+AK29*Settings!$B$13+AL29*Settings!$B$14+AQ29*Settings!$B$15
A30: WR | AH30: =IFERROR(X30*$F$4,0) | AI30: =IFERROR(AH30*Y30,0) | AJ30: =IFERROR(X30*SUM($AR$12:$AR$36),0) | AK30: =IFERROR(X30*$E$7,0) | AL30: =IFERROR(AH30*Z30,0) | AM30: =IFERROR(AA30*$G$4,0) | AN30: =IFERROR(AM30*AB30,0) | AO30: =IFERROR(AC30*$D$7,0) | AP30: =IFERROR(AD30*$H$4,0) | AQ30: =IFERROR(AP30*AE30,0) | AR30: =IFERROR(AQ30*AF30,0) | AS30: =IFERROR(AG30*$E$7,0) | AT30: =AN30*Settings!$B$10+AO30*Settings!$B$11+AR30*Settings!$B$7+AS30*Settings!$B$8+AJ30*Settings!$B$12+AK30*Settings!$B$13+AL30*Settings!$B$14 | AU30: =AN30*Settings!$B$10+AO30*Settings!$B$11+AR30*Settings!$B$7+AS30*Settings!$B$8+AJ30*Settings!$B$12+AK30*Settings!$B$13+AL30*Settings!$B$14+AQ30*Settings!$B$9 | AV30: =AN30*Settings!$B$10+AO30*Settings!$B$11+AR30*Settings!$B$7+AS30*Settings!$B$8+AJ30*Settings!$B$12+AK30*Settings!$B$13+AL30*Settings!$B$14+AQ30*Settings!$B$15
A31: WR | B31: Other WRs | W31: 17 | AH31: =IFERROR(X31*$F$4,0) | AI31: =IFERROR(AH31*Y31,0) | AJ31: =IFERROR(X31*SUM($AR$12:$AR$36),0) | AK31: =IFERROR(X31*$E$7,0) | AL31: =IFERROR(AH31*Z31,0) | AM31: =IFERROR(AA31*$G$4,0) | AN31: =IFERROR(AM31*AB31,0) | AO31: =IFERROR(AC31*$D$7,0) | AP31: =IFERROR(AD31*$H$4,0) | AQ31: =IFERROR(AP31*AE31,0) | AR31: =IFERROR(AQ31*AF31,0) | AS31: =IFERROR(AG31*$E$7,0) | AT31: =AN31*Settings!$B$10+AO31*Settings!$B$11+AR31*Settings!$B$7+AS31*Settings!$B$8+AJ31*Settings!$B$12+AK31*Settings!$B$13+AL31*Settings!$B$14 | AU31: =AN31*Settings!$B$10+AO31*Settings!$B$11+AR31*Settings!$B$7+AS31*Settings!$B$8+AJ31*Settings!$B$12+AK31*Settings!$B$13+AL31*Settings!$B$14+AQ31*Settings!$B$9 | AV31: =AN31*Settings!$B$10+AO31*Settings!$B$11+AR31*Settings!$B$7+AS31*Settings!$B$8+AJ31*Settings!$B$12+AK31*Settings!$B$13+AL31*Settings!$B$14+AQ31*Settings!$B$15
A32: TE | B32: Trey McBride | C32: 1 | D32: 26 | E32: ACT | F32: ARI | G32: 17 | H32: 0.864 | Q32: 0.2811 | R32: 0.2739 | S32: 0.752 | T32: 10.05 | U32: 0.3333 | V32: 0.3793 | W32: 17 | AD32: 0.251 | AE32: 0.7521 | AF32: 9.8 | AG32: 0.251 | AH32: =IFERROR(X32*$F$4,0) | AI32: =IFERROR(AH32*Y32,0) | AJ32: =IFERROR(X32*SUM($AR$12:$AR$36),0) | AK32: =IFERROR(X32*$E$7,0) | AL32: =IFERROR(AH32*Z32,0) | AM32: =IFERROR(AA32*$G$4,0) | AN32: =IFERROR(AM32*AB32,0) | AO32: =IFERROR(AC32*$D$7,0) | AP32: =IFERROR(AD32*$H$4,0) | AQ32: =IFERROR(AP32*AE32,0) | AR32: =IFERROR(AQ32*AF32,0) | AS32: =IFERROR(AG32*$E$7,0) | AT32: =AN32*Settings!$B$10+AO32*Settings!$B$11+AR32*Settings!$B$7+AS32*Settings!$B$8+AJ32*Settings!$B$12+AK32*Settings!$B$13+AL32*Settings!$B$14 | AU32: =AN32*Settings!$B$10+AO32*Settings!$B$11+AR32*Settings!$B$7+AS32*Settings!$B$8+AJ32*Settings!$B$12+AK32*Settings!$B$13+AL32*Settings!$B$14+AQ32*Settings!$B$9 | AV32: =AN32*Settings!$B$10+AO32*Settings!$B$11+AR32*Settings!$B$7+AS32*Settings!$B$8+AJ32*Settings!$B$12+AK32*Settings!$B$13+AL32*Settings!$B$14+AQ32*Settings!$B$15
A33: TE | B33: Elijah Higgins | C33: 2 | D33: 25 | E33: ACT | F33: ARI | G33: 17 | H33: 0.378 | Q33: 0.0459 | R33: 0.06 | S33: 0.808 | T33: 9.79 | U33: 0.0417 | W33: 17 | AD33: 0.0497 | AE33: 0.8078 | AF33: 9.94 | AG33: 0.0747 | AH33: =IFERROR(X33*$F$4,0) | AI33: =IFERROR(AH33*Y33,0) | AJ33: =IFERROR(X33*SUM($AR$12:$AR$36),0) | AK33: =IFERROR(X33*$E$7,0) | AL33: =IFERROR(AH33*Z33,0) | AM33: =IFERROR(AA33*$G$4,0) | AN33: =IFERROR(AM33*AB33,0) | AO33: =IFERROR(AC33*$D$7,0) | AP33: =IFERROR(AD33*$H$4,0) | AQ33: =IFERROR(AP33*AE33,0) | AR33: =IFERROR(AQ33*AF33,0) | AS33: =IFERROR(AG33*$E$7,0) | AT33: =AN33*Settings!$B$10+AO33*Settings!$B$11+AR33*Settings!$B$7+AS33*Settings!$B$8+AJ33*Settings!$B$12+AK33*Settings!$B$13+AL33*Settings!$B$14 | AU33: =AN33*Settings!$B$10+AO33*Settings!$B$11+AR33*Settings!$B$7+AS33*Settings!$B$8+AJ33*Settings!$B$12+AK33*Settings!$B$13+AL33*Settings!$B$14+AQ33*Settings!$B$9 | AV33: =AN33*Settings!$B$10+AO33*Settings!$B$11+AR33*Settings!$B$7+AS33*Settings!$B$8+AJ33*Settings!$B$12+AK33*Settings!$B$13+AL33*Settings!$B$14+AQ33*Settings!$B$15
A34: TE | B34: Hunter Long | C34: 3 | D34: 28 | E34: ACT | F34: JAC | G34: 9 | H34: 0.331 | Q34: 0.0166 | R34: 0.0311 | S34: 0.706 | T34: 7.08 | U34: 0.0513 | V34: 0.069 | W34: 17 | AA34: 0.0024 | AD34: 0.0181 | AE34: 0.7441 | AF34: 7.08 | AG34: 0.0593 | AH34: =IFERROR(X34*$F$4,0) | AI34: =IFERROR(AH34*Y34,0) | AJ34: =IFERROR(X34*SUM($AR$12:$AR$36),0) | AK34: =IFERROR(X34*$E$7,0) | AL34: =IFERROR(AH34*Z34,0) | AM34: =IFERROR(AA34*$G$4,0) | AN34: =IFERROR(AM34*AB34,0) | AO34: =IFERROR(AC34*$D$7,0) | AP34: =IFERROR(AD34*$H$4,0) | AQ34: =IFERROR(AP34*AE34,0) | AR34: =IFERROR(AQ34*AF34,0) | AS34: =IFERROR(AG34*$E$7,0) | AT34: =AN34*Settings!$B$10+AO34*Settings!$B$11+AR34*Settings!$B$7+AS34*Settings!$B$8+AJ34*Settings!$B$12+AK34*Settings!$B$13+AL34*Settings!$B$14 | AU34: =AN34*Settings!$B$10+AO34*Settings!$B$11+AR34*Settings!$B$7+AS34*Settings!$B$8+AJ34*Settings!$B$12+AK34*Settings!$B$13+AL34*Settings!$B$14+AQ34*Settings!$B$9 | AV34: =AN34*Settings!$B$10+AO34*Settings!$B$11+AR34*Settings!$B$7+AS34*Settings!$B$8+AJ34*Settings!$B$12+AK34*Settings!$B$13+AL34*Settings!$B$14+AQ34*Settings!$B$15
A35: TE | B35: Tip Reiman | C35: 4 | D35: 24 | E35: PUP | F35: ARI | G35: 4 | H35: 0.386 | Q35: 0.0134 | R35: 0.0081 | W35: 17 | AD35: 0.007 | AE35: 0.8 | AF35: 8.5 | AG35: 0 | AH35: =IFERROR(X35*$F$4,0) | AI35: =IFERROR(AH35*Y35,0) | AJ35: =IFERROR(X35*SUM($AR$12:$AR$36),0) | AK35: =IFERROR(X35*$E$7,0) | AL35: =IFERROR(AH35*Z35,0) | AM35: =IFERROR(AA35*$G$4,0) | AN35: =IFERROR(AM35*AB35,0) | AO35: =IFERROR(AC35*$D$7,0) | AP35: =IFERROR(AD35*$H$4,0) | AQ35: =IFERROR(AP35*AE35,0) | AR35: =IFERROR(AQ35*AF35,0) | AS35: =IFERROR(AG35*$E$7,0) | AT35: =AN35*Settings!$B$10+AO35*Settings!$B$11+AR35*Settings!$B$7+AS35*Settings!$B$8+AJ35*Settings!$B$12+AK35*Settings!$B$13+AL35*Settings!$B$14 | AU35: =AN35*Settings!$B$10+AO35*Settings!$B$11+AR35*Settings!$B$7+AS35*Settings!$B$8+AJ35*Settings!$B$12+AK35*Settings!$B$13+AL35*Settings!$B$14+AQ35*Settings!$B$9 | AV35: =AN35*Settings!$B$10+AO35*Settings!$B$11+AR35*Settings!$B$7+AS35*Settings!$B$8+AJ35*Settings!$B$12+AK35*Settings!$B$13+AL35*Settings!$B$14+AQ35*Settings!$B$15
A36: TE | B36: Other TEs | W36: 17 | AH36: =IFERROR(X36*$F$4,0) | AI36: =IFERROR(AH36*Y36,0) | AJ36: =IFERROR(X36*SUM($AR$12:$AR$36),0) | AK36: =IFERROR(X36*$E$7,0) | AL36: =IFERROR(AH36*Z36,0) | AM36: =IFERROR(AA36*$G$4,0) | AN36: =IFERROR(AM36*AB36,0) | AO36: =IFERROR(AC36*$D$7,0) | AP36: =IFERROR(AD36*$H$4,0) | AQ36: =IFERROR(AP36*AE36,0) | AR36: =IFERROR(AQ36*AF36,0) | AS36: =IFERROR(AG36*$E$7,0) | AT36: =AN36*Settings!$B$10+AO36*Settings!$B$11+AR36*Settings!$B$7+AS36*Settings!$B$8+AJ36*Settings!$B$12+AK36*Settings!$B$13+AL36*Settings!$B$14 | AU36: =AN36*Settings!$B$10+AO36*Settings!$B$11+AR36*Settings!$B$7+AS36*Settings!$B$8+AJ36*Settings!$B$12+AK36*Settings!$B$13+AL36*Settings!$B$14+AQ36*Settings!$B$9 | AV36: =AN36*Settings!$B$10+AO36*Settings!$B$11+AR36*Settings!$B$7+AS36*Settings!$B$8+AJ36*Settings!$B$12+AK36*Settings!$B$13+AL36*Settings!$B$14+AQ36*Settings!$B$15
A38: YOUR TOTAL | X38: =SUM(X12:X36) | AA38: =SUM(AA12:AA36) | AC38: =SUM(AC12:AC36) | AD38: =SUM(AD12:AD36) | AG38: =SUM(AG12:AG36) | AH38: =SUM(AH12:AH36) | AI38: =SUM(AI12:AI36) | AJ38: =SUM(AJ12:AJ36) | AK38: =SUM(AK12:AK36) | AL38: =SUM(AL12:AL36) | AM38: =SUM(AM12:AM36) | AN38: =SUM(AN12:AN36) | ... AV38: =SUM(AV12:AV36)
A39: TEAM | AH39: =$F$4 | AI39: =AQ38 | AJ39: =$F$7 | AK39: =$E$7 | AM39: =$G$4 | AN39: =$G$7 | AO39: =$D$7 | AP39: =$H$4 | AR39: =$H$7 | AS39: =$E$7
A40: DIFF | AH40: =AH38-$F$4 | AI40: =AI38-AQ38 | AJ40: =AJ38-$F$7 | AK40: =AK38-$E$7 | AM40: =AM38-$G$4 | AN40: =AN38-$G$7 | AO40: =AO38-$D$7 | AP40: =AP38-$H$4 | AR40: =AR38-$H$7 | AS40: =AS38-$E$7
B42: Share columns should total 100%. Attempts/targets/TDs should match TEAM closely. Yards are a guideline - within ~8% is fine.

Sheet ATL
A1: ATL - 2026
A2: TEAM VOLUME | C2: blue = you set it; grey = calculated | L2: 2025 ACTUAL
B3: Games | C3: Team Plays | D3: Plays/G | E3: Pass Play % | F3: Pass Att | G3: Rush Att | H3: Targets | L3: Plays | M3: Plays/G | N3: Pass% | O3: PassAtt | P3: RushAtt | Q3: Y/A
B4: 17 | C4: 1062 | D4: =$C$4/$B$4 | E4: 0.57 | F4: =ROUND($C$4*$E$4,0) | G4: =$C$4-$F$4 | H4: =ROUND($F$4*Settings!$B$4,0) | L4: 1048 | M4: 61.6471 | N4: 0.5448 | O4: 545 | P4: 477 | Q4: 6.7945
A5: TEAM SCORING & YARDS | C5: TDs from Vegas implied points; yards are a historical REFERENCE, not a cap
B6: Total TD | C6: Rush TD % | D6: Rush TD | E6: Pass TD | F6: ~Pass Yds | G6: ~Rush Yds | H6: ~Rec Yds | L6: PassYds | M6: RushYds | N6: PassTD | O6: RushTD | P6: TotTD | Q6: RuTD%
B7: 37.6 | C7: 0.47 | D7: =$B$7*$C$7 | E7: =$B$7-$D$7 | F7: 3893 | G7: 2108 | H7: =$F$7 | L7: 3703 | M7: 2138 | N7: 19 | O7: 17 | P7: 36 | Q7: 0.47222222
A9: NOTES | B9: 31% of targets and 34% of carries left this roster. NEW HC Kevin Stefanski + OC Tommy Rees. Zone-heavy run game; little pass-rate change expected. Emphasis on Robinson touches.
A11: Pos | B11: Player | C11: Dep | D11: Age | E11: Status | F11: '25 Tm | G11: '25 G | H11: Snap% | I11: '25 Pass% | J11: 3y Cmp% | K11: 3y Y/A | L11: 3y Int% | M11: '25 Rush% | N11: 3y Y/C | O11: '25 RZRu% | P11: '25 RuTD% | Q11: '24 Tgt% | R11: '25 Tgt% | S11: 3y Ctch | T11: 3y Y/R | U11: '25 RZTg% | V11: '25 ReTD% | W11: Games | X11: Pass % | Y11: Comp % | Z11: Int Rate | AA11: Rush % | AB11: Y/C | AC11: Rush TD % | AD11: Tgt % | AE11: Catch % | AF11: Y/R | AG11: Rec TD % | AH11: Pass Att | AI11: Cmp | AJ11: Pass Yds | AK11: Pass TD | AL11: Int | AM11: Rush Att | AN11: Rush Yds | AO11: Rush TD | AP11: Targets | AQ11: Rec | AR11: Rec Yds | AS11: Rec TD | AT11: STD | AU11: Half | AV11: PPR
A12: QB | B12: Tua Tagovailoa | C12: 1 | D12: 28 | E12: ACT | F12: MIA | G12: 14 | H12: 0.959 | I12: 0.8017 | J12: 0.694 | K12: 7.32 | L12: 0.03 | M12: 0.0377 | N12: 3.08 | O12: 0.0303 | W12: 17 | X12: 0.51 | Y12: 0.685 | Z12: 0.03 | AA12: 0.02 | AB12: 2.5 | AH12: =IFERROR(X12*$F$4,0) | AI12: =IFERROR(AH12*Y12,0) | AJ12: =IFERROR(X12*SUM($AR$12:$AR$36),0) | AK12: =IFERROR(X12*$E$7,0) | AL12: =IFERROR(AH12*Z12,0) | AM12: =IFERROR(AA12*$G$4,0) | AN12: =IFERROR(AM12*AB12,0) | AO12: =IFERROR(AC12*$D$7,0) | AP12: =IFERROR(AD12*$H$4,0) | AQ12: =IFERROR(AP12*AE12,0) | AR12: =IFERROR(AQ12*AF12,0) | AS12: =IFERROR(AG12*$E$7,0) | AT12: =AN12*Settings!$B$10+AO12*Settings!$B$11+AR12*Settings!$B$7+AS12*Settings!$B$8+AJ12*Settings!$B$12+AK12*Settings!$B$13+AL12*Settings!$B$14 | AU12: =AN12*Settings!$B$10+AO12*Settings!$B$11+AR12*Settings!$B$7+AS12*Settings!$B$8+AJ12*Settings!$B$12+AK12*Settings!$B$13+AL12*Settings!$B$14+AQ12*Settings!$B$9 | AV12: =AN12*Settings!$B$10+AO12*Settings!$B$11+AR12*Settings!$B$7+AS12*Settings!$B$8+AJ12*Settings!$B$12+AK12*Settings!$B$13+AL12*Settings!$B$14+AQ12*Settings!$B$15
A13: QB | B13: Michael Penix | C13: 2 | D13: 26 | E13: QUESTIONABLE | F13: ATL | G13: 9 | H13: 0.832 | I13: 0.5064 | J13: 0.596 | K13: 7.23 | L13: 0.015 | M13: 0.0302 | O13: 0.0448 | P13: 0.0588 | W13: 17 | X13: 0.48 | Y13: 0.596 | Z13: 0.015 | AA13: 0.03 | AB13: 3.1 | AC13: 0.052 | AH13: =IFERROR(X13*$F$4,0) | AI13: =IFERROR(AH13*Y13,0) | AJ13: =IFERROR(X13*SUM($AR$12:$AR$36),0) | AK13: =IFERROR(X13*$E$7,0) | AL13: =IFERROR(AH13*Z13,0) | AM13: =IFERROR(AA13*$G$4,0) | AN13: =IFERROR(AM13*AB13,0) | AO13: =IFERROR(AC13*$D$7,0) | AP13: =IFERROR(AD13*$H$4,0) | AQ13: =IFERROR(AP13*AE13,0) | AR13: =IFERROR(AQ13*AF13,0) | AS13: =IFERROR(AG13*$E$7,0) | AT13: =AN13*Settings!$B$10+AO13*Settings!$B$11+AR13*Settings!$B$7+AS13*Settings!$B$8+AJ13*Settings!$B$12+AK13*Settings!$B$13+AL13*Settings!$B$14 | AU13: =AN13*Settings!$B$10+AO13*Settings!$B$11+AR13*Settings!$B$7+AS13*Settings!$B$8+AJ13*Settings!$B$12+AK13*Settings!$B$13+AL13*Settings!$B$14+AQ13*Settings!$B$9 | AV13: =AN13*Settings!$B$10+AO13*Settings!$B$11+AR13*Settings!$B$7+AS13*Settings!$B$8+AJ13*Settings!$B$12+AK13*Settings!$B$13+AL13*Settings!$B$14+AQ13*Settings!$B$15
A14: QB | B14: Cooper Rush | C14: 3 | D14: 32 | E14: ACT | F14: BAL | G14: 4 | H14: 0.492 | I14: 0.1232 | J14: 0.649 | K14: 5.94 | L14: 0.039 | M14: 0.002 | W14: 17 | X14: 0.01 | Y14: 0.649 | Z14: 0.039 | AA14: 0.0057 | AB14: 1.5 | AH14: =IFERROR(X14*$F$4,0) | AI14: =IFERROR(AH14*Y14,0) | AJ14: =IFERROR(X14*SUM($AR$12:$AR$36),0) | AK14: =IFERROR(X14*$E$7,0) | AL14: =IFERROR(AH14*Z14,0) | AM14: =IFERROR(AA14*$G$4,0) | AN14: =IFERROR(AM14*AB14,0) | AO14: =IFERROR(AC14*$D$7,0) | AP14: =IFERROR(AD14*$H$4,0) | AQ14: =IFERROR(AP14*AE14,0) | AR14: =IFERROR(AQ14*AF14,0) | AS14: =IFERROR(AG14*$E$7,0) | AT14: =AN14*Settings!$B$10+AO14*Settings!$B$11+AR14*Settings!$B$7+AS14*Settings!$B$8+AJ14*Settings!$B$12+AK14*Settings!$B$13+AL14*Settings!$B$14 | AU14: =AN14*Settings!$B$10+AO14*Settings!$B$11+AR14*Settings!$B$7+AS14*Settings!$B$8+AJ14*Settings!$B$12+AK14*Settings!$B$13+AL14*Settings!$B$14+AQ14*Settings!$B$9 | AV14: =AN14*Settings!$B$10+AO14*Settings!$B$11+AR14*Settings!$B$7+AS14*Settings!$B$8+AJ14*Settings!$B$12+AK14*Settings!$B$13+AL14*Settings!$B$14+AQ14*Settings!$B$15
A15: QB | B15: Other QBs | W15: 17 | AH15: =IFERROR(X15*$F$4,0) | AI15: =IFERROR(AH15*Y15,0) | AJ15: =IFERROR(X15*SUM($AR$12:$AR$36),0) | AK15: =IFERROR(X15*$E$7,0) | AL15: =IFERROR(AH15*Z15,0) | AM15: =IFERROR(AA15*$G$4,0) | AN15: =IFERROR(AM15*AB15,0) | AO15: =IFERROR(AC15*$D$7,0) | AP15: =IFERROR(AD15*$H$4,0) | AQ15: =IFERROR(AP15*AE15,0) | AR15: =IFERROR(AQ15*AF15,0) | AS15: =IFERROR(AG15*$E$7,0) | AT15: =AN15*Settings!$B$10+AO15*Settings!$B$11+AR15*Settings!$B$7+AS15*Settings!$B$8+AJ15*Settings!$B$12+AK15*Settings!$B$13+AL15*Settings!$B$14 | AU15: =AN15*Settings!$B$10+AO15*Settings!$B$11+AR15*Settings!$B$7+AS15*Settings!$B$8+AJ15*Settings!$B$12+AK15*Settings!$B$13+AL15*Settings!$B$14+AQ15*Settings!$B$9 | AV15: =AN15*Settings!$B$10+AO15*Settings!$B$11+AR15*Settings!$B$7+AS15*Settings!$B$8+AJ15*Settings!$B$12+AK15*Settings!$B$13+AL15*Settings!$B$14+AQ15*Settings!$B$15
A16: RB | B16: Bijan Robinson | C16: 1 | D16: 24 | E16: ACT | F16: ATL | G16: 17 | H16: 0.753 | M16: 0.6185 | N16: 4.92 | O16: 0.4776 | P16: 0.4118 | Q16: 0.1336 | R16: 0.1985 | S16: 0.773 | T16: 8.99 | U16: 0.2143 | V16: 0.2105 | W16: 17 | AA16: 0.528 | AB16: 4.85 | AC16: 0.485 | AD16: 0.18 | AE16: 0.77 | AF16: 8.78 | AG16: 0.1383 | AH16: =IFERROR(X16*$F$4,0) | AI16: =IFERROR(AH16*Y16,0) | AJ16: =IFERROR(X16*SUM($AR$12:$AR$36),0) | AK16: =IFERROR(X16*$E$7,0) | AL16: =IFERROR(AH16*Z16,0) | AM16: =IFERROR(AA16*$G$4,0) | AN16: =IFERROR(AM16*AB16,0) | AO16: =IFERROR(AC16*$D$7,0) | AP16: =IFERROR(AD16*$H$4,0) | AQ16: =IFERROR(AP16*AE16,0) | AR16: =IFERROR(AQ16*AF16,0) | AS16: =IFERROR(AG16*$E$7,0) | AT16: =AN16*Settings!$B$10+AO16*Settings!$B$11+AR16*Settings!$B$7+AS16*Settings!$B$8+AJ16*Settings!$B$12+AK16*Settings!$B$13+AL16*Settings!$B$14 | AU16: =AN16*Settings!$B$10+AO16*Settings!$B$11+AR16*Settings!$B$7+AS16*Settings!$B$8+AJ16*Settings!$B$12+AK16*Settings!$B$13+AL16*Settings!$B$14+AQ16*Settings!$B$9 | AV16: =AN16*Settings!$B$10+AO16*Settings!$B$11+AR16*Settings!$B$7+AS16*Settings!$B$8+AJ16*Settings!$B$12+AK16*Settings!$B$13+AL16*Settings!$B$14+AQ16*Settings!$B$15
A17: RB | B17: Brian Robinson | C17: 2 | D17: 27 | E17: ACT | F17: SF | G17: 17 | H17: 0.337 | M17: 0.1991 | N17: 4.28 | O17: 0.1075 | P17: 0.1333 | Q17: 0.0496 | R17: 0.0218 | S17: 0.816 | T17: 8.9 | U17: 0.0482 | W17: 17 | AA17: 0.288 | AB17: 4.15 | AC17: 0.403 | AD17: 0.01 | AE17: 0.7349 | AF17: 8.62 | AG17: 0.1384 | AH17: =IFERROR(X17*$F$4,0) | AI17: =IFERROR(AH17*Y17,0) | AJ17: =IFERROR(X17*SUM($AR$12:$AR$36),0) | AK17: =IFERROR(X17*$E$7,0) | AL17: =IFERROR(AH17*Z17,0) | AM17: =IFERROR(AA17*$G$4,0) | AN17: =IFERROR(AM17*AB17,0) | AO17: =IFERROR(AC17*$D$7,0) | AP17: =IFERROR(AD17*$H$4,0) | AQ17: =IFERROR(AP17*AE17,0) | AR17: =IFERROR(AQ17*AF17,0) | AS17: =IFERROR(AG17*$E$7,0) | AT17: =AN17*Settings!$B$10+AO17*Settings!$B$11+AR17*Settings!$B$7+AS17*Settings!$B$8+AJ17*Settings!$B$12+AK17*Settings!$B$13+AL17*Settings!$B$14 | AU17: =AN17*Settings!$B$10+AO17*Settings!$B$11+AR17*Settings!$B$7+AS17*Settings!$B$8+AJ17*Settings!$B$12+AK17*Settings!$B$13+AL17*Settings!$B$14+AQ17*Settings!$B$9 | AV17: =AN17*Settings!$B$10+AO17*Settings!$B$11+AR17*Settings!$B$7+AS17*Settings!$B$8+AJ17*Settings!$B$12+AK17*Settings!$B$13+AL17*Settings!$B$14+AQ17*Settings!$B$15
A18: RB | AH18: =IFERROR(X18*$F$4,0) | AI18: =IFERROR(AH18*Y18,0) | AJ18: =IFERROR(X18*SUM($AR$12:$AR$36),0) | AK18: =IFERROR(X18*$E$7,0) | AL18: =IFERROR(AH18*Z18,0) | AM18: =IFERROR(AA18*$G$4,0) | AN18: =IFERROR(AM18*AB18,0) | AO18: =IFERROR(AC18*$D$7,0) | AP18: =IFERROR(AD18*$H$4,0) | AQ18: =IFERROR(AP18*AE18,0) | AR18: =IFERROR(AQ18*AF18,0) | AS18: =IFERROR(AG18*$E$7,0) | AT18: =AN18*Settings!$B$10+AO18*Settings!$B$11+AR18*Settings!$B$7+AS18*Settings!$B$8+AJ18*Settings!$B$12+AK18*Settings!$B$13+AL18*Settings!$B$14 | AU18: =AN18*Settings!$B$10+AO18*Settings!$B$11+AR18*Settings!$B$7+AS18*Settings!$B$8+AJ18*Settings!$B$12+AK18*Settings!$B$13+AL18*Settings!$B$14+AQ18*Settings!$B$9 | AV18: =AN18*Settings!$B$10+AO18*Settings!$B$11+AR18*Settings!$B$7+AS18*Settings!$B$8+AJ18*Settings!$B$12+AK18*Settings!$B$13+AL18*Settings!$B$14+AQ18*Settings!$B$15
A19: RB | AH19: =IFERROR(X19*$F$4,0) | AI19: =IFERROR(AH19*Y19,0) | AJ19: =IFERROR(X19*SUM($AR$12:$AR$36),0) | AK19: =IFERROR(X19*$E$7,0) | AL19: =IFERROR(AH19*Z19,0) | AM19: =IFERROR(AA19*$G$4,0) | AN19: =IFERROR(AM19*AB19,0) | AO19: =IFERROR(AC19*$D$7,0) | AP19: =IFERROR(AD19*$H$4,0) | AQ19: =IFERROR(AP19*AE19,0) | AR19: =IFERROR(AQ19*AF19,0) | AS19: =IFERROR(AG19*$E$7,0) | AT19: =AN19*Settings!$B$10+AO19*Settings!$B$11+AR19*Settings!$B$7+AS19*Settings!$B$8+AJ19*Settings!$B$12+AK19*Settings!$B$13+AL19*Settings!$B$14 | AU19: =AN19*Settings!$B$10+AO19*Settings!$B$11+AR19*Settings!$B$7+AS19*Settings!$B$8+AJ19*Settings!$B$12+AK19*Settings!$B$13+AL19*Settings!$B$14+AQ19*Settings!$B$9 | AV19: =AN19*Settings!$B$10+AO19*Settings!$B$11+AR19*Settings!$B$7+AS19*Settings!$B$8+AJ19*Settings!$B$12+AK19*Settings!$B$13+AL19*Settings!$B$14+AQ19*Settings!$B$15
A20: RB | AH20: =IFERROR(X20*$F$4,0) | AI20: =IFERROR(AH20*Y20,0) | AJ20: =IFERROR(X20*SUM($AR$12:$AR$36),0) | AK20: =IFERROR(X20*$E$7,0) | AL20: =IFERROR(AH20*Z20,0) | AM20: =IFERROR(AA20*$G$4,0) | AN20: =IFERROR(AM20*AB20,0) | AO20: =IFERROR(AC20*$D$7,0) | AP20: =IFERROR(AD20*$H$4,0) | AQ20: =IFERROR(AP20*AE20,0) | AR20: =IFERROR(AQ20*AF20,0) | AS20: =IFERROR(AG20*$E$7,0) | AT20: =AN20*Settings!$B$10+AO20*Settings!$B$11+AR20*Settings!$B$7+AS20*Settings!$B$8+AJ20*Settings!$B$12+AK20*Settings!$B$13+AL20*Settings!$B$14 | AU20: =AN20*Settings!$B$10+AO20*Settings!$B$11+AR20*Settings!$B$7+AS20*Settings!$B$8+AJ20*Settings!$B$12+AK20*Settings!$B$13+AL20*Settings!$B$14+AQ20*Settings!$B$9 | AV20: =AN20*Settings!$B$10+AO20*Settings!$B$11+AR20*Settings!$B$7+AS20*Settings!$B$8+AJ20*Settings!$B$12+AK20*Settings!$B$13+AL20*Settings!$B$14+AQ20*Settings!$B$15
A21: RB | AH21: =IFERROR(X21*$F$4,0) | AI21: =IFERROR(AH21*Y21,0) | AJ21: =IFERROR(X21*SUM($AR$12:$AR$36),0) | AK21: =IFERROR(X21*$E$7,0) | AL21: =IFERROR(AH21*Z21,0) | AM21: =IFERROR(AA21*$G$4,0) | AN21: =IFERROR(AM21*AB21,0) | AO21: =IFERROR(AC21*$D$7,0) | AP21: =IFERROR(AD21*$H$4,0) | AQ21: =IFERROR(AP21*AE21,0) | AR21: =IFERROR(AQ21*AF21,0) | AS21: =IFERROR(AG21*$E$7,0) | AT21: =AN21*Settings!$B$10+AO21*Settings!$B$11+AR21*Settings!$B$7+AS21*Settings!$B$8+AJ21*Settings!$B$12+AK21*Settings!$B$13+AL21*Settings!$B$14 | AU21: =AN21*Settings!$B$10+AO21*Settings!$B$11+AR21*Settings!$B$7+AS21*Settings!$B$8+AJ21*Settings!$B$12+AK21*Settings!$B$13+AL21*Settings!$B$14+AQ21*Settings!$B$9 | AV21: =AN21*Settings!$B$10+AO21*Settings!$B$11+AR21*Settings!$B$7+AS21*Settings!$B$8+AJ21*Settings!$B$12+AK21*Settings!$B$13+AL21*Settings!$B$14+AQ21*Settings!$B$15
A22: RB | B22: Other RBs | W22: 17 | AH22: =IFERROR(X22*$F$4,0) | AI22: =IFERROR(AH22*Y22,0) | AJ22: =IFERROR(X22*SUM($AR$12:$AR$36),0) | AK22: =IFERROR(X22*$E$7,0) | AL22: =IFERROR(AH22*Z22,0) | AM22: =IFERROR(AA22*$G$4,0) | AN22: =IFERROR(AM22*AB22,0) | AO22: =IFERROR(AC22*$D$7,0) | AP22: =IFERROR(AD22*$H$4,0) | AQ22: =IFERROR(AP22*AE22,0) | AR22: =IFERROR(AQ22*AF22,0) | AS22: =IFERROR(AG22*$E$7,0) | AT22: =AN22*Settings!$B$10+AO22*Settings!$B$11+AR22*Settings!$B$7+AS22*Settings!$B$8+AJ22*Settings!$B$12+AK22*Settings!$B$13+AL22*Settings!$B$14 | AU22: =AN22*Settings!$B$10+AO22*Settings!$B$11+AR22*Settings!$B$7+AS22*Settings!$B$8+AJ22*Settings!$B$12+AK22*Settings!$B$13+AL22*Settings!$B$14+AQ22*Settings!$B$9 | AV22: =AN22*Settings!$B$10+AO22*Settings!$B$11+AR22*Settings!$B$7+AS22*Settings!$B$8+AJ22*Settings!$B$12+AK22*Settings!$B$13+AL22*Settings!$B$14+AQ22*Settings!$B$15
A23: WR | B23: Drake London | C23: 1 | D23: 25 | E23: ACT | F23: ATL | G23: 12 | H23: 0.885 | Q23: 0.2931 | R23: 0.2158 | S23: 0.621 | T23: 13.14 | U23: 0.2321 | V23: 0.3684 | W23: 17 | AD23: 0.25 | AE23: 0.63 | AF23: 13.06 | AG23: 0.2772 | AH23: =IFERROR(X23*$F$4,0) | AI23: =IFERROR(AH23*Y23,0) | AJ23: =IFERROR(X23*SUM($AR$12:$AR$36),0) | AK23: =IFERROR(X23*$E$7,0) | AL23: =IFERROR(AH23*Z23,0) | AM23: =IFERROR(AA23*$G$4,0) | AN23: =IFERROR(AM23*AB23,0) | AO23: =IFERROR(AC23*$D$7,0) | AP23: =IFERROR(AD23*$H$4,0) | AQ23: =IFERROR(AP23*AE23,0) | AR23: =IFERROR(AQ23*AF23,0) | AS23: =IFERROR(AG23*$E$7,0) | AT23: =AN23*Settings!$B$10+AO23*Settings!$B$11+AR23*Settings!$B$7+AS23*Settings!$B$8+AJ23*Settings!$B$12+AK23*Settings!$B$13+AL23*Settings!$B$14 | AU23: =AN23*Settings!$B$10+AO23*Settings!$B$11+AR23*Settings!$B$7+AS23*Settings!$B$8+AJ23*Settings!$B$12+AK23*Settings!$B$13+AL23*Settings!$B$14+AQ23*Settings!$B$9 | AV23: =AN23*Settings!$B$10+AO23*Settings!$B$11+AR23*Settings!$B$7+AS23*Settings!$B$8+AJ23*Settings!$B$12+AK23*Settings!$B$13+AL23*Settings!$B$14+AQ23*Settings!$B$15
A24: WR | B24: Jahan Dotson | C24: 2 | D24: 26 | E24: ACT | F24: PHI | G24: 17 | H24: 0.624 | Q24: 0.0789 | R24: 0.0776 | S24: 0.541 | T24: 12.8 | U24: 0.0556 | V24: 0.0385 | W24: 17 | AD24: 0.0904 | AE24: 0.54 | AF24: 11.58 | AG24: 0.0624 | AH24: =IFERROR(X24*$F$4,0) | AI24: =IFERROR(AH24*Y24,0) | AJ24: =IFERROR(X24*SUM($AR$12:$AR$36),0) | AK24: =IFERROR(X24*$E$7,0) | AL24: =IFERROR(AH24*Z24,0) | AM24: =IFERROR(AA24*$G$4,0) | AN24: =IFERROR(AM24*AB24,0) | AO24: =IFERROR(AC24*$D$7,0) | AP24: =IFERROR(AD24*$H$4,0) | AQ24: =IFERROR(AP24*AE24,0) | AR24: =IFERROR(AQ24*AF24,0) | AS24: =IFERROR(AG24*$E$7,0) | AT24: =AN24*Settings!$B$10+AO24*Settings!$B$11+AR24*Settings!$B$7+AS24*Settings!$B$8+AJ24*Settings!$B$12+AK24*Settings!$B$13+AL24*Settings!$B$14 | AU24: =AN24*Settings!$B$10+AO24*Settings!$B$11+AR24*Settings!$B$7+AS24*Settings!$B$8+AJ24*Settings!$B$12+AK24*Settings!$B$13+AL24*Settings!$B$14+AQ24*Settings!$B$9 | AV24: =AN24*Settings!$B$10+AO24*Settings!$B$11+AR24*Settings!$B$7+AS24*Settings!$B$8+AJ24*Settings!$B$12+AK24*Settings!$B$13+AL24*Settings!$B$14+AQ24*Settings!$B$15
A25: WR | B25: Zachariah Branch | C25: 3 | D25: 22 | E25: ACT | W25: 17 | AD25: 0.1337 | AE25: 0.66 | AF25: 12.84 | AH25: =IFERROR(X25*$F$4,0) | AI25: =IFERROR(AH25*Y25,0) | AJ25: =IFERROR(X25*SUM($AR$12:$AR$36),0) | AK25: =IFERROR(X25*$E$7,0) | AL25: =IFERROR(AH25*Z25,0) | AM25: =IFERROR(AA25*$G$4,0) | AN25: =IFERROR(AM25*AB25,0) | AO25: =IFERROR(AC25*$D$7,0) | AP25: =IFERROR(AD25*$H$4,0) | AQ25: =IFERROR(AP25*AE25,0) | AR25: =IFERROR(AQ25*AF25,0) | AS25: =IFERROR(AG25*$E$7,0) | AT25: =AN25*Settings!$B$10+AO25*Settings!$B$11+AR25*Settings!$B$7+AS25*Settings!$B$8+AJ25*Settings!$B$12+AK25*Settings!$B$13+AL25*Settings!$B$14 | AU25: =AN25*Settings!$B$10+AO25*Settings!$B$11+AR25*Settings!$B$7+AS25*Settings!$B$8+AJ25*Settings!$B$12+AK25*Settings!$B$13+AL25*Settings!$B$14+AQ25*Settings!$B$9 | AV25: =AN25*Settings!$B$10+AO25*Settings!$B$11+AR25*Settings!$B$7+AS25*Settings!$B$8+AJ25*Settings!$B$12+AK25*Settings!$B$13+AL25*Settings!$B$14+AQ25*Settings!$B$15
A26: WR | B26: Olamide Zaccheaus | C26: 4 | D26: 29 | E26: ACT | F26: CHI | G26: 16 | H26: 0.475 | M26: 0.0081 | Q26: 0.127 | R26: 0.1222 | S26: 0.611 | T26: 9.28 | U26: 0.1791 | V26: 0.0714 | W26: 17 | AD26: 0.07 | AE26: 0.6113 | AF26: 9.1 | AG26: 0.0696 | AH26: =IFERROR(X26*$F$4,0) | AI26: =IFERROR(AH26*Y26,0) | AJ26: =IFERROR(X26*SUM($AR$12:$AR$36),0) | AK26: =IFERROR(X26*$E$7,0) | AL26: =IFERROR(AH26*Z26,0) | AM26: =IFERROR(AA26*$G$4,0) | AN26: =IFERROR(AM26*AB26,0) | AO26: =IFERROR(AC26*$D$7,0) | AP26: =IFERROR(AD26*$H$4,0) | AQ26: =IFERROR(AP26*AE26,0) | AR26: =IFERROR(AQ26*AF26,0) | AS26: =IFERROR(AG26*$E$7,0) | AT26: =AN26*Settings!$B$10+AO26*Settings!$B$11+AR26*Settings!$B$7+AS26*Settings!$B$8+AJ26*Settings!$B$12+AK26*Settings!$B$13+AL26*Settings!$B$14 | AU26: =AN26*Settings!$B$10+AO26*Settings!$B$11+AR26*Settings!$B$7+AS26*Settings!$B$8+AJ26*Settings!$B$12+AK26*Settings!$B$13+AL26*Settings!$B$14+AQ26*Settings!$B$9 | AV26: =AN26*Settings!$B$10+AO26*Settings!$B$11+AR26*Settings!$B$7+AS26*Settings!$B$8+AJ26*Settings!$B$12+AK26*Settings!$B$13+AL26*Settings!$B$14+AQ26*Settings!$B$15
A27: WR | B27: Chris Blair | C27: 5 | D27: 28 | E27: ACT | H27: 0.11 | Q27: 0.0037 | W27: 17 | AH27: =IFERROR(X27*$F$4,0) | AI27: =IFERROR(AH27*Y27,0) | AJ27: =IFERROR(X27*SUM($AR$12:$AR$36),0) | AK27: =IFERROR(X27*$E$7,0) | AL27: =IFERROR(AH27*Z27,0) | AM27: =IFERROR(AA27*$G$4,0) | AN27: =IFERROR(AM27*AB27,0) | AO27: =IFERROR(AC27*$D$7,0) | AP27: =IFERROR(AD27*$H$4,0) | AQ27: =IFERROR(AP27*AE27,0) | AR27: =IFERROR(AQ27*AF27,0) | AS27: =IFERROR(AG27*$E$7,0) | AT27: =AN27*Settings!$B$10+AO27*Settings!$B$11+AR27*Settings!$B$7+AS27*Settings!$B$8+AJ27*Settings!$B$12+AK27*Settings!$B$13+AL27*Settings!$B$14 | AU27: =AN27*Settings!$B$10+AO27*Settings!$B$11+AR27*Settings!$B$7+AS27*Settings!$B$8+AJ27*Settings!$B$12+AK27*Settings!$B$13+AL27*Settings!$B$14+AQ27*Settings!$B$9 | AV27: =AN27*Settings!$B$10+AO27*Settings!$B$11+AR27*Settings!$B$7+AS27*Settings!$B$8+AJ27*Settings!$B$12+AK27*Settings!$B$13+AL27*Settings!$B$14+AQ27*Settings!$B$15
A28: WR | B28: Malik Heath | C28: 6 | D28: 25 | E28: ACT | F28: GB | G28: 11 | H28: 0.277 | Q28: 0.028 | R28: 0.0152 | S28: 0.625 | T28: 8.33 | W28: 17 | AA28: 0.0022 | AD28: 0.0121 | AE28: 0.7783 | AF28: 8.33 | AG28: 0.0458 | AH28: =IFERROR(X28*$F$4,0) | AI28: =IFERROR(AH28*Y28,0) | AJ28: =IFERROR(X28*SUM($AR$12:$AR$36),0) | AK28: =IFERROR(X28*$E$7,0) | AL28: =IFERROR(AH28*Z28,0) | AM28: =IFERROR(AA28*$G$4,0) | AN28: =IFERROR(AM28*AB28,0) | AO28: =IFERROR(AC28*$D$7,0) | AP28: =IFERROR(AD28*$H$4,0) | AQ28: =IFERROR(AP28*AE28,0) | AR28: =IFERROR(AQ28*AF28,0) | AS28: =IFERROR(AG28*$E$7,0) | AT28: =AN28*Settings!$B$10+AO28*Settings!$B$11+AR28*Settings!$B$7+AS28*Settings!$B$8+AJ28*Settings!$B$12+AK28*Settings!$B$13+AL28*Settings!$B$14 | AU28: =AN28*Settings!$B$10+AO28*Settings!$B$11+AR28*Settings!$B$7+AS28*Settings!$B$8+AJ28*Settings!$B$12+AK28*Settings!$B$13+AL28*Settings!$B$14+AQ28*Settings!$B$9 | AV28: =AN28*Settings!$B$10+AO28*Settings!$B$11+AR28*Settings!$B$7+AS28*Settings!$B$8+AJ28*Settings!$B$12+AK28*Settings!$B$13+AL28*Settings!$B$14+AQ28*Settings!$B$15
A29: WR | B29: Garrett Scantling | C29: 7 | E29: ACT | W29: 17 | AA29: 0.0024 | AD29: 0.0063 | AE29: 0.65 | AF29: 12.84 | AH29: =IFERROR(X29*$F$4,0) | AI29: =IFERROR(AH29*Y29,0) | AJ29: =IFERROR(X29*SUM($AR$12:$AR$36),0) | AK29: =IFERROR(X29*$E$7,0) | AL29: =IFERROR(AH29*Z29,0) | AM29: =IFERROR(AA29*$G$4,0) | AN29: =IFERROR(AM29*AB29,0) | AO29: =IFERROR(AC29*$D$7,0) | AP29: =IFERROR(AD29*$H$4,0) | AQ29: =IFERROR(AP29*AE29,0) | AR29: =IFERROR(AQ29*AF29,0) | AS29: =IFERROR(AG29*$E$7,0) | AT29: =AN29*Settings!$B$10+AO29*Settings!$B$11+AR29*Settings!$B$7+AS29*Settings!$B$8+AJ29*Settings!$B$12+AK29*Settings!$B$13+AL29*Settings!$B$14 | AU29: =AN29*Settings!$B$10+AO29*Settings!$B$11+AR29*Settings!$B$7+AS29*Settings!$B$8+AJ29*Settings!$B$12+AK29*Settings!$B$13+AL29*Settings!$B$14+AQ29*Settings!$B$9 | AV29: =AN29*Settings!$B$10+AO29*Settings!$B$11+AR29*Settings!$B$7+AS29*Settings!$B$8+AJ29*Settings!$B$12+AK29*Settings!$B$13+AL29*Settings!$B$14+AQ29*Settings!$B$15
A30: WR | AH30: =IFERROR(X30*$F$4,0) | AI30: =IFERROR(AH30*Y30,0) | AJ30: =IFERROR(X30*SUM($AR$12:$AR$36),0) | AK30: =IFERROR(X30*$E$7,0) | AL30: =IFERROR(AH30*Z30,0) | AM30: =IFERROR(AA30*$G$4,0) | AN30: =IFERROR(AM30*AB30,0) | AO30: =IFERROR(AC30*$D$7,0) | AP30: =IFERROR(AD30*$H$4,0) | AQ30: =IFERROR(AP30*AE30,0) | AR30: =IFERROR(AQ30*AF30,0) | AS30: =IFERROR(AG30*$E$7,0) | AT30: =AN30*Settings!$B$10+AO30*Settings!$B$11+AR30*Settings!$B$7+AS30*Settings!$B$8+AJ30*Settings!$B$12+AK30*Settings!$B$13+AL30*Settings!$B$14 | AU30: =AN30*Settings!$B$10+AO30*Settings!$B$11+AR30*Settings!$B$7+AS30*Settings!$B$8+AJ30*Settings!$B$12+AK30*Settings!$B$13+AL30*Settings!$B$14+AQ30*Settings!$B$9 | AV30: =AN30*Settings!$B$10+AO30*Settings!$B$11+AR30*Settings!$B$7+AS30*Settings!$B$8+AJ30*Settings!$B$12+AK30*Settings!$B$13+AL30*Settings!$B$14+AQ30*Settings!$B$15
A31: WR | B31: Other WRs | W31: 17 | AH31: =IFERROR(X31*$F$4,0) | AI31: =IFERROR(AH31*Y31,0) | AJ31: =IFERROR(X31*SUM($AR$12:$AR$36),0) | AK31: =IFERROR(X31*$E$7,0) | AL31: =IFERROR(AH31*Z31,0) | AM31: =IFERROR(AA31*$G$4,0) | AN31: =IFERROR(AM31*AB31,0) | AO31: =IFERROR(AC31*$D$7,0) | AP31: =IFERROR(AD31*$H$4,0) | AQ31: =IFERROR(AP31*AE31,0) | AR31: =IFERROR(AQ31*AF31,0) | AS31: =IFERROR(AG31*$E$7,0) | AT31: =AN31*Settings!$B$10+AO31*Settings!$B$11+AR31*Settings!$B$7+AS31*Settings!$B$8+AJ31*Settings!$B$12+AK31*Settings!$B$13+AL31*Settings!$B$14 | AU31: =AN31*Settings!$B$10+AO31*Settings!$B$11+AR31*Settings!$B$7+AS31*Settings!$B$8+AJ31*Settings!$B$12+AK31*Settings!$B$13+AL31*Settings!$B$14+AQ31*Settings!$B$9 | AV31: =AN31*Settings!$B$10+AO31*Settings!$B$11+AR31*Settings!$B$7+AS31*Settings!$B$8+AJ31*Settings!$B$12+AK31*Settings!$B$13+AL31*Settings!$B$14+AQ31*Settings!$B$15
A32: TE | B32: Kyle Pitts | C32: 1 | D32: 25 | E32: ACT | F32: ATL | G32: 17 | H32: 0.755 | Q32: 0.1373 | R32: 0.2274 | S32: 0.681 | T32: 11.63 | U32: 0.1964 | V32: 0.2632 | W32: 17 | AD32: 0.1751 | AE32: 0.6812 | AF32: 10.8 | AG32: 0.186 | AH32: =IFERROR(X32*$F$4,0) | AI32: =IFERROR(AH32*Y32,0) | AJ32: =IFERROR(X32*SUM($AR$12:$AR$36),0) | AK32: =IFERROR(X32*$E$7,0) | AL32: =IFERROR(AH32*Z32,0) | AM32: =IFERROR(AA32*$G$4,0) | AN32: =IFERROR(AM32*AB32,0) | AO32: =IFERROR(AC32*$D$7,0) | AP32: =IFERROR(AD32*$H$4,0) | AQ32: =IFERROR(AP32*AE32,0) | AR32: =IFERROR(AQ32*AF32,0) | AS32: =IFERROR(AG32*$E$7,0) | AT32: =AN32*Settings!$B$10+AO32*Settings!$B$11+AR32*Settings!$B$7+AS32*Settings!$B$8+AJ32*Settings!$B$12+AK32*Settings!$B$13+AL32*Settings!$B$14 | AU32: =AN32*Settings!$B$10+AO32*Settings!$B$11+AR32*Settings!$B$7+AS32*Settings!$B$8+AJ32*Settings!$B$12+AK32*Settings!$B$13+AL32*Settings!$B$14+AQ32*Settings!$B$9 | AV32: =AN32*Settings!$B$10+AO32*Settings!$B$11+AR32*Settings!$B$7+AS32*Settings!$B$8+AJ32*Settings!$B$12+AK32*Settings!$B$13+AL32*Settings!$B$14+AQ32*Settings!$B$15
A33: TE | B33: Austin Hooper | C33: 2 | D33: 31 | E33: ACT | F33: NE | G33: 16 | H33: 0.512 | Q33: 0.118 | R33: 0.0539 | S33: 0.794 | T33: 11.27 | U33: 0.0769 | V33: 0.0645 | W33: 17 | AD33: 0.052 | AE33: 0.7935 | AF33: 10.69 | AG33: 0.0866 | AH33: =IFERROR(X33*$F$4,0) | AI33: =IFERROR(AH33*Y33,0) | AJ33: =IFERROR(X33*SUM($AR$12:$AR$36),0) | AK33: =IFERROR(X33*$E$7,0) | AL33: =IFERROR(AH33*Z33,0) | AM33: =IFERROR(AA33*$G$4,0) | AN33: =IFERROR(AM33*AB33,0) | AO33: =IFERROR(AC33*$D$7,0) | AP33: =IFERROR(AD33*$H$4,0) | AQ33: =IFERROR(AP33*AE33,0) | AR33: =IFERROR(AQ33*AF33,0) | AS33: =IFERROR(AG33*$E$7,0) | AT33: =AN33*Settings!$B$10+AO33*Settings!$B$11+AR33*Settings!$B$7+AS33*Settings!$B$8+AJ33*Settings!$B$12+AK33*Settings!$B$13+AL33*Settings!$B$14 | AU33: =AN33*Settings!$B$10+AO33*Settings!$B$11+AR33*Settings!$B$7+AS33*Settings!$B$8+AJ33*Settings!$B$12+AK33*Settings!$B$13+AL33*Settings!$B$14+AQ33*Settings!$B$9 | AV33: =AN33*Settings!$B$10+AO33*Settings!$B$11+AR33*Settings!$B$7+AS33*Settings!$B$8+AJ33*Settings!$B$12+AK33*Settings!$B$13+AL33*Settings!$B$14+AQ33*Settings!$B$15
A34: TE | B34: Charlie Woerner | C34: 3 | D34: 28 | E34: ACT | F34: ATL | G34: 17 | H34: 0.44 | Q34: 0.0223 | R34: 0.0173 | U34: 0.0179 | W34: 17 | AD34: 0.0157 | AE34: 0.8237 | AF34: 7 | AH34: =IFERROR(X34*$F$4,0) | AI34: =IFERROR(AH34*Y34,0) | AJ34: =IFERROR(X34*SUM($AR$12:$AR$36),0) | AK34: =IFERROR(X34*$E$7,0) | AL34: =IFERROR(AH34*Z34,0) | AM34: =IFERROR(AA34*$G$4,0) | AN34: =IFERROR(AM34*AB34,0) | AO34: =IFERROR(AC34*$D$7,0) | AP34: =IFERROR(AD34*$H$4,0) | AQ34: =IFERROR(AP34*AE34,0) | AR34: =IFERROR(AQ34*AF34,0) | AS34: =IFERROR(AG34*$E$7,0) | AT34: =AN34*Settings!$B$10+AO34*Settings!$B$11+AR34*Settings!$B$7+AS34*Settings!$B$8+AJ34*Settings!$B$12+AK34*Settings!$B$13+AL34*Settings!$B$14 | AU34: =AN34*Settings!$B$10+AO34*Settings!$B$11+AR34*Settings!$B$7+AS34*Settings!$B$8+AJ34*Settings!$B$12+AK34*Settings!$B$13+AL34*Settings!$B$14+AQ34*Settings!$B$9 | AV34: =AN34*Settings!$B$10+AO34*Settings!$B$11+AR34*Settings!$B$7+AS34*Settings!$B$8+AJ34*Settings!$B$12+AK34*Settings!$B$13+AL34*Settings!$B$14+AQ34*Settings!$B$15
A35: TE | B35: Lee Smith | C35: 4 | D35: 34 | E35: ACT | W35: 17 | AA35: 0.0024 | AD35: 0.0046 | AE35: 0.65 | AF35: 10.32 | AH35: =IFERROR(X35*$F$4,0) | AI35: =IFERROR(AH35*Y35,0) | AJ35: =IFERROR(X35*SUM($AR$12:$AR$36),0) | AK35: =IFERROR(X35*$E$7,0) | AL35: =IFERROR(AH35*Z35,0) | AM35: =IFERROR(AA35*$G$4,0) | AN35: =IFERROR(AM35*AB35,0) | AO35: =IFERROR(AC35*$D$7,0) | AP35: =IFERROR(AD35*$H$4,0) | AQ35: =IFERROR(AP35*AE35,0) | AR35: =IFERROR(AQ35*AF35,0) | AS35: =IFERROR(AG35*$E$7,0) | AT35: =AN35*Settings!$B$10+AO35*Settings!$B$11+AR35*Settings!$B$7+AS35*Settings!$B$8+AJ35*Settings!$B$12+AK35*Settings!$B$13+AL35*Settings!$B$14 | AU35: =AN35*Settings!$B$10+AO35*Settings!$B$11+AR35*Settings!$B$7+AS35*Settings!$B$8+AJ35*Settings!$B$12+AK35*Settings!$B$13+AL35*Settings!$B$14+AQ35*Settings!$B$9 | AV35: =AN35*Settings!$B$10+AO35*Settings!$B$11+AR35*Settings!$B$7+AS35*Settings!$B$8+AJ35*Settings!$B$12+AK35*Settings!$B$13+AL35*Settings!$B$14+AQ35*Settings!$B$15
A36: TE | B36: Other TEs | W36: 17 | AH36: =IFERROR(X36*$F$4,0) | AI36: =IFERROR(AH36*Y36,0) | AJ36: =IFERROR(X36*SUM($AR$12:$AR$36),0) | AK36: =IFERROR(X36*$E$7,0) | AL36: =IFERROR(AH36*Z36,0) | AM36: =IFERROR(AA36*$G$4,0) | AN36: =IFERROR(AM36*AB36,0) | AO36: =IFERROR(AC36*$D$7,0) | AP36: =IFERROR(AD36*$H$4,0) | AQ36: =IFERROR(AP36*AE36,0) | AR36: =IFERROR(AQ36*AF36,0) | AS36: =IFERROR(AG36*$E$7,0) | AT36: =AN36*Settings!$B$10+AO36*Settings!$B$11+AR36*Settings!$B$7+AS36*Settings!$B$8+AJ36*Settings!$B$12+AK36*Settings!$B$13+AL36*Settings!$B$14 | AU36: =AN36*Settings!$B$10+AO36*Settings!$B$11+AR36*Settings!$B$7+AS36*Settings!$B$8+AJ36*Settings!$B$12+AK36*Settings!$B$13+AL36*Settings!$B$14+AQ36*Settings!$B$9 | AV36: =AN36*Settings!$B$10+AO36*Settings!$B$11+AR36*Settings!$B$7+AS36*Settings!$B$8+AJ36*Settings!$B$12+AK36*Settings!$B$13+AL36*Settings!$B$14+AQ36*Settings!$B$15
A38: YOUR TOTAL | X38: =SUM(X12:X36) | AA38: =SUM(AA12:AA36) | AC38: =SUM(AC12:AC36) | AD38: =SUM(AD12:AD36) | AG38: =SUM(AG12:AG36) | AH38: =SUM(AH12:AH36) | AI38: =SUM(AI12:AI36) | AJ38: =SUM(AJ12:AJ36) | AK38: =SUM(AK12:AK36) | AL38: =SUM(AL12:AL36) | AM38: =SUM(AM12:AM36) | AN38: =SUM(AN12:AN36) | ... AV38: =SUM(AV12:AV36)
A39: TEAM | AH39: =$F$4 | AI39: =AQ38 | AJ39: =$F$7 | AK39: =$E$7 | AM39: =$G$4 | AN39: =$G$7 | AO39: =$D$7 | AP39: =$H$4 | AR39: =$H$7 | AS39: =$E$7
A40: DIFF | AH40: =AH38-$F$4 | AI40: =AI38-AQ38 | AJ40: =AJ38-$F$7 | AK40: =AK38-$E$7 | AM40: =AM38-$G$4 | AN40: =AN38-$G$7 | AO40: =AO38-$D$7 | AP40: =AP38-$H$4 | AR40: =AR38-$H$7 | AS40: =AS38-$E$7
B42: Share columns should total 100%. Attempts/targets/TDs should match TEAM closely. Yards are a guideline - within ~8% is fine.

Sheet BAL
A1: BAL - 2026
A2: TEAM VOLUME | C2: blue = you set it; grey = calculated | L2: 2025 ACTUAL
B3: Games | C3: Team Plays | D3: Plays/G | E3: Pass Play % | F3: Pass Att | G3: Rush Att | H3: Targets | L3: Plays | M3: Plays/G | N3: Pass% | O3: PassAtt | P3: RushAtt | Q3: Y/A
B4: 17 | C4: 1032 | D4: =$C$4/$B$4 | E4: 0.5063 | F4: =ROUND($C$4*$E$4,0) | G4: =$C$4-$F$4 | H4: =ROUND($F$4*Settings!$B$4,0) | L4: 974 | M4: 57.2941 | N4: 0.4795 | O4: 422 | P4: 507 | Q4: 7.7678
A5: TEAM SCORING & YARDS | C5: TDs from Vegas implied points; yards are a historical REFERENCE, not a cap
B6: Total TD | C6: Rush TD % | D6: Rush TD | E6: Pass TD | F6: ~Pass Yds | G6: ~Rush Yds | H6: ~Rec Yds | L6: PassYds | M6: RushYds | N6: PassTD | O6: RushTD | P6: TotTD | Q6: RuTD%
B7: 45.8 | C7: 0.4167 | D7: =$B$7*$C$7 | E7: =$B$7-$D$7 | F7: 3763 | G7: 2551 | H7: =$F$7 | L7: 3278 | M7: 2662 | N7: 23 | O7: 23 | P7: 46 | Q7: 0.5
A9: NOTES | B9: 27% of targets and 12% of carries left this roster. NEW HC Jesse Minter + OC Declan Doyle. More explosive plays expected - Doyle brings creativity and detail.
A11: Pos | B11: Player | C11: Dep | D11: Age | E11: Status | F11: '25 Tm | G11: '25 G | H11: Snap% | I11: '25 Pass% | J11: 3y Cmp% | K11: 3y Y/A | L11: 3y Int% | M11: '25 Rush% | N11: 3y Y/C | O11: '25 RZRu% | P11: '25 RuTD% | Q11: '24 Tgt% | R11: '25 Tgt% | S11: 3y Ctch | T11: 3y Y/R | U11: '25 RZTg% | V11: '25 ReTD% | W11: Games | X11: Pass % | Y11: Comp % | Z11: Int Rate | AA11: Rush % | AB11: Y/C | AC11: Rush TD % | AD11: Tgt % | AE11: Catch % | AF11: Y/R | AG11: Rec TD % | AH11: Pass Att | AI11: Cmp | AJ11: Pass Yds | AK11: Pass TD | AL11: Int | AM11: Rush Att | AN11: Rush Yds | AO11: Rush TD | AP11: Targets | AQ11: Rec | AR11: Rec Yds | AS11: Rec TD | AT11: STD | AU11: Half | AV11: PPR
A12: QB | B12: Lamar Jackson | C12: 1 | D12: 29 | E12: ACT | F12: BAL | G12: 13 | H12: 0.945 | I12: 0.7156 | J12: 0.654 | K12: 8.48 | L12: 0.016 | M12: 0.1184 | N12: 6.4 | O12: 0.12 | P12: 0.087 | W12: 17 | X12: 0.775 | Y12: 0.654 | Z12: 0.016 | AA12: 0.1607 | AB12: 6.44 | AC12: 0.1207 | AH12: =IFERROR(X12*$F$4,0) | AI12: =IFERROR(AH12*Y12,0) | AJ12: =IFERROR(X12*SUM($AR$12:$AR$36),0) | AK12: =IFERROR(X12*$E$7,0) | AL12: =IFERROR(AH12*Z12,0) | AM12: =IFERROR(AA12*$G$4,0) | AN12: =IFERROR(AM12*AB12,0) | AO12: =IFERROR(AC12*$D$7,0) | AP12: =IFERROR(AD12*$H$4,0) | AQ12: =IFERROR(AP12*AE12,0) | AR12: =IFERROR(AQ12*AF12,0) | AS12: =IFERROR(AG12*$E$7,0) | AT12: =AN12*Settings!$B$10+AO12*Settings!$B$11+AR12*Settings!$B$7+AS12*Settings!$B$8+AJ12*Settings!$B$12+AK12*Settings!$B$13+AL12*Settings!$B$14 | AU12: =AN12*Settings!$B$10+AO12*Settings!$B$11+AR12*Settings!$B$7+AS12*Settings!$B$8+AJ12*Settings!$B$12+AK12*Settings!$B$13+AL12*Settings!$B$14+AQ12*Settings!$B$9 | AV12: =AN12*Settings!$B$10+AO12*Settings!$B$11+AR12*Settings!$B$7+AS12*Settings!$B$8+AJ12*Settings!$B$12+AK12*Settings!$B$13+AL12*Settings!$B$14+AQ12*Settings!$B$15
